Workbook
Name SIGN: #REF!
Name SIGN: #REF!
Name SIGN: #REF!
Name SIGN: #REF!
Name SIGN: #REF!
Name SIGN: #REF!
Name SIGN: #REF!
Name SIGN_D: #REF!
Name SIGN_D: #REF!
Name SIGN_D: #REF!
Name SIGN_D: #REF!
Name SIGN_D: #REF!
Name SIGN_D: #REF!
Name SIGN_D: #REF!
Name Sign1: #REF!
Name Sign1: #REF!
Name Sign1: #REF!
Name Sign1: #REF!
Name Sign1: #REF!
Name Sign1: #REF!
Name Sign1: #REF!
Name и: #REF!
Name и: #REF!
Name и: #REF!
Name и: #REF!
Name и: #REF!
Name и: #REF!
Name и: #REF!
Name Р1: #REF!
Name Р1: #REF!
Name Р1: #REF!
Name Р1: #REF!
Name Р1: #REF!
Name Р1: #REF!
Name Р1: #REF!
Name ыва: #REF!
Name ыва: #REF!
Name ыва: #REF!
Name ыва: #REF!
Name ыва: #REF!
Name ыва: #REF!
Name ыва: #REF!

Sheet Титул
K1: УТВЕРЖДАЮ
K2: Начальник учебно-методического управления
K3: Р.С. Халимулина
K4: _________________________________
K5: «____»____________________20___г.
A7: Расписание учебных занятий на первое полугодие 2026-2027 учебного года
A8: ТРЕНЕРСКИЙ ФАКУЛЬТЕТ, направление подготовки (образовательная программа)
A9: 49.03.04 Спорт, Профиль (направленность) Спортивная подготовка по видам спорта «художественная гимнастика», «эстетическая гимнастика». Педагогическая деятельность в области физической культуры и спорта; Спортивная подготовка по видам спорта «спортивная гимнастика», «воздушно-силовая атлетика». Педагогическая деятельность в области физической культуры и спорта; Спортивная подготовка по виду спорта «легкая атлетика». Педагогическая деятельность в области физической культуры и спорта; Спортивная подготовка в циклических видах лыжного спорта. Педагогическая деятельность в области физической культуры и спорта; Спортивная подготовка в сложнокоординационных видах лыжного спорта. Педагогическая деятельность в области физической культуры и спорта; Спортивная подготовка по виду спорта «фигурное катание на коньках». Педагогическая деятельность в области физической культуры и спорта; Спортивная подготовка по видам спорта «конькобежный спорт», «шорт-трек», «кёрлинг». Педагогическая деятельность в области физической культуры и спорта; Спортивная подготовка по виду спорта «плавание». Педагогическая деятельность в области физической культуры и спорта; Спортивная подготовка в синхронном плавании. Педагогическая деятельность в области физической культуры и спорта; Спортивная подготовка по виду спорта «танцевальный спорт». Педагогическая деятельность в области физической культуры и спорта; Спортивная подготовка по виду спорта «чир спорт». Педагогическая деятельность в области физической культуры и спорта; Спортивная подготовка по видам спорта «велосипедный спорт», «триатлон». Педагогическая деятельность в области физической культуры и спорта ; Спортивная подготовка в гребных и парусных видах спорта. Педагогическая деятельность в области физической культуры и спорта; Спортивная подготовка по видам спорта "спортивная акробатика", "прыжки на батуте". Педагогическая деятельность в области физической культуры и спорта; Спортивная подготовка по видам спорта "спортивная аэробика", "фитнес аэробика". Педагогическая деятельность в области физической культуры и спорта; уровень образовния бакалавриат
A10: Курс 4, семестр 7, очная форма обучения
A11: группы С3-10-23, С3-11-23, С3-12-23, С3-13-23, С3-14-23, С3-15-23, С3-16-23
A12: № | B12: Наименование дисциплины (модуля), практика, научные исследования | C12: Кол-во часов (Л/П) | D12: Форма отчетности | E12: Учебные группы в соответствии с избранным видом спорта
E13: танцевальный спорт, чир спорт | F13: фигурное катание на коньках, конькобежный спорт, шорт-трек, кёрлинг | G13: легкая атлетика | H13: плавание, синхронное плавание | I13: гребные и парусные виды спорта, циклические и сложнокоординационные виды лыжного спорта | J13: велосипедный спорт, триатлон, спортивная акробатика, прыжки на батуте, спортивная гимнастика, воздушно-силовая атлетика | K13: художественная гимнастика, эстетическая гимнастика, спортивная аэробика, фитнес аэробика
E14: 10 группа | F14: 11 группа | G14: 12 группа | H14: 13 группа | I14: 14 группа | J14: 15 группа | K14: 16 группа
F15: Ф.И.О. преподавателя
A16: 1 | B16: Основы медицинских знаний и спортивная медицина | C16: 16/32 | D16: Экзамен | E16: Л - Тарасов А.В.
E17: Тарасов А.В. | F17: Тарасов А.В. | G17: Тарасов А.В. | H17: Тарасов А.В. | I17: Тарасов А.В. | J17: Тарасов А.В. | K17: Тарасов А.В.
A18: 2 | B18: Массаж | C18: 10/38 | D18: Диф.зачет | E18: Л - Саламатов М.Б.
E19: Власова Н.А. | F19: Власова Н.А. | G19: Власова Н.А. | H19: Власова Н.А. | I19: Ларин А.В. | J19: Саламатов М.Б. | K19: Саламатов М.Б.
A20: 3 | B20: Правовые основы профессиональной деятельности | C20: 10/22 | D20: Диф.зачет | E20: Л - Купцов Е.И.
E21: Купцов Е.И. | F21: Купцов Е.И. | G21: Купцов Е.И. | H21: Купцов Е.И. | I21: Купцов Е.И. | J21: Купцов Е.И. | K21: Купцов Е.И.
A22: 4 | B22: Спортивная метрология | C22: 10/22 | D22: Зачет | E22: Л - Тарханов И.В.
E23: Тарханов И.В. | F23: Тарханов И.В. | G23: Тарханов И.В. | H23: Тарханов И.В. | I23: Фураев А.Н. | J23: Фураев А.Н. | K23: Тарханов И.В.
A24: 5 | B24: Теория и методика избранного вида спорта | C24: 10/88 | D24: Зачет | E24: танцевальный спорт | F24: фигурное катание на коньках | G24: легкая атлетика | H24: плавание | I24: гребные и парусные виды спорта | J24: спортивная гимнастика, воздушно-силовая атлетика | K24: художественная гимнастика, эстетическая гимнастика
E25: Л - Сингина Н.Ф. | F25: Л - Жгун Е.В. | G25: Л - Татаринов И.Д., Сячин В.Д. | H25: Л - Чеботарева И.В., Соломатин В.Р. | I25: Л - Долгова Е.В. | J25: Л - Парахин В.А. | K25: Л - Ивашина В.В.
E26: П - Сингина Н.Ф. / Голивкин А.П. | F26: П - Жгун Е.В. | G26: П - Татаринов И.Д., Сячин В.Д. | H26: П - Чеботарева И.В., Соломатин В.Р. | I26: П - Долгова Е.В. | J26: П - Парахин В.А. | K26: П - Ивашина В.В., Булгачева П.В.
E27: чир спорт | F27: конькобежный спорт, шорт-трек, кёрлинг | H27: синхронное плавание | I27: циклические виды лыжного спорта | J27: спортивная акробатика, прыжки на батуте | K27: спортивная аэробика, фитнес аэробика
E28: Л - Сингина Н.Ф. | F28: Л - Разинов Ю.И. | H28: Л - Максимова М.Н. | I28: Л - Сенатская В.Г. | J28: Л - Захарчук М.С. | K28: Л - Лисицкая Т.С.
E29: П - Михайлов И. А. | F29: П - Разинов Ю.И., Тавыриков Е.Е. | H29: П - Максимова М.Н. | I29: П - Сенатская В.Г. | J29: П - Захарчук М.С. | K29: П - Лисицкая Т.С.
I30: сложнокоординационные виды лыжного спорта | J30: велосипедный спорт, триатлон до 10.10
I31: Л - Дубровинский С. С. | J31: Л - Дышаков А.С.
I32: П - Дубровинский С. С. | J32: П - Дышаков А.С.
A33: 6 | B33: Профессионально-спортивное совершенствование | C33: 0/36 | D33: Экзамен | E33: танцевальный спорт | F33: фигурное катание на коньках | G33: легкая атлетика | H33: плавание | I33: гребные и парусные виды спорта | J33: спортивная гимнастика, воздушно-силовая атлетика | K33: художественная гимнастика, эстетическая гимнастика
E34: П - Сингина Н.Ф./ Голивкин А.П. | F34: П - Смирнова А.В. | G34: П - Татаринов И.Д., Сячин В.Д. | H34: П - Чеботарева И.В., Соломатин В.Р. | I34: П - Долгова Е.В. | J34: П - Парахин В.А. | K34: П - Ивашина В.В., Булгачева П.В.
E35: чир спорт | F35: конькобежный спорт, шорт-трек, кёрлинг | H35: синхронное плавание | I35: циклические виды лыжного спорта | J35: спортивная акробатика, прыжки на батуте | K35: спортивная аэробика, фитнес аэробика
E36: П - Ракитина Т.М. | F36: П - Тавыриков Е.Е. | H36: П - Максимова М.Н. | I36: П - Сенатская В.Г. | J36: П - Михалина Г.М. | K36: П - Лисицкая Т.С.
I37: сложнокоординационные виды лыжного спорта | J37: велосипедный спорт, триатлон до 10.10
I38: П - Дубровинский С.С. (6ч) 01.09-25.09, с 28.09 Баталов А.Г. (30ч) | J38: П -Дышаков А.С.
B40: Условные обозначения:
B41: П - занятия семинарского типа | E41: Л - занятия лекционного типа | H41: Диф.зачет - дифференцированный зачет | J41: Б/о - без отчета
B42: Элективные дисциплины по ФКиС- Элективные дисциплины по физической культуре и спорту.
...

Sheet приложение1
A1: Приложение1 к расписанию учебных занятий на первое полугодие 2026-2027 учебного года
A2: ТРЕНЕРСКИЙ ФАКУЛЬТЕТ, направление подготовки (образовательная программа)
A3: 49.03.04 Спорт*
A4: Курс 4, семестр 7, очная форма обучения
A5: группы С3-10-23, С3-11-23, С3-12-23, С3-13-23, С3-14-23, С3-15-23, С3-16-23
A6: № | B6: Наименование дисциплины (модуля): | C6: № аудитории
A7: 1 | B7: Теория и методика спортивная акробатика, прыжки на батуте, спортивная аэробика, фитнес аэробика, спортивная гимнастика, воздушно-силовая атлетика, профессионально-спортивное совершенствование, методика реализации программ дополнительного образования в области физической культуры и спорта (спортивная гимнастика, воздушно-силовая атлетика, прыжки на батуте, фитнес аэробика, спортивная аэробика, спортивная акробатика) | C7: 205 СК, 206СК, 210СК, ауд.212СК, ауд.16СК
A8: 2 | B8: Теория и методика художественная гимнастика, эстетическая гимнастика, профессионально-спортивное совершенствование, методика реализации программ дополнительного образования в области физической культуры и спорта (художественная гимнастика, эстетическая гимнастика) | C8: 205 СК, 206СК, 210СК, ауд.212СК, ауд.16СК
A9: 3 | B9: Теория и методика гребного и парусного видов спорта, профессионально-спортивное совершенствование, методика реализации программ дополнительного образования в области физической культуры и спорта (гребные и парусные виды спорта) | C9: 321а мбк
A10: 4 | B10: Теория и методика фигурное катание на коньках, конькобежный спорт, шорт-трек, кёрлинг; профессионально-спортивное совершенствование; методика реализации программ дополнительного образования в области физической культуры и спорта (фигурное катание на коньках, конькобежный спорт, шорт-трек, кёрлинг) | C10: ауд.4 УСЗК, ауд.5 УСЗК, ГБУ ДО "Московская академия фигурного катания на коньках" г. Москва, Ул.Маршала Катукова, д.22
A11: 5 | B11: Теория и методика легкой атлетики, профессионально-спортивное совершенствование, методика реализации программ дополнительного образования в области физической культуры и спорта (легкая атлетика) | C11: легкоатлетический манеж
A12: 6 | B12: Теория и методика циклические виды лыжного спорта, сложнокоординационные виды лыжного спорта, профессионально-спортивное совершенствование, методика реализации программ дополнительного образования в области физической культуры и спорта (циклические виды лыжного спорта, сложнокоординационные виды лыжного спорта) | C12: 250 мбк, 282МБК, л/а манеж, 64 мбк, 281мбк
A13: 7 | B13: Теория и методика плавание, водное поло, профессионально-спортивное совершенствование, методика реализации программ дополнительного образования в области физической культуры и спорта (плавание, синхронное плавание) | C13: 92 УСЗК, 80 УСЗК, 83 УСЗК
A14: 8 | B14: Теория и методика велосипедный спорт, триатлон; профессионально-спортивное совершенствование, методика реализации программ дополнительного образования в области физической культуры и спорта (велосипедный спорт, триатлон) | C14: лекции - 215 мбк, практические занятия 518мбк
A15: 9 | B15: Теория и методика танцевальный спорт, профессионально-спортивное совершенствование, методика реализации программ дополнительного образования в области физической культуры и спорта (чир спорт) | C15: вторник - ауд.1 УСЗК, 11 УСЗК; четверг - ауд.1 УСЗК, 11 УСЗК; пятница - ауд.1 УСЗК, 11 УСЗК, 213СК - до 19.09
A16: 10 | B16: Теория и методика танцевальный спорт, профессионально-спортивное совершенствование, методика реализации программ дополнительного образования в области физической культуры и спорта (танцевальный спорт) | C16: вторник - ауд.1 УСЗК, 11 УСЗК; четверг - ауд.1 УСЗК, 11 УСЗК; пятница - ауд.1 УСЗК, 11 УСЗК, 213СК - до 19.09
A17: Условные обозначения:
A18: УСЗК - универсальный спортивно-зрелищный комплекс
A19: СК - спортивный корпус
A20: МБК - медико-биологический корпус
A21: * Профили (направленность) указанны на титульном листе

Sheet расписание ПСС
B1: Расписание учебных занятий на первое полугодие 2026-2027 учебного года
B2: ТРЕНЕРСКИЙ ФАКУЛЬТЕТ, направление подготовки (образовательная программа)
A3: 49.03.04 Спорт*
B4: Курс 4, семестр 7, очная форма обучения
B5: группы С3-10-23, С3-11-23, С3-12-23, С3-13-23, С3-14-23, С3-15-23, С3-16-23
B6: с 01.09-19.10, с 02.12-30.12
A7: День недели | B7: Дата | C7: Время | D7: 10 группа | E7: 11 группа | F7: 12 группа | G7: 13 группа | H7: 14 группа | I7: 15 группа | J7: 16 группа
D8: танцевальный спорт, чир спорт | E8: фигурное катание на коньках, конькобежный спорт, шорт-трек, кёрлинг | F8: легкая атлетика | G8: плавание, синхронное плавание | H8: гребные и парусные виды спорта, циклические и сложнокоординационные виды лыжного спорта | I8: велосипедный спорт, триатлон, спортивная акробатика, прыжки на батуте, спортивная гимнастика, воздушно-силовая атлетика | J8: художественная гимнастика, эстетическая гимнастика, спортивная аэробика, фитнес аэробика
A9: Понедельник | C9: 8.50-10.20
C10: 10.40-12.10
C11: 13.00-14.30 | H11: ПСС циклические и сложнокоординационные виды лыжного спорта 249мбк, 250мбк, 281мбк, 282мбк, легкоатлетический манеж - 21.09, 28.09, 05.10, 12.10, 19.10
C12: 14:50-16:20 | H12: ПСС циклические и сложнокоординационные виды лыжного спорта 249мбк, 250мбк, 281мбк, 282мбк, легкоатлетический манеж - 21.09, 28.09, 05.10, 12.10, 19.10
C13: 16:40-18:10
C14: 18:30-20:00
C15: 20:20-21:50
A16: Вторник | C16: 8.50-10.20
C17: 10.40-12.10
C18: 13.00-14.30 | F18: ПСС легкая атлетика - легкоатлетический манеж - 08.09-22.12
C19: 14:50-16:20
C20: 16:40-18:10 | D20: ПСС танцевальный спорт, чир спорт 16.30-18.00 ауд.1УСЗК, ауд.11УСЗК | G20: ПСС 08.09-16.12 бассейн УСЗК, ауд.83
C21: 18:30-20:00
C22: 20:20-21:50
A23: Среда | C23: 8.50-10.20 | G23: ПСС 03.09-16.12 бассейн УСЗК, ауд.83
C24: 10.40-12.10
C25: 13.00-14.30
C26: 14:50-16:20
C27: 16:40-18:10 | H27: ПСС гребные и парусные виды спорта 321а мбк 09.09-14.10, 02.12-16.12 | I27: ПСС 16.30-18.00 спортивная акробатика, прыжки на батуте, спортивная гимнастика, воздушно-силовая атлетика 210СК 07.09-16.10, 02.12-17.12
C28: 18:30-20:00 | E28: ПСС фигурное катание на коньках ауд.4 УСЗК, ауд.5 УСЗК 09.09 - 14.10, 02.12-16.12
C29: 20:20-21:50
A30: Четверг | C30: 8.50-10.20
C31: 10.40-12.10
C32: 13.00-14.30 | D32: ПСС танцевальный спорт 12.10-12.55 ауд.1УСЗК, ауд.11УСЗК | I32: ПСС 13.00-14.30 спортивная акробатика, прыжки на батуте 210СК 07.09-16.10, 02.12-17.12 | J32: ПСС художественная гимнастика, эстетическая гимнастика 206СК, спортивная аэробика, фитнес аэробика 205 СК - 07.09-16.10, 02.12-17.12
C33: 14:50-16:20 | J33: ПСС спортивная аэробика, фитнес аэробика 205 СК - 07.09-16.10, 02.12-17.12
C34: 16:40-18:10 | D34: ПСС чир спорт 16.30-18.00 205СК | F34: ПСС легкая атлетика - легкоатлетический манеж - 10.09 - 10.12 | I34: ПСС велосипедный спорт, триатлон 16.30-18.00 ауд.518мбк с 07.09-30.12
C35: 18:30-20:00 | E35: ПСС фигурное катание на коньках ауд.4 УСЗК, ауд.5 УСЗК 10.09 - 15.10, 03.12- 17.12
C36: 20:20-21:50
A37: Пятница | C37: 8.50-10.20
C38: 10.40-12.10
C39: 13.00-14.30 | D39: ПСС танцевальный спорт 12.10-12.55 ауд.1УСЗК, ауд.11УСЗК, чир спорт Сцена УСЗК | J39: ПСС художественная гимнастика, эстетическая гимнастика 13.00-14.30 206СК 07.09-16.10
C40: 14:50-16:20 | H40: ПСС циклические и сложнокоординационные виды лыжного спорта 249мбк, 250мбк, 281мбк, 282мбк, легкоатлетический манеж - 04.09
...

Sheet 01.09
B1: Расписание учебных занятий на первое полугодие 2026-2027 учебного года
B2: ТРЕНЕРСКИЙ ФАКУЛЬТЕТ, направление подготовки (образовательная программа)
A3: 49.03.04 Спорт, Профиль (направленность) Спортивная подготовка по видам спорта «художественная гимнастика», «эстетическая гимнастика». Педагогическая деятельность в области физической культуры и спорта; Спортивная подготовка по видам спорта «спортивная гимнастика», «воздушно-силовая атлетика». Педагогическая деятельность в области физической культуры и спорта; Спортивная подготовка по виду спорта «легкая атлетика». Педагогическая деятельность в области физической культуры и спорта; Спортивная подготовка в циклических видах лыжного спорта. Педагогическая деятельность в области физической культуры и спорта; Спортивная подготовка в сложнокоординационных видах лыжного спорта. Педагогическая деятельность в области физической культуры и спорта; Спортивная подготовка по виду спорта «фигурное катание на коньках». Педагогическая деятельность в области физической культуры и спорта; Спортивная подготовка по видам спорта «конькобежный спорт», «шорт-трек», «кёрлинг». Педагогическая деятельность в области физической культуры и спорта; Спортивная подготовка по виду спорта «плавание». Педагогическая деятельность в области физической культуры и спорта; Спортивная подготовка в синхронном плавании. Педагогическая деятельность в области физической культуры и спорта; Спортивная подготовка по виду спорта «танцевальный спорт». Педагогическая деятельность в области физической культуры и спорта; Спортивная подготовка по виду спорта «чир спорт». Педагогическая деятельность в области физической культуры и спорта; Спортивная подготовка по видам спорта «велосипедный спорт», «триатлон». Педагогическая деятельность в области физической культуры и спорта; Спортивная подготовка в гребных и парусных видах спорта. Педагогическая деятельность в области физической культуры и спорта; Спортивная подготовка по видам спорта "спортивная акробатика", "прыжки на батуте". Педагогическая деятельность в области физической культуры и спорта; Спортивная подготовка по видам спорта "спортивная аэробика", "фитнес аэробика". Педагогическая деятельность в области физической культуры и спорта; уровень образовния бакалавриат
B4: Курс 4, семестр 7, очная форма обучения
B5: группы С3-10-23, С3-11-23, С3-12-23, С3-13-23, С3-14-23, С3-15-23, С3-16-23
A7: День недели | B7: Дата | C7: Время | D7: 10 группа | E7: 11 группа | F7: 12 группа | G7: 13 группа | H7: 14 группа | I7: 15 группа | J7: 16 группа
D8: танцевальный спорт, чир спорт | E8: фигурное катание на коньках, конькобежный спорт, шорт-трек, кёрлинг | F8: легкая атлетика | G8: плавание, синхронное плавание | H8: гребные и парусные виды спорта, циклические и сложнокоординационные виды лыжного спорта | I8: велосипедный спорт, триатлон, спортивная акробатика, прыжки на батуте, спортивная гимнастика, воздушно-силовая атлетика | J8: художественная гимнастика, эстетическая гимнастика, спортивная аэробика, фитнес аэробика
A9: Понедельник | B9: 46265 | C9: 8.50-10.20
C10: 10.40-12.10
C11: 13.00-14.30
C12: 14.50-16.20
C13: 16.40-18.10
A14: Вторник | B14: =B9+1 -> 46266 | C14: 8.50-10.20
C15: 10.40-12.10
C16: 13.00-14.30 | D16: Л. Спортивная метрология Тарханов И.В. 212 ауд.к. | E16: Л. Спортивная метрология Тарханов И.В. 212 ауд.к. | F16: Л. Спортивная метрология Тарханов И.В. 212 ауд.к. | G16: Л. Спортивная метрология Тарханов И.В. 212 ауд.к. | H16: Л. Спортивная метрология Тарханов И.В. 212 ауд.к. | I16: Л. Спортивная метрология Тарханов И.В. 212 ауд.к. | J16: Л. Спортивная метрология Тарханов И.В. 212 ауд.к.
C17: 14.50-16.20 | D17: Л. Правовые основы профессиональной деятельности Купцов Е.И. 212 ауд.к. | E17: Л. Правовые основы профессиональной деятельности Купцов Е.И. 212 ауд.к. | F17: Л. Правовые основы профессиональной деятельности Купцов Е.И. 212 ауд.к. | G17: Л. Правовые основы профессиональной деятельности Купцов Е.И. 212 ауд.к. | H17: Л. Правовые основы профессиональной деятельности Купцов Е.И. 212 ауд.к. | I17: Л. Правовые основы профессиональной деятельности Купцов Е.И. 212 ауд.к. | J17: Л. Правовые основы профессиональной деятельности Купцов Е.И. 212 ауд.к.
C18: 16.40-18.10
A19: Среда | B19: =B14+1 -> 46267 | C19: 8.50-10.20
C20: 10.40-12.10 | I20: Л. Теория и методика велосипедного спорта, триатлона, спортивной акробатики, прыжков на батуте, спортивной гимнастики, воздушно-силовой атлетики Прил.1 | J20: Л. Теория и методика художественной гимнастики, эстетической гимнастики, спортивной аэробики, фитнес аэробики Прил.1
C21: 13.00-14.30 | D21: Л. Основы медицинских знаний и спортивная медицина Тарасов А.В. 220 ауд.к. | E21: Л. Основы медицинских знаний и спортивная медицина Тарасов А.В. 220 ауд.к. | F21: Л. Основы медицинских знаний и спортивная медицина Тарасов А.В. 220 ауд.к. | G21: Л. Основы медицинских знаний и спортивная медицина Тарасов А.В. 220 ауд.к. | H21: Л. Основы медицинских знаний и спортивная медицина Тарасов А.В. 220 ауд.к. | I21: Л. Основы медицинских знаний и спортивная медицина Тарасов А.В. 220 ауд.к. | J21: Л. Основы медицинских знаний и спортивная медицина Тарасов А.В. 220 ауд.к.
C22: 14.50-16.20 | D22: Л. Массаж Саламатов М.Б. 220 ауд.к. | E22: Л. Массаж Саламатов М.Б. 220 ауд.к. | F22: Л. Массаж Саламатов М.Б. 220 ауд.к. | G22: Л. Массаж Саламатов М.Б. 220 ауд.к. | H22: Л. Массаж Саламатов М.Б. 220 ауд.к. | I22: Л. Массаж Саламатов М.Б. 220 ауд.к. | J22: Л. Массаж Саламатов М.Б. 220 ауд.к.
C23: 16.40-18.10
A24: Четверг | B24: =B19+1 -> 46268 | C24: 8.50-10.20 | D24: Л. Теория и методика танцевального спорта, чир спорта Прил. 1 | E24: Пр. Спортивная метрология Тарханов И.В. 68мбк | F24: Л. Теория и методика легкой атлетики Прил.1 | G24: Пр. Основы медицинских знаний и спортивная медицина Тарасов А.В. 342мбк | H24: Пр. Массаж Ларин А.В. 346мбк | I24: Л. Теория и методика велосипедного спорта, триатлона, спортивной акробатики, прыжков на батуте, спортивной гимнастики, воздушно-силовой атлетики Прил.1 | J24: Л. Теория и методика художественной гимнастики, эстетической гимнастики, спортивной аэробики, фитнес аэробики Прил.1
C25: 10.40-12.10 | D25: Л. Теория и методика танцевального спорта, чир спорта Прил. 1 | E25: Л. Теория и методика фигурного катания на коньках, конькобежного спорта, шорт-трек, кёрлинга Прил.1 | F25: Пр. Массаж Власова Н.А. 346мбк | G25: Пр. Спортивная метрология Тарханов И.В. 68мбк | H25: Пр. Основы медицинских знаний и спортивная медицина Тарасов А.В. 342мбк | I25: Пр. Теория и методика велосипедного спорта, триатлона, спортивной акробатики, прыжков на батуте, спортивной гимнастики, воздушно-силовой атлетики Прил.1 | J25: Пр. Теория и методика художественной гимнастики, эстетической гимнастики, спортивной аэробики, фитнес аэробики Прил.1
C26: 13.00-14.30 | D26: Пр. Основы медицинских знаний и спортивная медицина Тарасов А.В. 342мбк | E26: Л. Теория и методика фигурного катания на коньках, конькобежного спорта, шорт-трек, кёрлинга Прил.1 | F26: Пр. Правовые основы профессиональной деятельности Купцов Е.И. 401 ауд.к. | G26: Пр. Массаж Власова Н.А. 346мбк | H26: Л. Теория и методика гребного и парусного видов спорта, Л. Теория и методика циклических и сложнокоординационных видов лыжного спорта Прил.1
C27: 14.50-16.20 | D27: Пр. Массаж Власова Н.А. 346мбк | F27: Пр. Основы медицинских знаний и спортивная медицина Тарасов А.В. 342мбк | H27: Л. Теория и методика гребного и парусного видов спорта, Л. Теория и методика циклических и сложнокоординационных видов лыжного спорта Прил.1
C28: 16.40-18.10
A29: Пятница | B29: =B24+1 -> 46269 | C29: 8.50-10.20 | D29: Пр. Теория и методика танцевального спорта, чир спорта Прил. 1 | E29: Пр. Основы медицинских знаний и спортивная медицина Тарасов А.В. 350мбк | F29: Пр. Спортивная метрология Тарханов И.В. 68мбк | H29: Пр. Массаж Ларин А.В. 346мбк
C30: 10.40-12.10 | D30: Пр. Теория и методика танцевального спорта, чир спорта Прил. 1 | E30: Пр. Теория и методика фигурного катания на коньках, конькобежного спорта, шорт-трек, кёрлинга Прил.1 | F30: Л. Теория и методика легкой атлетики Прил.1 | G30: Пр. Правовые основы профессиональной деятельности Купцов Е.И. 401 ауд.к. | H30: Пр. Спортивная метрология Фураев А.Н. 68мбк | J30: Пр. Массаж Саламатов М.Б. 346мбк
C31: 13.00-14.30 | D31: Пр. Спортивная метрология Тарханов И.В. 68мбк | E31: Пр. Теория и методика фигурного катания на коньках, конькобежного спорта, шорт-трек, кёрлинга Прил.1 | F31: Пр. Теория и методика легкой атлетики Прил.1 | G31: Л. Теория и методика плавания, синхронного плавания Прил. 1 | H31: Пр. Теория и методика гребного и парусного видов спорта, Пр. Теория и методика циклических и сложнокоординационных видов лыжного спорта Прил.1 | I31: Пр. Основы медицинских знаний и спортивная медицина Тарасов А.В. 350мбк | J31: Пр. Правовые основы профессиональной деятельности Купцов Е.И. 401 ауд.к.
C32: 14.50-16.20 | E32: Пр. Правовые основы профессиональной деятельности Купцов Е.И. 401 ауд.к. | G32: Л. Теория и методика плавания, синхронного плавания Прил. 1 | I32: Пр. Массаж Саламатов М.Б. 346мбк | J32: Пр. Основы медицинских знаний и спортивная медицина Тарасов А.В. 350мбк
C33: 16.40-18.10
A34: Суббота | B34: =B29+1 -> 46270 | C34: 8.50-10.20
C35: 10.40-12.10
C36: 13.00-14.30
C37: 14.50-16.20
C38: 16.40-18.10
B40: 16 | C40: *Л. Основы медицинских знаний и спортивная медицина* | D40: =COUNTIF(D$9:D$38,$C40) -> 1 | E40: =COUNTIF(E$9:E$38,$C40) -> 1 | F40: =COUNTIF(F$9:F$38,$C40) -> 1 | G40: =COUNTIF(G$9:G$38,$C40) -> 1 | H40: =COUNTIF(H$9:H$38,$C40) -> 1 | I40: =COUNTIF(I$9:I$38,$C40) -> 1 | J40: =COUNTIF(J$9:J$38,$C40) -> 1
B41: 32 | C41: *Пр. Основы медицинских знаний и спортивная медицина* | D41: =COUNTIF(D$9:D$38,$C41) -> 1 | E41: =COUNTIF(E$9:E$38,$C41) -> 1 | F41: =COUNTIF(F$9:F$38,$C41) -> 1 | G41: =COUNTIF(G$9:G$38,$C41) -> 1 | H41: =COUNTIF(H$9:H$38,$C41) -> 1 | I41: =COUNTIF(I$9:I$38,$C41) -> 1 | J41: =COUNTIF(J$9:J$38,$C41) -> 1
B42: 10 | C42: *Л. Массаж* | D42: =COUNTIF(D$9:D$38,$C42) -> 1 | E42: =COUNTIF(E$9:E$38,$C42) -> 1 | F42: =COUNTIF(F$9:F$38,$C42) -> 1 | G42: =COUNTIF(G$9:G$38,$C42) -> 1 | H42: =COUNTIF(H$9:H$38,$C42) -> 1 | I42: =COUNTIF(I$9:I$38,$C42) -> 1 | J42: =COUNTIF(J$9:J$38,$C42) -> 1
...

Sheet 07.09
B1: Расписание учебных занятий на первое полугодие 2026-2027 учебного года
B2: ТРЕНЕРСКИЙ ФАКУЛЬТЕТ, направление подготовки (образовательная программа)
A3: 49.03.04 Спорт*
B4: Курс 4, семестр 7, очная форма обучения
B5: группы С3-10-23, С3-11-23, С3-12-23, С3-13-23, С3-14-23, С3-15-23, С3-16-23
A7: День недели | B7: Дата | C7: Время | D7: 10 группа | E7: 11 группа | F7: 12 группа | G7: 13 группа | H7: 14 группа | I7: 15 группа | J7: 16 группа
D8: танцевальный спорт, чир спорт | E8: фигурное катание на коньках, конькобежный спорт, шорт-трек, кёрлинг | F8: легкая атлетика | G8: плавание, синхронное плавание | H8: гребные и парусные виды спорта, циклические и сложнокоординационные виды лыжного спорта | I8: велосипедный спорт, триатлон, спортивная акробатика, прыжки на батуте, спортивная гимнастика, воздушно-силовая атлетика | J8: художественная гимнастика, эстетическая гимнастика, спортивная аэробика, фитнес аэробика
A9: Понедельник | B9: 46272 | C9: 8.50-10.20 | E9: Пр. Массаж Власова Н.А. 346мбк | H9: Пр. Основы медицинских знаний и спортивная медицина Тарасов А.В. 350мбк | I9: Пр. Теория и методика велосипедного спорта, триатлона, спортивной акробатики, прыжков на батуте, спортивной гимнастики, воздушно-силовой атлетики Прил.1 | J9: Пр. Теория и методика художественной гимнастики, эстетической гимнастики, спортивной аэробики, фитнес аэробики Прил.1
C10: 10.40-12.10 | E10: Пр. Основы медицинских знаний и спортивная медицина Тарасов А.В. 350мбк | F10: Пр. Теория и методика легкой атлетики Прил.1 | G10: Пр. Массаж Власова Н.А. 346мбк | H10: Пр. Правовые основы профессиональной деятельности Купцов Е.И. 401ауд.к. | I10: Пр. Теория и методика велосипедного спорта, триатлона, спортивной акробатики, прыжков на батуте, спортивной гимнастики, воздушно-силовой атлетики Прил.1 | J10: Пр. Теория и методика художественной гимнастики, эстетической гимнастики, спортивной аэробики, фитнес аэробики Прил.1
C11: 13.00-14.30 | D11: Пр. Основы медицинских знаний и спортивная медицина Тарасов А.В. 439мбк | E11: Пр. Правовые основы профессиональной деятельности Купцов Е.И. 401ауд.к. | F11: Пр. Теория и методика легкой атлетики Прил.1 | G11: Пр. Теория и методика плавания, синхронного плавания Прил. 1 | H11: Пр. Теория и методика циклических и сложнокоординационных видов лыжного спорта Прил.1 | I11: Пр. Массаж Саламатов М.Б. 346мбк | J11: Пр. Спортивная метрология Тарханов И.В. 68мбк
C12: 14.50-16.20 | D12: Пр. Правовые основы профессиональной деятельности Купцов Е.И. 401ауд.к. | G12: Пр. Теория и методика плавания, синхронного плавания Прил. 1 | H12: Пр. Теория и методика циклических и сложнокоординационных видов лыжного спорта Прил.1 | I12: Пр. Спортивная метрология Фураев А.Н. 68мбк | J12: Пр. Массаж Саламатов М.Б. 346мбк
C13: 16.40-18.10
A14: Вторник | B14: =B9+1 -> 46273 | C14: 8.50-10.20 | D14: Л. Спортивная метрология Тарханов И.В. 220 ауд.к. | E14: Л. Спортивная метрология Тарханов И.В. 220 ауд.к. | F14: Л. Спортивная метрология Тарханов И.В. 220 ауд.к. | G14: Л. Спортивная метрология Тарханов И.В. 220 ауд.к. | H14: Л. Спортивная метрология Тарханов И.В. 220 ауд.к. | I14: Л. Спортивная метрология Тарханов И.В. 220 ауд.к. | J14: Л. Спортивная метрология Тарханов И.В. 220 ауд.к.
C15: 10.40-12.10 | D15: Л. Правовые основы профессиональной деятельности Купцов Е.И. 220 ауд.к. | E15: Л. Правовые основы профессиональной деятельности Купцов Е.И. 220 ауд.к. | F15: Л. Правовые основы профессиональной деятельности Купцов Е.И. 220 ауд.к. | G15: Л. Правовые основы профессиональной деятельности Купцов Е.И. 220 ауд.к. | H15: Л. Правовые основы профессиональной деятельности Купцов Е.И. 220 ауд.к. | I15: Л. Правовые основы профессиональной деятельности Купцов Е.И. 220 ауд.к. | J15: Л. Правовые основы профессиональной деятельности Купцов Е.И. 220 ауд.к.
C16: 13.00-14.30 | D16: Пр. Массаж Власова Н.А. 346мбк | E16: Пр. Теория и методика фигурного катания на коньках, конькобежного спорта, шорт-трек, кёрлинга Прил.1 | G16: Пр. Теория и методика плавания, синхронного плавания Прил. 1 | H16: Пр. Теория и методика гребного и парусного видов спорта, Пр. Теория и методика циклических и сложнокоординационных видов лыжного спорта Прил.1 | I16: Пр. Правовые основы профессиональной деятельности Купцов Е.И. 401ауд.к. | J16: Пр. Основы медицинских знаний и спортивная медицина Тарасов А.В. 350мбк
C17: 14.50-16.20 | D17: Пр. Теория и методика танцевального спорта, чир спорта Прил. 1 | E17: Пр. Теория и методика фигурного катания на коньках, конькобежного спорта, шорт-трек, кёрлинга Прил.1 | G17: Пр. Теория и методика плавания, синхронного плавания Прил. 1 | H17: Пр. Теория и методика гребного и парусного видов спорта, Пр. Теория и методика циклических и сложнокоординационных видов лыжного спорта Прил.1 | I17: Пр. Основы медицинских знаний и спортивная медицина Тарасов А.В. 350мбк | J17: Пр. Правовые основы профессиональной деятельности Купцов Е.И. 401ауд.к.
C18: 16.40-18.10
A19: Среда | B19: =B14+1 -> 46274 | C19: 8.50-10.20 | E19: Пр. Основы медицинских знаний и спортивная медицина Тарасов А.В. 342мбк | F19: Пр. Массаж Власова Н.А. 346мбк | I19: Пр. Теория и методика велосипедного спорта, триатлона, спортивной акробатики, прыжков на батуте, спортивной гимнастики, воздушно-силовой атлетики Прил.1 | J19: Пр. Теория и методика художественной гимнастики, эстетической гимнастики, спортивной аэробики, фитнес аэробики Прил.1
C20: 10.40-12.10 | E20: Пр. Массаж Власова Н.А. 346мбк | F20: Пр. Основы медицинских знаний и спортивная медицина Тарасов А.В. 342мбк | I20: Пр. Теория и методика велосипедного спорта, триатлона, спортивной акробатики, прыжков на батуте, спортивной гимнастики, воздушно-силовой атлетики Прил.1 | J20: Пр. Теория и методика художественной гимнастики, эстетической гимнастики, спортивной аэробики, фитнес аэробики Прил.1
C21: 13.00-14.30 | D21: Л. Основы медицинских знаний и спортивная медицина Тарасов А.В. 220 ауд.к. | E21: Л. Основы медицинских знаний и спортивная медицина Тарасов А.В. 220 ауд.к. | F21: Л. Основы медицинских знаний и спортивная медицина Тарасов А.В. 220 ауд.к. | G21: Л. Основы медицинских знаний и спортивная медицина Тарасов А.В. 220 ауд.к. | H21: Л. Основы медицинских знаний и спортивная медицина Тарасов А.В. 220 ауд.к. | I21: Л. Основы медицинских знаний и спортивная медицина Тарасов А.В. 220 ауд.к. | J21: Л. Основы медицинских знаний и спортивная медицина Тарасов А.В. 220 ауд.к.
C22: 14.50-16.20 | D22: Л. Массаж Саламатов М.Б. 220 ауд.к. | E22: Л. Массаж Саламатов М.Б. 220 ауд.к. | F22: Л. Массаж Саламатов М.Б. 220 ауд.к. | G22: Л. Массаж Саламатов М.Б. 220 ауд.к. | H22: Л. Массаж Саламатов М.Б. 220 ауд.к. | I22: Л. Массаж Саламатов М.Б. 220 ауд.к. | J22: Л. Массаж Саламатов М.Б. 220 ауд.к.
C23: 16.40-18.10
A24: Четверг | B24: =B19+1 -> 46275 | C24: 8.50-10.20 | D24: Пр. Теория и методика танцевального спорта, чир спорта Прил. 1 | E24: Пр. Спортивная метрология Тарханов И.В. 68мбк | F24: Пр. Теория и методика легкой атлетики Прил.1 | G24: Пр. Основы медицинских знаний и спортивная медицина Тарасов А.В. 342мбк | H24: Пр. Массаж Ларин А.В. 346мбк | I24: Пр. Теория и методика велосипедного спорта, триатлона, спортивной акробатики, прыжков на батуте, спортивной гимнастики, воздушно-силовой атлетики Прил.1 | J24: Пр. Теория и методика художественной гимнастики, эстетической гимнастики, спортивной аэробики, фитнес аэробики Прил.1
C25: 10.40-12.10 | D25: Пр. Теория и методика танцевального спорта, чир спорта Прил. 1 | E25: Пр. Теория и методика фигурного катания на коньках, конькобежного спорта, шорт-трек, кёрлинга Прил.1 | F25: Пр. Массаж Власова Н.А. 346мбк | G25: Пр. Спортивная метрология Тарханов И.В. 68мбк | H25: Пр. Основы медицинских знаний и спортивная медицина Тарасов А.В. 342мбк | I25: Пр. Теория и методика велосипедного спорта, триатлона, спортивной акробатики, прыжков на батуте, спортивной гимнастики, воздушно-силовой атлетики Прил.1 | J25: Пр. Теория и методика художественной гимнастики, эстетической гимнастики, спортивной аэробики, фитнес аэробики Прил.1
C26: 13.00-14.30 | D26: Пр. Основы медицинских знаний и спортивная медицина Тарасов А.В. 445мбк | F26: Пр. Правовые основы профессиональной деятельности Купцов Е.И. 401 ауд.к. | G26: Пр. Массаж Власова Н.А. 346мбк | H26: Пр. Теория и методика гребного и парусного видов спорта, Пр. Теория и методика циклических и сложнокоординационных видов лыжного спорта Прил.1
C27: 14.50-16.20 | D27: Пр. Массаж Власова Н.А. 346мбк | F27: Пр. Основы медицинских знаний и спортивная медицина Тарасов А.В. 445мбк | H27: Пр. Теория и методика гребного и парусного видов спорта, Пр. Теория и методика циклических и сложнокоординационных видов лыжного спорта Прил.1
C28: 16.40-18.10
A29: Пятница | B29: =B24+1 -> 46276 | C29: 8.50-10.20 | D29: Пр. Теория и методика танцевального спорта, чир спорта Прил. 1 | F29: Пр. Спортивная метрология Тарханов И.В. 68мбк | H29: Пр. Массаж Ларин А.В. 346мбк | J29: Пр. Основы медицинских знаний и спортивная медицина Тарасов А.В. 350мбк
C30: 10.40-12.10 | D30: Пр. Теория и методика танцевального спорта, чир спорта Прил. 1 | E30: Пр. Теория и методика фигурного катания на коньках, конькобежного спорта, шорт-трек, кёрлинга Прил.1 | F30: Пр. Теория и методика легкой атлетики Прил.1 | G30: Пр. Правовые основы профессиональной деятельности Купцов Е.И. 401 ауд.к. | H30: Пр. Спортивная метрология Фураев А.Н. 68мбк | J30: Пр. Массаж Саламатов М.Б. 346мбк
C31: 13.00-14.30 | D31: Пр. Спортивная метрология Тарханов И.В. 69мбк | E31: Пр. Теория и методика фигурного катания на коньках, конькобежного спорта, шорт-трек, кёрлинга Прил.1 | F31: Пр. Теория и методика легкой атлетики Прил.1 | G31: Пр. Теория и методика плавания, синхронного плавания Прил. 1 | H31: Пр. Теория и методика гребного и парусного видов спорта, Пр. Теория и методика циклических и сложнокоординационных видов лыжного спорта Прил.1 | I31: Пр. Основы медицинских знаний и спортивная медицина Тарасов А.В. 350мбк
C32: 14.50-16.20 | H32: Пр. Теория и методика гребного и парусного видов спорта, Пр. Теория и методика циклических и сложнокоординационных видов лыжного спорта Прил.1 | I32: Пр. Массаж Саламатов М.Б. 346мбк
C33: 16.40-18.10
A34: Суббота | B34: =B29+1 -> 46277 | C34: 8.50-10.20
C35: 10.40-12.10
C36: 13.00-14.30
C37: 14.50-16.20
C38: 16.40-18.10
D39: * Профили (направленность) указанны на титульном листе
C40: ='01.09'!C40 -> *Л. Основы медицинских знаний и спортивная медицина* | D40: ='01.09'!D40+COUNTIF(D$9:D$38,$C40) -> 2 | E40: ='01.09'!E40+COUNTIF(E$9:E$38,$C40) -> 2 | F40: ='01.09'!F40+COUNTIF(F$9:F$38,$C40) -> 2 | G40: ='01.09'!G40+COUNTIF(G$9:G$38,$C40) -> 2 | H40: ='01.09'!H40+COUNTIF(H$9:H$38,$C40) -> 2 | I40: ='01.09'!I40+COUNTIF(I$9:I$38,$C40) -> 2 | J40: ='01.09'!J40+COUNTIF(J$9:J$38,$C40) -> 2
C41: ='01.09'!C41 -> *Пр. Основы медицинских знаний и спортивная медицина* | D41: ='01.09'!D41+COUNTIF(D$9:D$38,$C41) -> 3 | E41: ='01.09'!E41+COUNTIF(E$9:E$38,$C41) -> 3 | F41: ='01.09'!F41+COUNTIF(F$9:F$38,$C41) -> 3 | G41: ='01.09'!G41+COUNTIF(G$9:G$38,$C41) -> 2 | H41: ='01.09'!H41+COUNTIF(H$9:H$38,$C41) -> 3 | I41: ='01.09'!I41+COUNTIF(I$9:I$38,$C41) -> 3 | J41: ='01.09'!J41+COUNTIF(J$9:J$38,$C41) -> 3
...

Sheet 14.09
B1: Расписание учебных занятий на первое полугодие 2026-2027 учебного года
B2: ТРЕНЕРСКИЙ ФАКУЛЬТЕТ, направление подготовки (образовательная программа)
A3: 49.03.04 Спорт*
B4: Курс 4, семестр 7, очная форма обучения
B5: группы С3-10-23, С3-11-23, С3-12-23, С3-13-23, С3-14-23, С3-15-23, С3-16-23
A7: День недели | B7: Дата | C7: Время | D7: 10 группа | E7: 11 группа | F7: 12 группа | G7: 13 группа | H7: 14 группа | I7: 15 группа | J7: 16 группа
D8: танцевальный спорт, чир спорт | E8: фигурное катание на коньках, конькобежный спорт, шорт-трек, кёрлинг | F8: легкая атлетика | G8: плавание, синхронное плавание | H8: гребные и парусные виды спорта, циклические и сложнокоординационные виды лыжного спорта | I8: велосипедный спорт, триатлон, спортивная акробатика, прыжки на батуте, спортивная гимнастика, воздушно-силовая атлетика | J8: художественная гимнастика, эстетическая гимнастика, спортивная аэробика, фитнес аэробика
A9: Понедельник | B9: 46279 | C9: 8.50-10.20 | E9: Пр. Массаж Власова Н.А. 346мбк | H9: Пр. Основы медицинских знаний и спортивная медицина Тарасов А.В. 350мбк | I9: Пр. Теория и методика велосипедного спорта, триатлона, спортивной акробатики, прыжков на батуте, спортивной гимнастики, воздушно-силовой атлетики Прил.1 | J9: Пр. Теория и методика художественной гимнастики, эстетической гимнастики, спортивной аэробики, фитнес аэробики Прил.1
C10: 10.40-12.10 | E10: Пр. Основы медицинских знаний и спортивная медицина Тарасов А.В. 350мбк | F10: Пр. Теория и методика легкой атлетики Прил.1 | G10: Пр. Массаж Власова Н.А. 346мбк | H10: Пр. Правовые основы профессиональной деятельности Купцов Е.И. 401ауд.к. | I10: Пр. Теория и методика велосипедного спорта, триатлона, спортивной акробатики, прыжков на батуте, спортивной гимнастики, воздушно-силовой атлетики Прил.1 | J10: Пр. Теория и методика художественной гимнастики, эстетической гимнастики, спортивной аэробики, фитнес аэробики Прил.1
C11: 13.00-14.30 | D11: Пр. Основы медицинских знаний и спортивная медицина Тарасов А.В. 439мбк | E11: Пр. Правовые основы профессиональной деятельности Купцов Е.И. 401ауд.к. | F11: Пр. Теория и методика легкой атлетики Прил.1 | G11: Пр. Теория и методика плавания, синхронного плавания Прил. 1 | H11: Пр. Теория и методика циклических и сложнокоординационных видов лыжного спорта Прил.1 | I11: Пр. Массаж Саламатов М.Б. 346мбк | J11: Пр. Спортивная метрология Тарханов И.В. 69мбк
C12: 14.50-16.20 | D12: Пр. Правовые основы профессиональной деятельности Купцов Е.И. 401ауд.к. | G12: Пр. Теория и методика плавания, синхронного плавания Прил. 1 | H12: Пр. Теория и методика циклических и сложнокоординационных видов лыжного спорта Прил.1 | I12: Пр. Спортивная метрология Фураев А.Н. 69мбк | J12: Пр. Массаж Саламатов М.Б. 346мбк
C13: 16.40-18.10
A14: Вторник | B14: =B9+1 -> 46280 | C14: 8.50-10.20 | D14: Л. Спортивная метрология Тарханов И.В. 220 ауд.к. | E14: Л. Спортивная метрология Тарханов И.В. 220 ауд.к. | F14: Л. Спортивная метрология Тарханов И.В. 220 ауд.к. | G14: Л. Спортивная метрология Тарханов И.В. 220 ауд.к. | H14: Л. Спортивная метрология Тарханов И.В. 220 ауд.к. | I14: Л. Спортивная метрология Тарханов И.В. 220 ауд.к. | J14: Л. Спортивная метрология Тарханов И.В. 220 ауд.к.
C15: 10.40-12.10 | D15: Л. Правовые основы профессиональной деятельности Купцов Е.И. 220 ауд.к. | E15: Л. Правовые основы профессиональной деятельности Купцов Е.И. 220 ауд.к. | F15: Л. Правовые основы профессиональной деятельности Купцов Е.И. 220 ауд.к. | G15: Л. Правовые основы профессиональной деятельности Купцов Е.И. 220 ауд.к. | H15: Л. Правовые основы профессиональной деятельности Купцов Е.И. 220 ауд.к. | I15: Л. Правовые основы профессиональной деятельности Купцов Е.И. 220 ауд.к. | J15: Л. Правовые основы профессиональной деятельности Купцов Е.И. 220 ауд.к.
C16: 13.00-14.30 | D16: Пр. Массаж Власова Н.А. 346мбк | E16: Пр. Теория и методика фигурного катания на коньках, конькобежного спорта, шорт-трек, кёрлинга Прил.1 | G16: Пр. Теория и методика плавания, синхронного плавания Прил. 1 | H16: Пр. Теория и методика гребного и парусного видов спорта, Пр. Теория и методика циклических и сложнокоординационных видов лыжного спорта Прил.1 | I16: Пр. Правовые основы профессиональной деятельности Купцов Е.И. 401ауд.к. | J16: Пр. Основы медицинских знаний и спортивная медицина Тарасов А.В. 350мбк
C17: 14.50-16.20 | D17: Пр. Теория и методика танцевального спорта, чир спорта Прил. 1 | E17: Пр. Теория и методика фигурного катания на коньках, конькобежного спорта, шорт-трек, кёрлинга Прил.1 | G17: Пр. Теория и методика плавания, синхронного плавания Прил. 1 | H17: Пр. Теория и методика гребного и парусного видов спорта, Пр. Теория и методика циклических и сложнокоординационных видов лыжного спорта Прил.1 | I17: Пр. Основы медицинских знаний и спортивная медицина Тарасов А.В. 350мбк | J17: Пр. Правовые основы профессиональной деятельности Купцов Е.И. 401ауд.к.
C18: 16.40-18.10
A19: Среда | B19: =B14+1 -> 46281 | C19: 8.50-10.20 | E19: Пр. Основы медицинских знаний и спортивная медицина Тарасов А.В. 342мбк | F19: Пр. Массаж Власова Н.А. 346мбк | I19: Пр. Теория и методика велосипедного спорта, триатлона, спортивной акробатики, прыжков на батуте, спортивной гимнастики, воздушно-силовой атлетики Прил.1 | J19: Пр. Теория и методика художественной гимнастики, эстетической гимнастики, спортивной аэробики, фитнес аэробики Прил.1
C20: 10.40-12.10 | E20: Пр. Массаж Власова Н.А. 346мбк | F20: Пр. Основы медицинских знаний и спортивная медицина Тарасов А.В. 342мбк | I20: Пр. Теория и методика велосипедного спорта, триатлона, спортивной акробатики, прыжков на батуте, спортивной гимнастики, воздушно-силовой атлетики Прил.1 | J20: Пр. Теория и методика художественной гимнастики, эстетической гимнастики, спортивной аэробики, фитнес аэробики Прил.1
C21: 13.00-14.30 | D21: Л. Основы медицинских знаний и спортивная медицина Тарасов А.В. 220 ауд.к. | E21: Л. Основы медицинских знаний и спортивная медицина Тарасов А.В. 220 ауд.к. | F21: Л. Основы медицинских знаний и спортивная медицина Тарасов А.В. 220 ауд.к. | G21: Л. Основы медицинских знаний и спортивная медицина Тарасов А.В. 220 ауд.к. | H21: Л. Основы медицинских знаний и спортивная медицина Тарасов А.В. 220 ауд.к. | I21: Л. Основы медицинских знаний и спортивная медицина Тарасов А.В. 220 ауд.к. | J21: Л. Основы медицинских знаний и спортивная медицина Тарасов А.В. 220 ауд.к.
C22: 14.50-16.20 | D22: Л. Массаж Саламатов М.Б. 220 ауд.к. | E22: Л. Массаж Саламатов М.Б. 220 ауд.к. | F22: Л. Массаж Саламатов М.Б. 220 ауд.к. | G22: Л. Массаж Саламатов М.Б. 220 ауд.к. | H22: Л. Массаж Саламатов М.Б. 220 ауд.к. | I22: Л. Массаж Саламатов М.Б. 220 ауд.к. | J22: Л. Массаж Саламатов М.Б. 220 ауд.к.
C23: 16.40-18.10
A24: Четверг | B24: =B19+1 -> 46282 | C24: 8.50-10.20 | D24: Пр. Теория и методика танцевального спорта, чир спорта Прил. 1 | E24: Пр. Спортивная метрология Тарханов И.В. 68мбк | F24: Пр. Теория и методика легкой атлетики Прил.1 | G24: Пр. Основы медицинских знаний и спортивная медицина Тарасов А.В. 342мбк | H24: Пр. Массаж Ларин А.В. 346мбк | I24: Пр. Теория и методика велосипедного спорта, триатлона, спортивной акробатики, прыжков на батуте, спортивной гимнастики, воздушно-силовой атлетики Прил.1 | J24: Пр. Теория и методика художественной гимнастики, эстетической гимнастики, спортивной аэробики, фитнес аэробики Прил.1
C25: 10.40-12.10 | D25: Пр. Теория и методика танцевального спорта, чир спорта Прил. 1 | E25: Пр. Теория и методика фигурного катания на коньках, конькобежного спорта, шорт-трек, кёрлинга Прил.1 | F25: Пр. Массаж Власова Н.А. 346мбк | G25: Пр. Спортивная метрология Тарханов И.В. 68мбк | H25: Пр. Основы медицинских знаний и спортивная медицина Тарасов А.В. 342мбк | I25: Пр. Теория и методика велосипедного спорта, триатлона, спортивной акробатики, прыжков на батуте, спортивной гимнастики, воздушно-силовой атлетики Прил.1 | J25: Пр. Теория и методика художественной гимнастики, эстетической гимнастики, спортивной аэробики, фитнес аэробики Прил.1
C26: 13.00-14.30 | D26: Пр. Основы медицинских знаний и спортивная медицина Тарасов А.В. 445мбк | F26: Пр. Правовые основы профессиональной деятельности Купцов Е.И. 401 ауд.к. | G26: Пр. Массаж Власова Н.А. 346мбк | H26: Пр. Теория и методика гребного и парусного видов спорта, Л. Теория и методика циклических и сложнокоординационных видов лыжного спорта Прил.1
C27: 14.50-16.20 | D27: Пр. Массаж Власова Н.А. 346мбк | F27: Пр. Основы медицинских знаний и спортивная медицина Тарасов А.В. 445мбк | H27: Пр. Теория и методика гребного и парусного видов спорта, Пр. Теория и методика циклических и сложнокоординационных видов лыжного спорта Прил.1
C28: 16.40-18.10
A29: Пятница | B29: =B24+1 -> 46283 | C29: 8.50-10.20 | D29: Пр. Теория и методика танцевального спорта, чир спорта Прил. 1 | F29: Пр. Спортивная метрология Тарханов И.В. 68мбк | H29: Пр. Массаж Ларин А.В. 346мбк | J29: Пр. Основы медицинских знаний и спортивная медицина Тарасов А.В. 350мбк
C30: 10.40-12.10 | D30: Пр. Теория и методика танцевального спорта, чир спорта Прил. 1 | E30: Пр. Теория и методика фигурного катания на коньках, конькобежного спорта, шорт-трек, кёрлинга Прил.1 | F30: Пр. Теория и методика легкой атлетики Прил.1 | G30: Пр. Правовые основы профессиональной деятельности Купцов Е.И. 401 ауд.к. | H30: Пр. Спортивная метрология Фураев А.Н. 68мбк | J30: Пр. Массаж Саламатов М.Б. 346мбк
C31: 13.00-14.30 | D31: Пр. Спортивная метрология Тарханов И.В. 69мбк | E31: Пр. Теория и методика фигурного катания на коньках, конькобежного спорта, шорт-трек, кёрлинга Прил.1 | F31: Пр. Теория и методика легкой атлетики Прил.1 | G31: Пр. Теория и методика плавания, синхронного плавания Прил. 1 | H31: Пр. Теория и методика гребного и парусного видов спорта, Пр. Теория и методика циклических и сложнокоординационных видов лыжного спорта Прил.1 | I31: Пр. Основы медицинских знаний и спортивная медицина Тарасов А.В. 350мбк
C32: 14.50-16.20 | G32: Пр. Теория и методика плавания, синхронного плавания Прил. 1 | H32: Пр. Теория и методика гребного и парусного видов спорта, Пр. Теория и методика циклических и сложнокоординационных видов лыжного спорта Прил.1 | I32: Пр. Массаж Саламатов М.Б. 346мбк
C33: 16.40-18.10
A34: Суббота | B34: =B29+1 -> 46284 | C34: 8.50-10.20
C35: 10.40-12.10
C36: 13.00-14.30
C37: 14.50-16.20
C38: 16.40-18.10
D39: * Профили (направленность) указанны на титульном листе
C40: ='01.09'!C40 -> *Л. Основы медицинских знаний и спортивная медицина* | D40: ='07.09'!D40+COUNTIF(D$9:D$38,$C40) -> 3 | E40: ='07.09'!E40+COUNTIF(E$9:E$38,$C40) -> 3 | F40: ='07.09'!F40+COUNTIF(F$9:F$38,$C40) -> 3 | G40: ='07.09'!G40+COUNTIF(G$9:G$38,$C40) -> 3 | H40: ='07.09'!H40+COUNTIF(H$9:H$38,$C40) -> 3 | I40: ='07.09'!I40+COUNTIF(I$9:I$38,$C40) -> 3 | J40: ='07.09'!J40+COUNTIF(J$9:J$38,$C40) -> 3
C41: ='01.09'!C41 -> *Пр. Основы медицинских знаний и спортивная медицина* | D41: ='07.09'!D41+COUNTIF(D$9:D$38,$C41) -> 5 | E41: ='07.09'!E41+COUNTIF(E$9:E$38,$C41) -> 5 | F41: ='07.09'!F41+COUNTIF(F$9:F$38,$C41) -> 5 | G41: ='07.09'!G41+COUNTIF(G$9:G$38,$C41) -> 3 | H41: ='07.09'!H41+COUNTIF(H$9:H$38,$C41) -> 5 | I41: ='07.09'!I41+COUNTIF(I$9:I$38,$C41) -> 5 | J41: ='07.09'!J41+COUNTIF(J$9:J$38,$C41) -> 5
...

Sheet 21.09
B1: Расписание учебных занятий на первое полугодие 2026-2027 учебного года
B2: ТРЕНЕРСКИЙ ФАКУЛЬТЕТ, направление подготовки (образовательная программа)
A3: 49.03.04 Спорт*
B4: Курс 4, семестр 7, очная форма обучения
B5: группы С3-10-23, С3-11-23, С3-12-23, С3-13-23, С3-14-23, С3-15-23, С3-16-23
A7: День недели | B7: Дата | C7: Время | D7: 10 группа | E7: 11 группа | F7: 12 группа | G7: 13 группа | H7: 14 группа | I7: 15 группа | J7: 16 группа
D8: танцевальный спорт, чир спорт | E8: фигурное катание на коньках, конькобежный спорт, шорт-трек, кёрлинг | F8: легкая атлетика | G8: плавание, синхронное плавание | H8: гребные и парусные виды спорта, циклические и сложнокоординационные виды лыжного спорта | I8: велосипедный спорт, триатлон, спортивная акробатика, прыжки на батуте, спортивная гимнастика, воздушно-силовая атлетика | J8: художественная гимнастика, эстетическая гимнастика, спортивная аэробика, фитнес аэробика
A9: Понедельник | B9: 46286 | C9: 8.50-10.20 | E9: Пр. Массаж Власова Н.А. 346мбк | H9: Пр. Основы медицинских знаний и спортивная медицина Тарасов А.В. 350мбк | I9: Л. Теория и методика велосипедного спорта, триатлона, спортивной акробатики, прыжков на батуте, спортивной гимнастики, воздушно-силовой атлетики Прил.1 | J9: Л. Теория и методика художественной гимнастики, эстетической гимнастики, спортивной аэробики, фитнес аэробики Прил.1
C10: 10.40-12.10 | E10: Пр. Основы медицинских знаний и спортивная медицина Тарасов А.В. 350мбк | F10: Пр. Теория и методика легкой атлетики Прил.1 | G10: Пр. Массаж Власова Н.А. 346мбк | H10: Пр. Правовые основы профессиональной деятельности Купцов Е.И. 401ауд.к. | I10: Пр. Теория и методика велосипедного спорта, триатлона, спортивной акробатики, прыжков на батуте, спортивной гимнастики, воздушно-силовой атлетики Прил.1 | J10: Пр. Теория и методика художественной гимнастики, эстетической гимнастики, спортивной аэробики, фитнес аэробики Прил.1
C11: 13.00-14.30 | D11: Пр. Основы медицинских знаний и спортивная медицина Тарасов А.В. 439мбк | E11: Пр. Правовые основы профессиональной деятельности Купцов Е.И. 401ауд.к. | F11: Пр. Теория и методика легкой атлетики Прил.1 | G11: Пр. Теория и методика плавания, синхронного плавания Прил. 1 | I11: Пр. Массаж Саламатов М.Б. 346мбк | J11: Пр. Спортивная метрология Тарханов И.В. 68мбк
C12: 14.50-16.20 | D12: Пр. Правовые основы профессиональной деятельности Купцов Е.И. 401ауд.к. | G12: Пр. Теория и методика плавания, синхронного плавания Прил. 1 | I12: Пр. Спортивная метрология Фураев А.Н. 68мбк | J12: Пр. Массаж Саламатов М.Б. 346мбк
C13: 16.40-18.10
A14: Вторник | B14: =B9+1 -> 46287 | C14: 8.50-10.20 | D14: Л. Спортивная метрология Тарханов И.В. 220 ауд.к. | E14: Л. Спортивная метрология Тарханов И.В. 220 ауд.к. | F14: Л. Спортивная метрология Тарханов И.В. 220 ауд.к. | G14: Л. Спортивная метрология Тарханов И.В. 220 ауд.к. | H14: Л. Спортивная метрология Тарханов И.В. 220 ауд.к. | I14: Л. Спортивная метрология Тарханов И.В. 220 ауд.к. | J14: Л. Спортивная метрология Тарханов И.В. 220 ауд.к.
C15: 10.40-12.10 | D15: Л. Правовые основы профессиональной деятельности Купцов Е.И. 220 ауд.к. | E15: Л. Правовые основы профессиональной деятельности Купцов Е.И. 220 ауд.к. | F15: Л. Правовые основы профессиональной деятельности Купцов Е.И. 220 ауд.к. | G15: Л. Правовые основы профессиональной деятельности Купцов Е.И. 220 ауд.к. | H15: Л. Правовые основы профессиональной деятельности Купцов Е.И. 220 ауд.к. | I15: Л. Правовые основы профессиональной деятельности Купцов Е.И. 220 ауд.к. | J15: Л. Правовые основы профессиональной деятельности Купцов Е.И. 220 ауд.к.
C16: 13.00-14.30 | D16: Пр. Массаж Власова Н.А. 346мбк | E16: Пр. Теория и методика фигурного катания на коньках, конькобежного спорта, шорт-трек, кёрлинга Прил.1 | G16: Л. Теория и методика плавания, синхронного плавания Прил. 1 | H16: Л. Теория и методика гребного и парусного видов спорта, Пр. Теория и методика циклических и сложнокоординационных видов лыжного спорта Прил.1 | I16: Пр. Правовые основы профессиональной деятельности Купцов Е.И. 401ауд.к. | J16: Пр. Основы медицинских знаний и спортивная медицина Тарасов А.В. 350мбк
C17: 14.50-16.20 | D17: Пр. Теория и методика танцевального спорта, чир спорта Прил. 1 | E17: Л. Теория и методика фигурного катания на коньках, конькобежного спорта, шорт-трек, кёрлинга Прил.1 | G17: Пр. Теория и методика плавания, синхронного плавания Прил. 1 | H17: Пр. Теория и методика гребного и парусного видов спорта, Пр. Теория и методика циклических и сложнокоординационных видов лыжного спорта Прил.1 | I17: Пр. Основы медицинских знаний и спортивная медицина Тарасов А.В. 350мбк | J17: Пр. Правовые основы профессиональной деятельности Купцов Е.И. 401ауд.к.
C18: 16.40-18.10
A19: Среда | B19: =B14+1 -> 46288 | C19: 8.50-10.20 | E19: Пр. Основы медицинских знаний и спортивная медицина Тарасов А.В. 342мбк | F19: Пр. Массаж Власова Н.А. 346мбк | I19: Пр. Теория и методика велосипедного спорта, триатлона, спортивной акробатики, прыжков на батуте, спортивной гимнастики, воздушно-силовой атлетики Прил.1 | J19: Пр. Теория и методика художественной гимнастики, эстетической гимнастики, спортивной аэробики, фитнес аэробики Прил.1
C20: 10.40-12.10 | E20: Пр. Массаж Власова Н.А. 346мбк | F20: Пр. Основы медицинских знаний и спортивная медицина Тарасов А.В. 342мбк | I20: Пр. Теория и методика велосипедного спорта, триатлона, спортивной акробатики, прыжков на батуте, спортивной гимнастики, воздушно-силовой атлетики Прил.1 | J20: Пр. Теория и методика художественной гимнастики, эстетической гимнастики, спортивной аэробики, фитнес аэробики Прил.1
C21: 13.00-14.30 | D21: Л. Основы медицинских знаний и спортивная медицина Тарасов А.В. 220 ауд.к. | E21: Л. Основы медицинских знаний и спортивная медицина Тарасов А.В. 220 ауд.к. | F21: Л. Основы медицинских знаний и спортивная медицина Тарасов А.В. 220 ауд.к. | G21: Л. Основы медицинских знаний и спортивная медицина Тарасов А.В. 220 ауд.к. | H21: Л. Основы медицинских знаний и спортивная медицина Тарасов А.В. 220 ауд.к. | I21: Л. Основы медицинских знаний и спортивная медицина Тарасов А.В. 220 ауд.к. | J21: Л. Основы медицинских знаний и спортивная медицина Тарасов А.В. 220 ауд.к.
C22: 14.50-16.20 | D22: Л. Массаж Саламатов М.Б. 220 ауд.к. | E22: Л. Массаж Саламатов М.Б. 220 ауд.к. | F22: Л. Массаж Саламатов М.Б. 220 ауд.к. | G22: Л. Массаж Саламатов М.Б. 220 ауд.к. | H22: Л. Массаж Саламатов М.Б. 220 ауд.к. | I22: Л. Массаж Саламатов М.Б. 220 ауд.к. | J22: Л. Массаж Саламатов М.Б. 220 ауд.к.
C23: 16.40-18.10
A24: Четверг | B24: =B19+1 -> 46289 | C24: 8.50-10.20 | D24: Л. Теория и методика танцевального спорта, чир спорта Прил. 1 | E24: Пр. Спортивная метрология Тарханов И.В. 68мбк | F24: Л. Теория и методика легкой атлетики Прил.1 | G24: Пр. Основы медицинских знаний и спортивная медицина Тарасов А.В. 342мбк | H24: Пр. Массаж Ларин А.В. 346мбк | I24: Пр. Теория и методика велосипедного спорта, триатлона, спортивной акробатики, прыжков на батуте, спортивной гимнастики, воздушно-силовой атлетики Прил.1 | J24: Пр. Теория и методика художественной гимнастики, эстетической гимнастики, спортивной аэробики, фитнес аэробики Прил.1
C25: 10.40-12.10 | D25: Пр. Теория и методика танцевального спорта, чир спорта Прил. 1 | E25: Пр. Теория и методика фигурного катания на коньках, конькобежного спорта, шорт-трек, кёрлинга Прил.1 | F25: Пр. Массаж Власова Н.А. 346мбк | G25: Пр. Спортивная метрология Тарханов И.В. 68мбк | H25: Пр. Основы медицинских знаний и спортивная медицина Тарасов А.В. 342мбк | I25: Пр. Теория и методика велосипедного спорта, триатлона, спортивной акробатики, прыжков на батуте, спортивной гимнастики, воздушно-силовой атлетики Прил.1 | J25: Пр. Теория и методика художественной гимнастики, эстетической гимнастики, спортивной аэробики, фитнес аэробики Прил.1
C26: 13.00-14.30 | D26: Пр. Основы медицинских знаний и спортивная медицина Тарасов А.В. 445мбк | F26: Пр. Правовые основы профессиональной деятельности Купцов Е.И. 401 ауд.к. | G26: Пр. Массаж Власова Н.А. 346мбк | H26: Пр. Теория и методика гребного и парусного видов спорта, Пр. Теория и методика циклических и сложнокоординационных видов лыжного спорта Прил.1
C27: 14.50-16.20 | D27: Пр. Массаж Власова Н.А. 346мбк | F27: Пр. Основы медицинских знаний и спортивная медицина Тарасов А.В. 445мбк | H27: Пр. Теория и методика гребного и парусного видов спорта, Пр. Теория и методика циклических и сложнокоординационных видов лыжного спорта Прил.1
C28: 16.40-18.10
A29: Пятница | B29: =B24+1 -> 46290 | C29: 8.50-10.20 | D29: Пр. Теория и методика танцевального спорта, чир спорта Прил. 1 | F29: Пр. Спортивная метрология Тарханов И.В. 68мбк | H29: Пр. Массаж Ларин А.В. 346мбк | J29: Пр. Основы медицинских знаний и спортивная медицина Тарасов А.В. 350мбк
C30: 10.40-12.10 | D30: Пр. Теория и методика танцевального спорта, чир спорта Прил. 1 | E30: Пр. Теория и методика фигурного катания на коньках, конькобежного спорта, шорт-трек, кёрлинга Прил.1 | F30: Пр. Теория и методика легкой атлетики Прил.1 | G30: Пр. Правовые основы профессиональной деятельности Купцов Е.И. 401 ауд.к. | H30: Пр. Спортивная метрология Фураев А.Н. 68мбк | J30: Пр. Массаж Саламатов М.Б. 346мбк
C31: 13.00-14.30 | D31: Пр. Спортивная метрология Тарханов И.В. 69мбк | E31: Пр. Теория и методика фигурного катания на коньках, конькобежного спорта, шорт-трек, кёрлинга Прил.1 | F31: Пр. Теория и методика легкой атлетики Прил.1 | G31: Пр. Теория и методика плавания, синхронного плавания Прил. 1 | H31: Пр. Теория и методика гребного и парусного видов спорта, Пр. Теория и методика циклических и сложнокоординационных видов лыжного спорта Прил.1 | I31: Пр. Основы медицинских знаний и спортивная медицина Тарасов А.В. 350мбк
C32: 14.50-16.20 | G32: Пр. Теория и методика плавания, синхронного плавания Прил. 1 | H32: Пр. Теория и методика гребного и парусного видов спорта, Пр. Теория и методика циклических и сложнокоординационных видов лыжного спорта Прил.1 | I32: Пр. Массаж Саламатов М.Б. 346мбк
C33: 16.40-18.10
A34: Суббота | B34: =B29+1 -> 46291 | C34: 8.50-10.20
C35: 10.40-12.10
C36: 13.00-14.30
C37: 14.50-16.20
C38: 16.40-18.10
D39: * Профили (направленность) указанны на титульном листе
C40: ='01.09'!C40 -> *Л. Основы медицинских знаний и спортивная медицина* | D40: ='14.09'!D40+COUNTIF(D$9:D$38,$C40) -> 4 | E40: ='14.09'!E40+COUNTIF(E$9:E$38,$C40) -> 4 | F40: ='14.09'!F40+COUNTIF(F$9:F$38,$C40) -> 4 | G40: ='14.09'!G40+COUNTIF(G$9:G$38,$C40) -> 4 | H40: ='14.09'!H40+COUNTIF(H$9:H$38,$C40) -> 4 | I40: ='14.09'!I40+COUNTIF(I$9:I$38,$C40) -> 4 | J40: ='14.09'!J40+COUNTIF(J$9:J$38,$C40) -> 4
C41: ='01.09'!C41 -> *Пр. Основы медицинских знаний и спортивная медицина* | D41: ='14.09'!D41+COUNTIF(D$9:D$38,$C41) -> 7 | E41: ='14.09'!E41+COUNTIF(E$9:E$38,$C41) -> 7 | F41: ='14.09'!F41+COUNTIF(F$9:F$38,$C41) -> 7 | G41: ='14.09'!G41+COUNTIF(G$9:G$38,$C41) -> 4 | H41: ='14.09'!H41+COUNTIF(H$9:H$38,$C41) -> 7 | I41: ='14.09'!I41+COUNTIF(I$9:I$38,$C41) -> 7 | J41: ='14.09'!J41+COUNTIF(J$9:J$38,$C41) -> 7
...

Sheet 28.09
B1: Расписание учебных занятий на первое полугодие 2026-2027 учебного года
B2: ТРЕНЕРСКИЙ ФАКУЛЬТЕТ, направление подготовки (образовательная программа)
A3: 49.03.04 Спорт*
B4: Курс 4, семестр 7, очная форма обучения
B5: группы С3-10-23, С3-11-23, С3-12-23, С3-13-23, С3-14-23, С3-15-23, С3-16-23
A7: День недели | B7: Дата | C7: Время | D7: 10 группа | E7: 11 группа | F7: 12 группа | G7: 13 группа | H7: 14 группа | I7: 15 группа | J7: 16 группа
D8: танцевальный спорт, чир спорт | E8: фигурное катание на коньках, конькобежный спорт, шорт-трек, кёрлинг | F8: легкая атлетика | G8: плавание, синхронное плавание | H8: гребные и парусные виды спорта, циклические и сложнокоординационные виды лыжного спорта | I8: велосипедный спорт, триатлон, спортивная акробатика, прыжки на батуте, спортивная гимнастика, воздушно-силовая атлетика | J8: художественная гимнастика, эстетическая гимнастика, спортивная аэробика, фитнес аэробика
