Workbook
Name SIGN: #REF!
Name SIGN: #REF!
Name SIGN: #REF!
Name SIGN: #REF!
Name SIGN_D: #REF!
Name SIGN_D: #REF!
Name SIGN_D: #REF!
Name SIGN_D: #REF!
Name Sign1: #REF!
Name Sign1: #REF!
Name Sign1: #REF!
Name Sign1: #REF!
Name и: #REF!
Name и: #REF!
Name и: #REF!
Name и: #REF!
Name оо: #REF!
Name оо: #REF!
Name оо: #REF!
Name Р1: #REF!
Name Р1: #REF!
Name Р1: #REF!
Name Р1: #REF!
Name ыва: #REF!
Name ыва: #REF!
Name ыва: #REF!
Name ыва: #REF!

Sheet титульный лист

Sheet Титул
I1: УТВЕРЖДАЮ
I2: Начальник учебно-методического управления
I3: Р.С. Халимулина
I4: _________________________________
I5: «____»____________________20___г.
A7: Расписание учебных занятий на первое полугодие 2026-2027 учебного года
A8: ТРЕНЕРСКИЙ ФАКУЛЬТЕТ, направление подготовки (образовательная программа)
A9: 49.03.04 Спорт, Профиль (направленность): Спортивная подготовка по виду спорта «баскетбол». Педагогическая деятельность в области физической культуры и спорта; Спортивная подготовка по виду спорта «волейбол». Педагогическая деятельность в области физической культуры и спорта; Спортивная подготовка по видам спорта «гандбол», «бейсбол», «регби». Педагогическая деятельность в области физической культуры и спорта; Спортивная подготовка по виду спорта «компьютерный спорт». Педагогическая деятельность в области физической культуры и спорта; Спортивная подготовка по виду спорта «теннис». Педагогическая деятельность в области физической культуры и спорта; Спортивная подготовка по виду спорта «хоккей». Педагогическая деятельность в области физической культуры и спорта; Спортивная подготовка по виду спорта «футбол». Педагогическая деятельность в области физической культуры и спорта; Спортивная подготовка по видам спорта "настольный теннис", "бадминтон", "бильярд". Педагогическая деятельность в области физической культуры и спорта; Спортивная подготовка по виду спорта «гонки дронов (беспилотных воздушных судов)». Педагогическая деятельность в области физической культуры и спорта; уровень образования бакалавриат
B10: Курс 2, семестр 3, очная форма обучения
B11: группы С1-01А-25, С1-01Б-25, С1-02А-25, С1-02Б-25, С1-03-25, С1-04А-25, С1-04Б-25, С1-05А-25, С1-05Б-25
A12: № | B12: Наименование дисциплины (модуля), практика, научные исследования | C12: Кол-во часов (Л/П) | D12: Форма отчетности | E12: Учебные группы в соответствии с избранным видом спорта
E14: Баскетбол, гандбол, бейсбол, регби | F14: Волейбол, гонки дронов, компьютерный спорт | G14: Теннис, настольный теннис, бадминтон, бильярд | H14: Футбол | I14: Хоккей
E15: 1 группа | F15: 2 группа | G15: 3 группа | H15: 4 группа | I15: 5 группа
E16: Ф.И.О. преподавателя
A17: 1 | B17: Физиология человека | C17: 24/56 | D17: Экзамен | E17: Л - Ширяева Т.П.
E18: Белицкая Л.А., Колесник О.В. | F18: Белицкая Л.А., Ширяева Т.П. | G18: Колесник О.В. | H18: Белицкая Л.А., Андреева А.М. | I18: Ширяева Т.П., Андреева А.М.
A19: 2 | B19: Педагогика физической культуры и спорта | C19: 10/22 | D19: Экзамен | E19: Л - Цакаев С.Ш.
E20: Цакаев С.Ш. | F20: Цакаев С.Ш. | G20: Цакаев С.Ш. | H20: Цакаев С.Ш., Германов Г.Н. | I20: Цакаев С.Ш.
A21: 3 | B21: Теория и методика физической культуры | C21: 20/18 | D21: Зачет | E21: Л - Мачканова Е.В.
E22: Мачканова Е.В. | F22: Мачканова Е.В. | G22: Мачканова Е.В. | H22: Мачканова Е.В. | I22: Мачканова Е.В.
A23: 4 | B23: Плавание | C23: 4/60 | D23: Зачет | E23: Л - Никитина С.М.
E24: Шакина Е.Е., Чистова Н.А. | F24: Колесов А.Д., Павлова Т.Н. | G24: Шакина Е.Е. | H24: Никитина С.М. , Павлова Т.Н. | I24: Никитина С.М., Шакина Е.Е.
A25: 5 | B25: Подвижные игры в спорте и образовании | C25: 2/30 | D25: Зачет | E25: Л - Дробышевская Н.В.
E26: Дробышевская Н.В., Салахудинова Е.С. | F26: Дробышевская Н.В., Салахудинова Е.С. | G26: Дробышевская Н.В. | H26: Дробышевская Н.В., Кузьмичева Е.В. | I26: Дробышевская Н.В., Салахудинова Е.С.
A27: 6 | B27: Самооборона (самбо) | C27: 2/30 | D27: Зачет | E27: Л - Иванченко М.М.
E28: Махмудов М.М., Марянян С.А. | F28: Махмудов М.М., Иванченко М.М. | G28: Марянян С.А. | H28: Попов Д.В., Иванченко М.М. | I28: Попов Д.В., Иванченко М.М.
A29: 7 | B29: Методика преподавания предмета "физическая культура" в образовательных организациях | C29: 6/22 | D29: Б/о | E29: Л - Мачканова Е.В.
E30: Гасанова-Матвеева З.А. | F30: Гасанова-Матвеева З.А. | G30: Гасанова-Матвеева З.А. | H30: Трунева Т.В. | I30: Трунева Т.В.
A31: 8 | B31: Элективные дисциплины по ФКиС: Фехтование | C31: 2/18 | D31: Зачет | E31: Л - Моисеев А.Б.
E32: Моисеев А.Б., Полишките К. | F32: Моисеев А.Б., Полишките К. | G32: Полишките К. | H32: Моисеев А.Б., Полишките К. | I32: Моисеев А.Б., Полишките К.
A33: 9 | B33: Теория и методика избранного вида спорта | C33: 10/70 | D33: Зачет | E33: Баскетбол | F33: Волейбол | G33: Теннис | H33: Футбол | I33: Хоккей
E34: Л - Каменев А.В. | F34: Л - Ананьин А.С. | G34: Л - Степанова М.Е. | H34: Л - Шалыгин Д.А., Беляков А.К. | I34: Л - Крутских В.В.
E35: П - Каменев А.В., Сорокин С.А., Чернов С.В. | F35: П - Ананьин А.С., Суханова А.В. | G35: П - Степанова М.Е., Абитаев И.О. | H35: П - Лексаков А.В., Шалыгин Д.А., Макеев П.В., Беляков А.К. | I35: П - Крутских В.В., Руссу А.А.
E36: Гандбол, бейсбол, регби | F36: Гонки дронов (беспилотных воздушных судов) | G36: Настольный теннис, бадминтон
E37: Л - Чигарев Н.Н. | F37: Л - Новоселов М.А. | G37: Л - Лаптев А.И.
E38: П - Чигарев Н.Н. | F38: П - Зубов Д.А., Новоселов М.А. | G38: П - Лаптев А.И.
F39: Компьютерный спорт
F40: Л, П - Чигров А.С.
A41: 10 | B41: Методика реализации программ дополнительного образования в области физической культуры и спорта | C41: 6/22 | D41: Б/о | E41: Баскетбол | F41: Волейбол | G41: Теннис | H41: Футбол | I41: Хоккей
E42: Л - Каменев А.В. | F42: Л - Ананьин А.С. | G42: Л - Степанова М.Е. | H42: Л - Шалыгин Д.А. | I42: Л - Крутских В.В.
...

Sheet приложение1
A1: Приложение1 к расписанию учебных занятий на первое полугодие 2026-2027 учебного года
A2: ТРЕНЕРСКИЙ ФАКУЛЬТЕТ, направление подготовки (образовательная программа)
A3: 49.03.04 Спорт, Профиль (направленность): Спортивная подготовка по виду спорта «баскетбол». Педагогическая деятельность в области физической культуры и спорта; Спортивная подготовка по виду спорта «волейбол». Педагогическая деятельность в области физической культуры и спорта; Спортивная подготовка по видам спорта «гандбол», «бейсбол», «регби». Педагогическая деятельность в области физической культуры и спорта; Спортивная подготовка по виду спорта «компьютерный спорт». Педагогическая деятельность в области физической культуры и спорта; Спортивная подготовка по виду спорта «теннис». Педагогическая деятельность в области физической культуры и спорта; Спортивная подготовка по виду спорта «хоккей». Педагогическая деятельность в области физической культуры и спорта; Спортивная подготовка по виду спорта «футбол». Педагогическая деятельность в области физической культуры и спорта; Спортивная подготовка по видам спорта "настольный теннис", "бадминтон", "бильярд". Педагогическая деятельность в области физической культуры и спорта; Спортивная подготовка по виду спорта «гонки дронов (беспилотных воздушных судов)». Педагогическая деятельность в области физической культуры и спорта; уровень образования бакалавриат
A4: Курс 2, семестр 3, очная форма обучения
A5: группы С1-01А-25, С1-01Б-25, С1-02А-25, С1-02Б-25, С1-03-25, С1-04А-25, С1-04Б-25, С1-05А-25, С1-05Б-25
A6: № | B6: Наименование дисциплины (модуля): | C6: № аудитории
A7: 1 | B7: Теория и методика баскетбола, профессионально-спортивное совершенствование, методика реализации программ дополнительного образования в области физической культуры и спорта (баскетбол) | C7: 224СК, 238СК, ауд.№ 9-10СК
A8: 2 | B8: Теория и методика настольного тенниса, бадминтона, бильярда, профессионально-спортивное совершенствование, методика реализации программ дополнительного образования в области физической культуры и спорта (настольный теннис, бадминтон, бильярд) | C8: понедельник: 15 МБК, 223СК, Модуль Д; четверг: 15 МБК, 223СК
A9: 3 | B9: Теория и методика волейбола, профессионально-спортивное совершенствование, методика реализации программ дополнительного образования в области физической культуры и спорта (волейбол) | C9: 230СК, 54СК
A10: 4 | B10: Теория и методика гандбол, бейсбол, регби, профессионально-спортивное совершенствование, методика реализации программ дополнительного образования в области физической культуры и спорта (гандбол, бейсбол, регби) | C10: универсальный зал УСЗК, каб. 12 УСЗК
A11: 5 | B11: Теория и методика гонок дронов (беспилотных воздушных судов), профессионально-спортивное совершенствование, методика реализации программ дополнительного образования в области физической культуры и спорта (гонки дронов (беспилотных воздушных судов) | C11: 228 гл.к., л/а манеж, 217мбк
A12: 6 | B12: Теория и методика тенниса, профессионально-спортивное совершенствование,, методика реализации программ дополнительного образования в области физической культуры и спорта (теннис) | C12: Теннисный центр 1 и 2 корт
A13: 7 | B13: Теория и методика футбола, профессионально-спортивное совершенствование, методика реализации программ дополнительного образования в области физической культуры и спорта (футбол) | C13: 252СК, 61СК, 62СК, 65СК, открытый стадион
A14: 8 | B14: Теория и методика хоккея, профессионально-спортивное совершенствование, методика реализации программ дополнительного образования в области физической культуры и спорта (хоккей) | C14: ауд.9 УСЗК, ауд.16-17 УСЗК, Ледовая арена УСЗК
A15: 9 | B15: Теория и методика компьютерного спорта, профессионально-спортивное совершенствование, методика реализации программ дополнительного образования в области физической культуры и спорта (компьютерный спорт) | C15: 228 гл.к.
A16: Условные обозначения:
A17: УСЗК - универсальный спортивно-зрелищный комплекс
A18: МБК - медико-биологический корпус
A19: СК - спортивный корпус

Sheet расписание ПСС
F1: Расписание учебных занятий на первое полугодие 2026-2027 учебного года
F2: ТРЕНЕРСКИЙ ФАКУЛЬТЕТ, направление подготовки (образовательная программа)
A3: 49.03.04 Спорт, Профиль (направленность): Спортивная подготовка по виду спорта «баскетбол». Педагогическая деятельность в области физической культуры и спорта; Спортивная подготовка по виду спорта «волейбол». Педагогическая деятельность в области физической культуры и спорта; Спортивная подготовка по видам спорта «гандбол», «бейсбол», «регби». Педагогическая деятельность в области физической культуры и спорта; Спортивная подготовка по виду спорта «компьютерный спорт». Педагогическая деятельность в области физической культуры и спорта; Спортивная подготовка по виду спорта «теннис». Педагогическая деятельность в области физической культуры и спорта; Спортивная подготовка по виду спорта «хоккей». Педагогическая деятельность в области физической культуры и спорта; Спортивная подготовка по виду спорта «футбол». Педагогическая деятельность в области физической культуры и спорта; Спортивная подготовка по видам спорта "настольный теннис", "бадминтон", "бильярд". Педагогическая деятельность в области физической культуры и спорта; Спортивная подготовка по виду спорта «шахматы». Педагогическая деятельность в области физической культуры и спорта по 19.02; Спортивная подготовка по виду спорта «гонки дронов (беспилотных воздушных судов)». Педагогическая деятельность в области физической культуры и спорта; уровень образования бакалавриат
A4: Курс 2, семестр 3, очная форма обучения
A5: группы С1-01А-25, С1-01Б-25, С1-02А-25, С1-02Б-25, С1-03-25, С1-04А-25, С1-04Б-25, С1-05А-25, С1-05Б-25
A6: 01.09-26.12
A7: День недели | B7: Дата | C7: Время | D7: 1 группа | E7: 2 группа | F7: 3 группа | G7: 4 группа | H7: 5 группа
D8: Баскетбол, гандбол, бейсбол, регби | E8: Волейбол, гонки дронов, компьютерный спорт | F8: Теннис, настольный теннис, бадминтон, бильярд | G8: Футбол | H8: Хоккей
A9: Понедельник | C9: 8.50-10.20
C10: 10.40-12.10
C11: 13.00-14.30
C12: 14.50-16.20
C13: 16.40-18.10
C14: 18.30-20.00 | E14: ПСС Волейбол 18.00-19.30 230СК, 54СК
A15: Вторник | C15: 8.50-10.20
C16: 10.40-12.10
C17: 13.00-14.30 | F17: ПСС теннис 08.09-10.11 корт 1 и 2
C18: 14.50-16.20
C19: 16.40-18.10
C20: 18.30-20.00 | D20: ПСС баскетбол 224СК
C21: 20.20-21.50 | E21: ПСС гонки дронов 20.20-21.00- 228 гл.к., 21.00-21.50 - л/а манеж
A22: Среда | C22: 8.50-10.20
C23: 10.40-12.10
C24: 13.00-14.30
C25: 14.50-16.20
C26: 16.40-18.10 | H26: с 09.09 ПСС хоккей Ледовая площадка в УСЗК
C27: 20.20-21.50
A28: Четверг | C28: 8.50-10.20
C29: 10.40-12.10
C30: 13.00-14.30
C31: 14.50-16.20
C32: 16.40-18.10 | D32: ПСС гандбол 07.09 - 01.10 арена УСЗК / каб. 12 УСЗК
C33: 18.30-20.00
C34: 20.20-21.50
A35: Пятница | C35: 8.50-10.20
C36: 10.40-12.10
C37: 13.00-14.30
C38: 14.50-16.20
C39: 16.40-18.10 | E39: ПСС компьютерный спорт 228 гл.к.
A40: Суббота | C40: 8.50-10.20
...

Sheet Иностр язык(немец, рус)
F1: Расписание учебных занятий на первое полугодие 2026-2027 учебного года
F2: ТРЕНЕРСКИЙ ФАКУЛЬТЕТ, направление подготовки (образовательная программа)
B3: 49.03.04 Спорт, Профиль (направленность): Спортивная подготовка по виду спорта «баскетбол». Педагогическая деятельность в области физической культуры и спорта; Спортивная подготовка по виду спорта «волейбол». Педагогическая деятельность в области физической культуры и спорта; Спортивная подготовка по видам спорта «гандбол», «бейсбол», «регби». Педагогическая деятельность в области физической культуры и спорта; Спортивная подготовка по виду спорта «компьютерный спорт». Педагогическая деятельность в области физической культуры и спорта; Спортивная подготовка по виду спорта «теннис». Педагогическая деятельность в области физической культуры и спорта; Спортивная подготовка по виду спорта «хоккей». Педагогическая деятельность в области физической культуры и спорта; Спортивная подготовка по виду спорта «футбол». Педагогическая деятельность в области физической культуры и спорта; Спортивная подготовка по видам спорта "настольный теннис", "бадминтон", "бильярд". Педагогическая деятельность в области физической культуры и спорта; Спортивная подготовка по виду спорта «гонки дронов (беспилотных воздушных судов)». Педагогическая деятельность в области физической культуры и спорта; уровень образования бакалавриат
B4: Курс 2, семестр 3, очная форма обучения
B5: группы С1-01А-25, С1-01Б-25, С1-02А-25, С1-02Б-25, С1-03-25, С1-04А-25, С1-04Б-25, С1-05А-25, С1-05Б-25
A6: День недели | B6: Дата | C6: Время | D6: 1 группа | E6: 2 группа | F6: 3 группа | G6: 4 группа | H6: 5 группа
D7: Баскетбол, гандбол, бейсбол, регби | E7: Волейбол, шахматы по 19.02, гонки дронов, компьютерный спорт | F7: Теннис, настольный теннис, бадминтон, бильярд | G7: Футбол | H7: Хоккей
A8: Понедельник | C8: 8.50-10.20
C9: 10.40-12.10
C10: 13.00-14.30
C11: 14.50-16.20
C12: 16.40-18.10
A13: Вторник | C13: 8.50-10.20
C14: 10.40-12.10
C15: 13.00-14.30
C16: 14.50-16.20
C17: 16.40-18.10
A18: Среда | C18: 8.50-10.20
C19: 10.40-12.10
C20: 13.00-14.30
C21: 14.50-16.20
C22: 16.40-18.10
A23: Четверг | C23: 8.50-10.20
C24: 10.40-12.10
C25: 13.00-14.30
C26: 14.50-16.20
C27: 16.40-18.10
A28: Пятница | C28: 8.50-10.20
C29: 10.40-12.10
C30: 13.00-14.30
C31: 14.50-16.20
C32: 16.40-18.10
A33: Суббота | C33: 8.50-10.20
C34: 10.40-12.10
C35: 13.00-14.30
C36: 14.50-16.20
C37: 16.40-18.10

Sheet 01.09
B1: Расписание учебных занятий на первое полугодие 2026-2027 учебного года
B2: ТРЕНЕРСКИЙ ФАКУЛЬТЕТ, направление подготовки (образовательная программа)
A3: 49.03.04 Спорт, Профиль (направленность): Спортивная подготовка по виду спорта «баскетбол». Педагогическая деятельность в области физической культуры и спорта; Спортивная подготовка по виду спорта «волейбол». Педагогическая деятельность в области физической культуры и спорта; Спортивная подготовка по видам спорта «гандбол», «бейсбол», «регби». Педагогическая деятельность в области физической культуры и спорта; Спортивная подготовка по виду спорта «компьютерный спорт». Педагогическая деятельность в области физической культуры и спорта; Спортивная подготовка по виду спорта «теннис». Педагогическая деятельность в области физической культуры и спорта; Спортивная подготовка по виду спорта «хоккей». Педагогическая деятельность в области физической культуры и спорта; Спортивная подготовка по виду спорта «футбол». Педагогическая деятельность в области физической культуры и спорта; Спортивная подготовка по видам спорта "настольный теннис", "бадминтон", "бильярд". Педагогическая деятельность в области физической культуры и спорта; Спортивная подготовка по виду спорта «гонки дронов (беспилотных воздушных судов)». Педагогическая деятельность в области физической культуры и спорта; уровень образования бакалавриат
A4: Курс 2, семестр 3, очная форма обучения
A5: группы С1-01А-25, С1-01Б-25, С1-02А-25, С1-02Б-25, С1-03-25, С1-04А-25, С1-04Б-25, С1-05А-25, С1-05Б-25
A6: День недели | B6: Дата | C6: Время | D6: 1 группа | E6: 2 группа | F6: 3 группа | G6: 4 группа | H6: 5 группа
D7: Баскетбол, гандбол, бейсбол, регби | E7: Волейбол, гонки дронов, компьютерный спорт | F7: Теннис, настольный теннис, бадминтон, бильярд | G7: Футбол | H7: Хоккей
A8: Понедельник | B8: 46265 | C8: 8.50-10.20 | J8: Лекция. Информатика. Яшкина Е.Н. 277МБК
C9: 10.40-12.10 | J9: Пр. Информатика. Яшкина Е.Н. 277МБК
C10: 13.00-14.30 | J10: Лекция. Русский язык и культура речи. Гордиенко В.Е. | K10: 5лекций
C11: 14.50-16.20 | J11: Лекция. Русский язык и культура речи.Волкова М.С. | K11: 2лекции
C12: 16.40-18.10 | J12: Пр. Русский язык и культура речи. Уткина Е.Л. 410ауд.к | L12: 2группы
A13: Вторник | B13: =B8+1 -> 46266 | C13: 8.50-10.20 | J13: Пр. Русский язык и культура речи. Ишина Л.М. 409 ауд.к. | L13: 1группа
C14: 10.40-12.10 | D14: Л. Физиология человека Ширяева Т.П. 161 мбк | E14: Л. Физиология человека Ширяева Т.П. 161 мбк | F14: Л. Физиология человека Ширяева Т.П. 161 мбк | G14: Л. Физиология человека Ширяева Т.П. 161 мбк | H14: Л. Физиология человека Ширяева Т.П. 161 мбк | J14: Пр. Русский язык и культура речи. Гордиенко В.Е. 408 ауд.к. | L14: две гр
C15: 13.00-14.30 | D15: Л. Подвижные игры в спорте и образовании Дробышевская Н.В. 161 мбк | E15: Л. Подвижные игры в спорте и образовании Дробышевская Н.В. 161 мбк | F15: Л. Подвижные игры в спорте и образовании Дробышевская Н.В. 161 мбк | G15: Л. Подвижные игры в спорте и образовании Дробышевская Н.В. 161 мбк | H15: Л. Подвижные игры в спорте и образовании Дробышевская Н.В. 161 мбк | J15: Пр. Русский язык и культура речи. Капустина Ю.А. 409ауд.к. | L15: одна гр.
C16: 14.50-16.20 | D16: Л. Самооборона (самбо) Иванченко М.М. 161 мбк | E16: Л. Самооборона (самбо) Иванченко М.М. 161 мбк | F16: Л. Самооборона (самбо) Иванченко М.М. 161 мбк | G16: Л. Самооборона (самбо) Иванченко М.М. 161 мбк | H16: Л. Самооборона (самбо) Иванченко М.М. 161 мбк | J16: Лекция. Анатомия человека. Павлычева Л.А. 162 МБК | L16: 2,4,6 гр
C17: 16.40-18.10 | J17: Лекция. Анатомия человека. Титова Е.П. 161 МБК | L17: 1,5 гр
A18: Среда | B18: =B13+1 -> 46267 | C18: 8.50-10.20 | D18: Л. Плавание Никитина С.М. 220 ауд.к. | E18: Л. Плавание Никитина С.М. 220 ауд.к. | F18: Л. Плавание Никитина С.М. 220 ауд.к. | G18: Л. Плавание Никитина С.М. 220 ауд.к. | H18: Л. Плавание Никитина С.М. 220 ауд.к. | J18: Пр. Анатомия человека. Титова Е.П. 154МБК | L18: 1,5 гр
C19: 10.40-12.10 | D19: Л. Плавание Никитина С.М. 220 ауд.к. | E19: Л. Плавание Никитина С.М. 220 ауд.к. | F19: Л. Плавание Никитина С.М. 220 ауд.к. | G19: Л. Плавание Никитина С.М. 220 ауд.к. | H19: Л. Плавание Никитина С.М. 220 ауд.к. | J19: Пр. Анатомия человека. Павлычева Л.А. 131 МБК | L19: 2,4,6 гр
C20: 13.00-14.30 | H20: Л. Теория и методика хоккея Прил.1 | J20: Лекция. ТиМ избранного вида спорта. ауд.прил.1.
C21: 14.50-16.20 | H21: Пр. Теория и методика хоккея Прил.1 | J21: Пр. ТиМ избранного вида спорта. ауд.прил.1.
C22: 16.40-18.10 | J22: Лекция. Тяжелоатлетические виды спорта. Баюрин А.П.161МБК
A23: Четверг | B23: =B18+1 -> 46268 | C23: 8.50-10.20 | D23: Л. Теория и методика баскетбола, гандбола, бейсбола, регби Прил.1 | F23: Л. Теория и методика тенниса, настольного тенниса, бадминтона, бильярда Прил.1 | G23: Л. Теория и методика футбола Прил.1 | J23: Пр. Тяжелоатлетические виды спорта. Соловьев В.Б. ауд.прил.1.
C24: 10.40-12.10 | D24: Пр. Теория и методика баскетбола, гандбола, бейсбола, регби Прил.1 | F24: Пр. Теория и методика тенниса, настольного тенниса, бадминтона, бильярда Прил.1 | G24: Пр. Теория и методика футбола Прил.1 | J24: Лекция. Баскетбол. Андрющенко Л.Б.
C25: 13.00-14.30 | D25: Л. Педагогика физической культуры и спорта Цакаев С.Ш. 212 ауд.к. | E25: Л. Педагогика физической культуры и спорта Цакаев С.Ш. 212 ауд.к. | F25: Л. Педагогика физической культуры и спорта Цакаев С.Ш. 212 ауд.к. | G25: Л. Педагогика физической культуры и спорта Цакаев С.Ш. 212 ауд.к. | H25: Л. Педагогика физической культуры и спорта Цакаев С.Ш. 212 ауд.к. | J25: Пр. Баскетбол. Лосева И.В., Мартынова А.В., Никонов Д.Н., Лаптев С.О., Аверясова Ю.О.
C26: 14.50-16.20 | D26: Л. Физиология человека Ширяева Т.П. 212 ауд.к. | E26: Л. Физиология человека Ширяева Т.П. 212 ауд.к. | F26: Л. Физиология человека Ширяева Т.П. 212 ауд.к. | G26: Л. Физиология человека Ширяева Т.П. 212 ауд.к. | H26: Л. Физиология человека Ширяева Т.П. 212 ауд.к. | J26: Лекция . Лыжные гонки. Сенатская В.Г. 212ауд.к.
C27: 16.40-18.10 | J27: Пр. Лыжные гонки.
A28: Пятница | B28: =B23+1 -> 46269 | C28: 8.50-10.20 | J28: Пр. Гимнастика
C29: 10.40-12.10 | J29: Лекция. Физическая культура и спорт. Еремин М.В.
C30: 13.00-14.30 | E30: Л. Теория и методика волейбола, компьютерного спорта, гонок дронов Прил.1 | J30: Пр. Спортивно-педагогическое совершенствование. ауд.прил.1.
C31: 14.50-16.20 | E31: Пр. Теория и методика волейбола, компьютерного спорта, гонок дронов Прил.1 | J31: Пр. Элективные дисциплины по физ.культуре и спорту. Подвижные игры. Томашевич А.М. Модуль Д | K31: 1гр,3гр
C32: 16.40-18.10 | J32: Пр. Элективные дисциплины по физ.культуре и спорту. Подвижные игры.Салахудинова Е.С. Модуль Б | K32: 2гр.,4гр
A33: Суббота | B33: =B28+1 -> 46270 | C33: 8.50-10.20 | J33: Пр. Гимнастика
C34: 10.40-12.10 | J34: Лекция. Физическая культура и спорт. Еремин М.В.
C35: 13.00-14.30 | J35: Пр. Спортивно-педагогическое совершенствование. ауд.прил.1.
C36: 14.50-16.20 | J36: Пр. Элективные дисциплины по физ.культуре и спорту. Подвижные игры. Томашевич А.М. Модуль Д | K36: 1гр,3гр
C37: 16.40-18.10 | J37: Пр. Элективные дисциплины по физ.культуре и спорту. Подвижные игры.Салахудинова Е.С. Модуль Б | K37: 2гр.,4гр
B39: 24 | C39: *Л. Физиология человека* | D39: =COUNTIF(D$8:D$37,$C39) -> 2 | E39: =COUNTIF(E$8:E$37,$C39) -> 2 | F39: =COUNTIF(F$8:F$37,$C39) -> 2 | G39: =COUNTIF(G$8:G$37,$C39) -> 2 | H39: =COUNTIF(H$8:H$37,$C39) -> 2
B40: 56 | C40: *Пр. Физиология человека* | D40: =COUNTIF(D$8:D$37,$C40) -> 0 | E40: =COUNTIF(E$8:E$37,$C40) -> 0 | F40: =COUNTIF(F$8:F$37,$C40) -> 0 | G40: =COUNTIF(G$8:G$37,$C40) -> 0 | H40: =COUNTIF(H$8:H$37,$C40) -> 0
B41: 2 | C41: *Л. Элективные дисциплины по ФКиС: Фехтование* | D41: =COUNTIF(D$8:D$37,$C41) -> 0 | E41: =COUNTIF(E$8:E$37,$C41) -> 0 | F41: =COUNTIF(F$8:F$37,$C41) -> 0 | G41: =COUNTIF(G$8:G$37,$C41) -> 0 | H41: =COUNTIF(H$8:H$37,$C41) -> 0
...

Sheet 07.09
B1: Расписание учебных занятий на первое полугодие 2026-2027 учебного года
B2: ТРЕНЕРСКИЙ ФАКУЛЬТЕТ, направление подготовки (образовательная программа)
B3: 49.03.04 Спорт *
B4: Курс 2, семестр 3, очная форма обучения
A5: группы С1-01А-25, С1-01Б-25, С1-02А-25, С1-02Б-25, С1-03-25, С1-04А-25, С1-04Б-25, С1-05А-25, С1-05Б-25
A6: День недели | B6: Дата | C6: Время | D6: 1 группа | E6: 2 группа | F6: 3 группа | G6: 4 группа | H6: 5 группа
D7: Баскетбол, гандбол, бейсбол, регби | E7: Волейбол, гонки дронов, компьютерный спорт | F7: Теннис, настольный теннис, бадминтон, бильярд | G7: Футбол | H7: Хоккей
A8: Понедельник | B8: 46272 | C8: 8.50-10.20 | D8: Пр. Теория и методика гандбола, бейсбола, регби Прил.1 | F8: Пр. Теория и методика тенниса, настольного тенниса, бадминтона, бильярда Прил.1 | G8: Пр. Физиология человека Белицкая Л.А. 240мбк, Андреева А.М. 238мбк | H8: Пр. Подвижные игры в спорте и образовании Дробышевская Н.В., Салахудинова Е.С. Модуль Б
C9: 10.40-12.10 | D9: Пр. Теория и методика гандбола, бейсбола, регби Прил.1 | F9: Пр. Теория и методика тенниса, настольного тенниса, бадминтона, бильярда Прил.1 | G9: Пр. Подвижные игры в спорте и образовании Дробышевская Н.В., Кузьмичева Е.В. Модуль Б | H9: Пр. Физиология человека Ширяева Т.П. 237 мбк, Андреева А.М. 234мбк
C10: 13.00-14.30
C11: 14.50-16.20
C12: 16.40-18.10
A13: Вторник | B13: =B8+1 -> 46273 | C13: 8.50-10.20 | D13: Л. Теория и методика физической культуры Мачканова Е.В. 212 ауд.к. | E13: Л. Теория и методика физической культуры Мачканова Е.В. 212 ауд.к. | F13: Л. Теория и методика физической культуры Мачканова Е.В. 212 ауд.к. | G13: Л. Теория и методика физической культуры Мачканова Е.В. 212 ауд.к. | H13: Л. Теория и методика физической культуры Мачканова Е.В. 212 ауд.к.
C14: 10.40-12.10 | D14: Л. Физиология человека Ширяева Т.П. 212 ауд.к. | E14: Л. Физиология человека Ширяева Т.П. 212 ауд.к. | F14: Л. Физиология человека Ширяева Т.П. 212 ауд.к. | G14: Л. Физиология человека Ширяева Т.П. 212 ауд.к. | H14: Л. Физиология человека Ширяева Т.П. 212 ауд.к.
C15: 13.00-14.30 | D15: Пр. Подвижные игры в спорте и образовании Дробышевская Н.В., Салахудинова Е.С. Модуль Б | E15: Пр. Физиология человека Белицкая Л.А. 234мбк, Ширяева Т.П. 238 мбк | G15: Пр. Теория и методика футбола Прил.1 | H15: Пр. Теория и методика хоккея Прил.1
C16: 14.50-16.20 | E16: Пр. Подвижные игры в спорте и образовании Дробышевская Н.В., Салахудинова Е.С. Модуль Б | G16: Пр. Теория и методика футбола Прил.1 | H16: Пр. Теория и методика хоккея Прил.1
C17: 16.40-18.10
C18: 18.30-20.00
A19: Среда | B19: =B13+1 -> 46274 | C19: 8.50-10.20 | D19: Пр. Плавание Шакина Е.Е., Чистова Н.А. бассейн УСЗК | E19: Пр. Плавание Колесов А.Д., Павлова Т.Н. бассейн УСЗК | F19: Пр. Подвижные игры в спорте и образовании Дробышевская Н.В. Модуль Б
C20: 10.40-12.10 | D20: Пр. Плавание Шакина Е.Е., Чистова Н.А. бассейн УСЗК | E20: Пр. Плавание Колесов А.Д., Павлова Т.Н.. бассейн УСЗК | F20: Пр. Физиология человека Колесник О.В. 254мбк
C21: 13.00-14.30 | D21: Пр. Физиология человека Белицкая Л.А. 234мбк, Колесник О.В. 254мбк | F21: Пр. Самооборона (самбо) Марянян С.А. 14СК
C22: 14.50-16.20
C23: 16.40-18.10
A24: Четверг | B24: =B19+1 -> 46275 | C24: 8.50-10.20 | D24: Пр. Теория и методика баскетбола Прил.1 | E24: Пр. Физиология человека Белицкая Л.А. 234мбк, Ширяева Т.П. 254мбк | H24: Пр. Плавание Никитина С.М., Шакина Е.Е. бассейн УСЗК
C25: 10.40-12.10 | D25: Пр. Теория и методика баскетбола Прил.1 | E25: Пр. Самооборона (самбо) Махмудов М.М., Иванченко М.М. 14СК | H25: Пр. Плавание Никитина С.М., Шакина Е.Е. бассейн УСЗК
C26: 13.00-14.30 | D26: Л. Педагогика физической культуры и спорта Цакаев С.Ш. 212 ауд.к. | E26: Л. Педагогика физической культуры и спорта Цакаев С.Ш. 212 ауд.к. | F26: Л. Педагогика физической культуры и спорта Цакаев С.Ш. 212 ауд.к. | G26: Л. Педагогика физической культуры и спорта Цакаев С.Ш. 212 ауд.к. | H26: Л. Педагогика физической культуры и спорта Цакаев С.Ш. 212 ауд.к.
C27: 14.50-16.20 | D27: Л. Методика преподавания предмета "физическая культура" в образовательных организациях Мачканова Е.В. 212 ауд.к. | E27: Л. Методика преподавания предмета "физическая культура" в образовательных организациях Мачканова Е.В. 212 ауд.к. | F27: Л. Методика преподавания предмета "физическая культура" в образовательных организациях Мачканова Е.В. 212 ауд.к. | G27: Л. Методика преподавания предмета "физическая культура" в образовательных организациях Мачканова Е.В. 212 ауд.к. | H27: Л. Методика преподавания предмета "физическая культура" в образовательных организациях Мачканова Е.В. 212 ауд.к.
C28: 16.40-18.10
A29: Пятница | B29: =B24+1 -> 46276 | C29: 8.50-10.20 | D29: Пр. Самооборона (самбо) Махмудов М.М., Марянян С.А. 14СК | F29: Пр. Плавание Шакина Е.Е. бассейн УСЗК | G29: Пр. Плавание Никитина С.М. , Павлова Т.Н. бассейн УСЗК
C30: 10.40-12.10 | D30: Пр. Физиология человека Белицкая Л.А. 234мбк, Колесник О.В. 238мбк | F30: Пр. Плавание Шакина Е.Е. бассейн УСЗК | G30: Пр. Плавание Никитина С.М. , Павлова Т.Н. бассейн УСЗК
C31: 13.00-14.30 | E31: Пр. Теория и методика волейбола, компьютерного спорта, гонок дронов Прил.1 | F31: Пр. Физиология человека Колесник О.В. 254мбк | G31: Пр. Физиология человека Белицкая Л.А. 237мбк, Андреева А.М. 238мбк | H31: Пр. Самооборона (самбо) Попов Д.В., Иванченко М.М. 27СК
C32: 14.50-16.20 | E32: Пр. Теория и методика волейбола, компьютерного спорта, гонок дронов Прил.1 | G32: Пр. Самооборона (самбо) Попов Д.В., Иванченко М.М. 27СК | H32: Пр. Физиология человека Ширяева Т.П. 254мбк, Андреева А.М. 234мбк
C33: 16.40-18.10
A34: Суббота | B34: =B29+1 -> 46277 | C34: 8.50-10.20
C35: 10.40-12.10
C36: 13.00-14.30
C37: 14.50-16.20
C38: 16.40-18.10
D39: * Профили (направленность) указанны на титульном листе
C40: ='01.09'!C39 -> *Л. Физиология человека* | D40: ='01.09'!D39+COUNTIF(D$8:D$38,$C40) -> 3 | E40: ='01.09'!E39+COUNTIF(E$8:E$38,$C40) -> 3 | F40: ='01.09'!F39+COUNTIF(F$8:F$38,$C40) -> 3 | G40: ='01.09'!G39+COUNTIF(G$8:G$38,$C40) -> 3 | H40: ='01.09'!H39+COUNTIF(H$8:H$38,$C40) -> 3
...

Sheet 14.09
B1: Расписание учебных занятий на первое полугодие 2026-2027 учебного года
B2: ТРЕНЕРСКИЙ ФАКУЛЬТЕТ, направление подготовки (образовательная программа)
B3: 49.03.04 Спорт *
B4: Курс 2, семестр 3, очная форма обучения
A5: группы С1-01А-25, С1-01Б-25, С1-02А-25, С1-02Б-25, С1-03-25, С1-04А-25, С1-04Б-25, С1-05А-25, С1-05Б-25
A6: День недели | B6: Дата | C6: Время | D6: 1 группа | E6: 2 группа | F6: 3 группа | G6: 4 группа | H6: 5 группа
D7: Баскетбол, гандбол, бейсбол, регби | E7: Волейбол, гонки дронов, компьютерный спорт | F7: Теннис, настольный теннис, бадминтон, бильярд | G7: Футбол | H7: Хоккей
A8: Понедельник | B8: 46279 | C8: 8.50-10.20 | D8: Пр. Теория и методика гандбола, бейсбола, регби Прил.1 | E8: Пр. Теория и методика волейбола, гонок дронов Прил.1; Л. Методика реализации программ дополнительного образования в области ФКиС: компьютерный спорт Прил.1 | F8: Пр. Теория и методика тенниса, настольного тенниса, бадминтона, бильярда Прил.1 | G8: Пр. Физиология человека Белицкая Л.А. 240мбк, Андреева А.М. 238мбк | H8: Пр. Подвижные игры в спорте и образовании Дробышевская Н.В., Салахудинова Е.С. Модуль Б
C9: 10.40-12.10 | D9: Пр. Теория и методика гандбола, бейсбола, регби Прил.1 | E9: Пр. Теория и методика компьютерного спорта Прил.1; Л. Методика реализации программ дополнительного образования в области ФКиС: волейбол, гонки дронов Прил.1 | F9: Пр. Теория и методика тенниса, настольного тенниса, бадминтона, бильярда Прил.1 | G9: Пр. Подвижные игры в спорте и образовании Дробышевская Н.В., Кузьмичева Е.В. Модуль Б | H9: Пр. Физиология человека Ширяева Т.П. 254мбк, Андреева А.М. 234мбк
C10: 13.00-14.30 | D10: Пр. Теория и методика баскетбола Прил.1
C11: 14.50-16.20 | D11: Пр. Теория и методика баскетбола Прил.1
C12: 16.40-18.10
A13: Вторник | B13: =B8+1 -> 46280 | C13: 8.50-10.20 | D13: Л. Теория и методика физической культуры Мачканова Е.В. 212 ауд.к. | E13: Л. Теория и методика физической культуры Мачканова Е.В. 212 ауд.к. | F13: Л. Теория и методика физической культуры Мачканова Е.В. 212 ауд.к. | G13: Л. Теория и методика физической культуры Мачканова Е.В. 212 ауд.к. | H13: Л. Теория и методика физической культуры Мачканова Е.В. 212 ауд.к.
C14: 10.40-12.10 | D14: Л. Физиология человека Ширяева Т.П. 212 ауд.к. | E14: Л. Физиология человека Ширяева Т.П. 212 ауд.к. | F14: Л. Физиология человека Ширяева Т.П. 212 ауд.к. | G14: Л. Физиология человека Ширяева Т.П. 212 ауд.к. | H14: Л. Физиология человека Ширяева Т.П. 212 ауд.к.
C15: 13.00-14.30 | D15: Пр. Подвижные игры в спорте и образовании Дробышевская Н.В., Салахудинова Е.С. Модуль Б | E15: Пр. Физиология человека Белицкая Л.А. 234мбк, Ширяева Т.П. 254мбк | G15: Пр. Теория и методика футбола Прил.1 | H15: Пр. Теория и методика хоккея Прил.1
C16: 14.50-16.20 | E16: Пр. Подвижные игры в спорте и образовании Дробышевская Н.В., Салахудинова Е.С. Модуль Б | G16: Пр. Теория и методика футбола Прил.1 | H16: Л. Методика реализации программ дополнительного образования в области ФКиС Прил.1
C17: 16.40-18.10
C18: 18.30-20.00
A19: Среда | B19: =B13+1 -> 46281 | C19: 8.50-10.20 | D19: Пр. Плавание Шакина Е.Е., Чистова Н.А. бассейн УСЗК | E19: Пр. Плавание Колесов А.Д., Павлова Т.Н. бассейн УСЗК | F19: Пр. Подвижные игры в спорте и образовании Дробышевская Н.В. Модуль Б
C20: 10.40-12.10 | D20: Пр. Плавание Шакина Е.Е., Чистова Н.А. бассейн УСЗК | E20: Пр. Плавание Колесов А.Д., Павлова Т.Н.. бассейн УСЗК | F20: Пр. Физиология человека Колесник О.В. 254мбк
C21: 13.00-14.30 | D21: Пр. Физиология человека Белицкая Л.А. 234мбк, Колесник О.В. 254мбк | F21: Пр. Самооборона (самбо) Марянян С.А. 14СК | H21: Пр. Теория и методика хоккея Прил.1
C22: 14.50-16.20 | D22: Л. Теория и методика гандбола, бейсбола, регби Прил.1 | H22: Л. Теория и методика хоккея Прил.1
C23: 16.40-18.10
A24: Четверг | B24: =B19+1 -> 46282 | C24: 8.50-10.20 | D24: Л. Теория и методика баскетбола Прил.1 | E24: Пр. Физиология человека Белицкая Л.А. 234мбк, Ширяева Т.П. 254мбк | F24: Л. Теория и методика тенниса, настольного тенниса, бадминтона, бильярда Прил.1 | G24: Л. Методика реализации программ дополнительного образования в области ФКиС Прил.1 | H24: Пр. Плавание Никитина С.М., Шакина Е.Е. бассейн УСЗК
C25: 10.40-12.10 | D25: Л. Методика реализации программ дополнительного образования в области ФКиС Прил.1 | E25: Пр. Самооборона (самбо) Махмудов М.М., Иванченко М.М. 14СК | F25: Л. Методика реализации программ дополнительного образования в области ФКиС Прил.1 | G25: Л. Теория и методика футбола Прил.1 | H25: Пр. Плавание Никитина С.М., Шакина Е.Е. бассейн УСЗК
C26: 13.00-14.30 | D26: Л. Педагогика физической культуры и спорта Цакаев С.Ш. 212 ауд.к. | E26: Л. Педагогика физической культуры и спорта Цакаев С.Ш. 212 ауд.к. | F26: Л. Педагогика физической культуры и спорта Цакаев С.Ш. 212 ауд.к. | G26: Л. Педагогика физической культуры и спорта Цакаев С.Ш. 212 ауд.к. | H26: Л. Педагогика физической культуры и спорта Цакаев С.Ш. 212 ауд.к.
C27: 14.50-16.20 | D27: Л. Методика преподавания предмета "физическая культура" в образовательных организациях Мачканова Е.В. 212 ауд.к. | E27: Л. Методика преподавания предмета "физическая культура" в образовательных организациях Мачканова Е.В. 212 ауд.к. | F27: Л. Методика преподавания предмета "физическая культура" в образовательных организациях Мачканова Е.В. 212 ауд.к. | G27: Л. Методика преподавания предмета "физическая культура" в образовательных организациях Мачканова Е.В. 212 ауд.к. | H27: Л. Методика преподавания предмета "физическая культура" в образовательных организациях Мачканова Е.В. 212 ауд.к.
C28: 16.40-18.10
A29: Пятница | B29: =B24+1 -> 46283 | C29: 8.50-10.20 | D29: Пр. Самооборона (самбо) Махмудов М.М., Марянян С.А. 14СК | F29: Пр. Плавание Шакина Е.Е. бассейн УСЗК | G29: Пр. Плавание Никитина С.М. , Павлова Т.Н. бассейн УСЗК
C30: 10.40-12.10 | D30: Пр. Физиология человека Белицкая Л.А. 234мбк, Колесник О.В. 238мбк | F30: Пр. Плавание Шакина Е.Е. бассейн УСЗК | G30: Пр. Плавание Никитина С.М. , Павлова Т.Н. бассейн УСЗК
C31: 13.00-14.30 | E31: Пр. Теория и методика волейбола, компьютерного спорта, гонок дронов Прил.1 | F31: Пр. Физиология человека Колесник О.В. 254мбк | G31: Пр. Физиология человека Белицкая Л.А. 237мбк, Андреева А.М. 238мбк | H31: Пр. Самооборона (самбо) Попов Д.В., Иванченко М.М. 27СК
C32: 14.50-16.20 | E32: Л. Теория и методика волейбола, компьютерного спорта, гонок дронов Прил.1 | G32: Пр. Самооборона (самбо) Попов Д.В., Иванченко М.М. 27СК | H32: Пр. Физиология человека Ширяева Т.П. 254мбк, Андреева А.М. 234мбк
C33: 16.40-18.10
A34: Суббота | B34: =B29+1 -> 46284 | C34: 8.50-10.20
C35: 10.40-12.10
C36: 13.00-14.30
C37: 14.50-16.20
C38: 16.40-18.10
D39: * Профили (направленность) указанны на титульном листе
C40: ='01.09'!C39 -> *Л. Физиология человека* | D40: ='07.09'!D40+COUNTIF(D$8:D$38,$C40) -> 4 | E40: ='07.09'!E40+COUNTIF(E$8:E$38,$C40) -> 4 | F40: ='07.09'!F40+COUNTIF(F$8:F$38,$C40) -> 4 | G40: ='07.09'!G40+COUNTIF(G$8:G$38,$C40) -> 4 | H40: ='07.09'!H40+COUNTIF(H$8:H$38,$C40) -> 4
...

Sheet 21.09
B1: Расписание учебных занятий на первое полугодие 2026-2027 учебного года
B2: ТРЕНЕРСКИЙ ФАКУЛЬТЕТ, направление подготовки (образовательная программа)
B3: 49.03.04 Спорт *
B4: Курс 2, семестр 3, очная форма обучения
A5: группы С1-01А-25, С1-01Б-25, С1-02А-25, С1-02Б-25, С1-03-25, С1-04А-25, С1-04Б-25, С1-05А-25, С1-05Б-25
A6: День недели | B6: Дата | C6: Время | D6: 1 группа | E6: 2 группа | F6: 3 группа | G6: 4 группа | H6: 5 группа
D7: Баскетбол, гандбол, бейсбол, регби | E7: Волейбол, гонки дронов, компьютерный спорт | F7: Теннис, настольный теннис, бадминтон, бильярд | G7: Футбол | H7: Хоккей
A8: Понедельник | B8: 46286 | C8: 8.50-10.20 | D8: Л. Теория и методика гандбола, бейсбола, регби Прил.1 | E8: Л. Теория и методика волейбола, гонок дронов Прил.1; Л. Методика реализации программ дополнительного образования в области ФКиС: компьютерный спорт Прил.1 | F8: Л. Теория и методика тенниса, настольного тенниса, бадминтона, бильярда Прил.1 | G8: Пр. Физиология человека Белицкая Л.А. 240мбк, Андреева А.М. 238мбк | H8: Пр. Подвижные игры в спорте и образовании Дробышевская Н.В., Салахудинова Е.С. Модуль Б
C9: 10.40-12.10 | D9: Пр. Теория и методика гандбола, бейсбола, регби Прил.1 | E9: Л. Теория и методика компьютерного спорта Прил.1; Л. Методика реализации программ дополнительного образования в области ФКиС: волейбол, гонки дронов Прил.1 | F9: Пр. Теория и методика тенниса, настольного тенниса, бадминтона, бильярда Прил.1 | G9: Пр. Подвижные игры в спорте и образовании Дробышевская Н.В., Кузьмичева Е.В. Модуль Б | H9: Пр. Физиология человека Ширяева Т.П. 254мбк, Андреева А.М. 234мбк
C10: 13.00-14.30 | D10: Л. Теория и методика баскетбола Прил.1
C11: 14.50-16.20 | D11: Пр. Теория и методика баскетбола Прил.1
C12: 16.40-18.10
A13: Вторник | B13: =B8+1 -> 46287 | C13: 8.50-10.20 | D13: Л. Теория и методика физической культуры Мачканова Е.В. 212 ауд.к. | E13: Л. Теория и методика физической культуры Мачканова Е.В. 212 ауд.к. | F13: Л. Теория и методика физической культуры Мачканова Е.В. 212 ауд.к. | G13: Л. Теория и методика физической культуры Мачканова Е.В. 212 ауд.к. | H13: Л. Теория и методика физической культуры Мачканова Е.В. 212 ауд.к.
C14: 10.40-12.10 | D14: Л. Физиология человека Ширяева Т.П. 212 ауд.к. | E14: Л. Физиология человека Ширяева Т.П. 212 ауд.к. | F14: Л. Физиология человека Ширяева Т.П. 212 ауд.к. | G14: Л. Физиология человека Ширяева Т.П. 212 ауд.к. | H14: Л. Физиология человека Ширяева Т.П. 212 ауд.к.
C15: 13.00-14.30 | D15: Пр. Подвижные игры в спорте и образовании Дробышевская Н.В., Салахудинова Е.С. Модуль Б | E15: Пр. Физиология человека Белицкая Л.А. 234мбк, Ширяева Т.П. 254мбк | G15: Л. Теория и методика футбола Прил.1 | H15: Л. Теория и методика хоккея Прил.1
C16: 14.50-16.20 | E16: Пр. Подвижные игры в спорте и образовании Дробышевская Н.В., Салахудинова Е.С. Модуль Б | G16: Пр. Теория и методика футбола Прил.1 | H16: Л. Методика реализации программ дополнительного образования в области ФКиС Прил.1
C17: 16.40-18.10
C18: 18.30-20.00
A19: Среда | B19: =B13+1 -> 46288 | C19: 8.50-10.20 | D19: Пр. Плавание Шакина Е.Е., Чистова Н.А. бассейн УСЗК | E19: Пр. Плавание Колесов А.Д., Павлова Т.Н. бассейн УСЗК | F19: Пр. Подвижные игры в спорте и образовании Дробышевская Н.В. Модуль Б
C20: 10.40-12.10 | D20: Пр. Плавание Шакина Е.Е., Чистова Н.А. бассейн УСЗК | E20: Пр. Плавание Колесов А.Д., Павлова Т.Н.. бассейн УСЗК | F20: Пр. Физиология человека Колесник О.В. 254мбк
C21: 13.00-14.30 | D21: Пр. Физиология человека Белицкая Л.А. 234мбк, Колесник О.В. 254мбк | F21: Пр. Самооборона (самбо) Марянян С.А. 14СК | H21: Пр. Теория и методика хоккея Прил.1
C22: 14.50-16.20 | D22: Пр. Теория и методика гандбола, бейсбола, регби Прил.1 | H22: Пр. Теория и методика хоккея Прил.1
C23: 16.40-18.10
A24: Четверг | B24: =B19+1 -> 46289 | C24: 8.50-10.20 | D24: Пр. Теория и методика баскетбола Прил.1 | E24: Пр. Физиология человека Белицкая Л.А. 234мбк, Ширяева Т.П. 254мбк | F24: Л. Методика реализации программ дополнительного образования в области ФКиС Прил.1 | G24: Л. Методика реализации программ дополнительного образования в области ФКиС Прил.1 | H24: Пр. Плавание Никитина С.М., Шакина Е.Е. бассейн УСЗК
C25: 10.40-12.10 | D25: Л. Методика реализации программ дополнительного образования в области ФКиС Прил.1 | E25: Пр. Самооборона (самбо) Махмудов М.М., Иванченко М.М. 14СК | F25: Пр. Теория и методика тенниса, настольного тенниса, бадминтона, бильярда Прил.1 | G25: Пр. Теория и методика футбола Прил.1 | H25: Пр. Плавание Никитина С.М., Шакина Е.Е. бассейн УСЗК
C26: 13.00-14.30 | D26: Л. Педагогика физической культуры и спорта Цакаев С.Ш. 212 ауд.к. | E26: Л. Педагогика физической культуры и спорта Цакаев С.Ш. 212 ауд.к. | F26: Л. Педагогика физической культуры и спорта Цакаев С.Ш. 212 ауд.к. | G26: Л. Педагогика физической культуры и спорта Цакаев С.Ш. 212 ауд.к. | H26: Л. Педагогика физической культуры и спорта Цакаев С.Ш. 212 ауд.к.
C27: 14.50-16.20 | D27: Л. Методика преподавания предмета "физическая культура" в образовательных организациях Мачканова Е.В. 212 ауд.к. | E27: Л. Методика преподавания предмета "физическая культура" в образовательных организациях Мачканова Е.В. 212 ауд.к. | F27: Л. Методика преподавания предмета "физическая культура" в образовательных организациях Мачканова Е.В. 212 ауд.к. | G27: Л. Методика преподавания предмета "физическая культура" в образовательных организациях Мачканова Е.В. 212 ауд.к. | H27: Л. Методика преподавания предмета "физическая культура" в образовательных организациях Мачканова Е.В. 212 ауд.к.
C28: 16.40-18.10
A29: Пятница | B29: =B24+1 -> 46290 | C29: 8.50-10.20 | D29: Пр. Самооборона (самбо) Махмудов М.М., Марянян С.А. 14СК | F29: Пр. Плавание Шакина Е.Е. бассейн УСЗК | G29: Пр. Плавание Никитина С.М. , Павлова Т.Н. бассейн УСЗК
C30: 10.40-12.10 | D30: Пр. Физиология человека Белицкая Л.А. 234мбк, Колесник О.В. 238мбк | F30: Пр. Плавание Шакина Е.Е. бассейн УСЗК | G30: Пр. Плавание Никитина С.М. , Павлова Т.Н. бассейн УСЗК
C31: 13.00-14.30 | E31: Пр. Теория и методика волейбола, компьютерного спорта, гонок дронов Прил.1 | F31: Пр. Физиология человека Колесник О.В. 254мбк | G31: Пр. Физиология человека Белицкая Л.А. 237мбк, Андреева А.М. 238мбк | H31: Пр. Самооборона (самбо) Попов Д.В., Иванченко М.М. 27СК
C32: 14.50-16.20 | E32: Пр. Теория и методика волейбола, компьютерного спорта, гонок дронов Прил.1 | G32: Пр. Самооборона (самбо) Попов Д.В., Иванченко М.М. 27СК | H32: Пр. Физиология человека Ширяева Т.П. 254мбк, Андреева А.М. 234мбк
C33: 16.40-18.10
A34: Суббота | B34: =B29+1 -> 46291 | C34: 8.50-10.20
C35: 10.40-12.10
C36: 13.00-14.30
C37: 14.50-16.20
C38: 16.40-18.10
D39: * Профили (направленность) указанны на титульном листе
C40: ='01.09'!C39 -> *Л. Физиология человека* | D40: ='14.09'!D40+COUNTIF(D$8:D$38,$C40) -> 5 | E40: ='14.09'!E40+COUNTIF(E$8:E$38,$C40) -> 5 | F40: ='14.09'!F40+COUNTIF(F$8:F$38,$C40) -> 5 | G40: ='14.09'!G40+COUNTIF(G$8:G$38,$C40) -> 5 | H40: ='14.09'!H40+COUNTIF(H$8:H$38,$C40) -> 5
...

Sheet 28.09
B1: Расписание учебных занятий на первое полугодие 2026-2027 учебного года
B2: ТРЕНЕРСКИЙ ФАКУЛЬТЕТ, направление подготовки (образовательная программа)
B3: 49.03.04 Спорт *
B4: Курс 2, семестр 3, очная форма обучения
A5: группы С1-01А-25, С1-01Б-25, С1-02А-25, С1-02Б-25, С1-03-25, С1-04А-25, С1-04Б-25, С1-05А-25, С1-05Б-25
A6: День недели | B6: Дата | C6: Время | D6: 1 группа | E6: 2 группа | F6: 3 группа | G6: 4 группа | H6: 5 группа
D7: Баскетбол, гандбол, бейсбол, регби | E7: Волейбол, гонки дронов, компьютерный спорт | F7: Теннис, настольный теннис, бадминтон, бильярд | G7: Футбол | H7: Хоккей
A8: Понедельник | B8: 46293 | C8: 8.50-10.20 | D8: Пр. Теория и методика гандбола, бейсбола, регби Прил.1 | E8: Пр. Теория и методика волейбола, гонок дронов Прил.1; Л. Методика реализации программ дополнительного образования в области ФКиС: компьютерный спорт Прил.1 | F8: Пр. Теория и методика тенниса, настольного тенниса, бадминтона, бильярда Прил.1 | G8: Пр. Физиология человека Белицкая Л.А. 240мбк, Андреева А.М. 238мбк | H8: Пр. Подвижные игры в спорте и образовании Дробышевская Н.В., Салахудинова Е.С. Модуль Б
C9: 10.40-12.10 | D9: Пр. Теория и методика гандбола, бейсбола, регби Прил.1 | E9: Пр. Теория и методика компьютерного спорта Прил.1; Л. Методика реализации программ дополнительного образования в области ФКиС: волейбол, гонки дронов Прил.1 | F9: Пр. Теория и методика тенниса, настольного тенниса, бадминтона, бильярда Прил.1 | G9: Пр. Подвижные игры в спорте и образовании Дробышевская Н.В., Кузьмичева Е.В. Модуль Б | H9: Пр. Физиология человека Ширяева Т.П. 254мбк, Андреева А.М. 234мбк
C10: 13.00-14.30 | D10: Пр. Теория и методика баскетбола Прил.1
C11: 14.50-16.20 | D11: Пр. Теория и методика баскетбола Прил.1
C12: 16.40-18.10
A13: Вторник | B13: =B8+1 -> 46294 | C13: 8.50-10.20 | D13: Л. Теория и методика физической культуры Мачканова Е.В. 212 ауд.к. | E13: Л. Теория и методика физической культуры Мачканова Е.В. 212 ауд.к. | F13: Л. Теория и методика физической культуры Мачканова Е.В. 212 ауд.к. | G13: Л. Теория и методика физической культуры Мачканова Е.В. 212 ауд.к. | H13: Л. Теория и методика физической культуры Мачканова Е.В. 212 ауд.к.
C14: 10.40-12.10 | D14: Л. Физиология человека Ширяева Т.П. 212 ауд.к. | E14: Л. Физиология человека Ширяева Т.П. 212 ауд.к. | F14: Л. Физиология человека Ширяева Т.П. 212 ауд.к. | G14: Л. Физиология человека Ширяева Т.П. 212 ауд.к. | H14: Л. Физиология человека Ширяева Т.П. 212 ауд.к.
C15: 13.00-14.30 | D15: Пр. Подвижные игры в спорте и образовании Дробышевская Н.В., Салахудинова Е.С. Модуль Б | E15: Пр. Физиология человека Белицкая Л.А. 234мбк, Ширяева Т.П. 254мбк | G15: Пр. Теория и методика футбола Прил.1 | H15: Пр. Теория и методика хоккея Прил.1
C16: 14.50-16.20 | E16: Пр. Подвижные игры в спорте и образовании Дробышевская Н.В., Салахудинова Е.С. Модуль Б | G16: Пр. Теория и методика футбола Прил.1 | H16: Л. Методика реализации программ дополнительного образования в области ФКиС Прил.1
C17: 16.40-18.10
C18: 18.30-20.00
A19: Среда | B19: =B13+1 -> 46295 | C19: 8.50-10.20 | D19: Пр. Плавание Шакина Е.Е., Чистова Н.А. бассейн УСЗК | E19: Пр. Плавание Колесов А.Д., Павлова Т.Н. бассейн УСЗК | F19: Пр. Подвижные игры в спорте и образовании Дробышевская Н.В. Модуль Б
C20: 10.40-12.10 | D20: Пр. Плавание Шакина Е.Е., Чистова Н.А. бассейн УСЗК | E20: Пр. Плавание Колесов А.Д., Павлова Т.Н.. бассейн УСЗК | F20: Пр. Физиология человека Колесник О.В. 254мбк
C21: 13.00-14.30 | D21: Пр. Физиология человека Белицкая Л.А. 234мбк, Колесник О.В. 254мбк | F21: Пр. Самооборона (самбо) Марянян С.А. 14СК | H21: Пр. Теория и методика хоккея Прил.1
C22: 14.50-16.20 | D22: Пр. Теория и методика гандбола, бейсбола, регби Прил.1 | H22: Пр. Теория и методика хоккея Прил.1
C23: 16.40-18.10
A24: Четверг | B24: =B19+1 -> 46296 | C24: 8.50-10.20 | D24: Пр. Теория и методика баскетбола Прил.1 | E24: Пр. Физиология человека Белицкая Л.А. 234мбк, Ширяева Т.П. 254мбк | F24: Л. Методика реализации программ дополнительного образования в области ФКиС Прил.1 | G24: Л. Методика реализации программ дополнительного образования в области ФКиС Прил.1 | H24: Пр. Плавание Никитина С.М., Шакина Е.Е. бассейн УСЗК
C25: 10.40-12.10 | D25: Л. Методика реализации программ дополнительного образования в области ФКиС Прил.1 | E25: Пр. Самооборона (самбо) Махмудов М.М., Иванченко М.М. 14СК | F25: Пр. Теория и методика тенниса, настольного тенниса, бадминтона, бильярда Прил.1 | G25: Пр. Теория и методика футбола Прил.1 | H25: Пр. Плавание Никитина С.М., Шакина Е.Е. бассейн УСЗК
C26: 13.00-14.30 | D26: Л. Педагогика физической культуры и спорта Цакаев С.Ш. 216 ауд.к. | E26: Л. Педагогика физической культуры и спорта Цакаев С.Ш. 216 ауд.к. | F26: Л. Педагогика физической культуры и спорта Цакаев С.Ш. 216 ауд.к. | G26: Л. Педагогика физической культуры и спорта Цакаев С.Ш. 216 ауд.к. | H26: Л. Педагогика физической культуры и спорта Цакаев С.Ш. 216 ауд.к.
C27: 14.50-16.20 | D27: Л. Элективные дисциплины по ФКиС: Фехтование Моисеев А.Б. 216 ауд.к. | E27: Л. Элективные дисциплины по ФКиС: Фехтование Моисеев А.Б. 216 ауд.к. | F27: Л. Элективные дисциплины по ФКиС: Фехтование Моисеев А.Б. 216 ауд.к. | G27: Л. Элективные дисциплины по ФКиС: Фехтование Моисеев А.Б. 216 ауд.к. | H27: Л. Элективные дисциплины по ФКиС: Фехтование Моисеев А.Б. 216 ауд.к.
C28: 16.40-18.10
A29: Пятница | B29: =B24+1 -> 46297 | C29: 8.50-10.20 | D29: Пр. Самооборона (самбо) Махмудов М.М., Марянян С.А. 14СК | F29: Пр. Плавание Шакина Е.Е. бассейн УСЗК | G29: Пр. Плавание Никитина С.М. , Павлова Т.Н. бассейн УСЗК
C30: 10.40-12.10 | D30: Пр. Физиология человека Белицкая Л.А. 234мбк, Колесник О.В. 238мбк | F30: Пр. Плавание Шакина Е.Е. бассейн УСЗК | G30: Пр. Плавание Никитина С.М. , Павлова Т.Н. бассейн УСЗК
C31: 13.00-14.30 | E31: Пр. Теория и методика волейбола, компьютерного спорта, гонок дронов Прил.1 | F31: Пр. Физиология человека Колесник О.В. 254мбк | G31: Пр. Физиология человека Белицкая Л.А. 237мбк, Андреева А.М. 238мбк | H31: Пр. Самооборона (самбо) Попов Д.В., Иванченко М.М. 27СК
C32: 14.50-16.20 | E32: Пр. Теория и методика волейбола, компьютерного спорта, гонок дронов Прил.1 | G32: Пр. Самооборона (самбо) Попов Д.В., Иванченко М.М. 27СК | H32: Пр. Физиология человека Ширяева Т.П. 254мбк, Андреева А.М. 234мбк
C33: 16.40-18.10
A34: Суббота | B34: =B29+1 -> 46298 | C34: 8.50-10.20
C35: 10.40-12.10
C36: 13.00-14.30
C37: 14.50-16.20
C38: 16.40-18.10
D39: * Профили (направленность) указанны на титульном листе
C40: ='01.09'!C39 -> *Л. Физиология человека* | D40: ='21.09'!D40+COUNTIF(D$8:D$38,$C40) -> 6 | E40: ='21.09'!E40+COUNTIF(E$8:E$38,$C40) -> 6 | F40: ='21.09'!F40+COUNTIF(F$8:F$38,$C40) -> 6 | G40: ='21.09'!G40+COUNTIF(G$8:G$38,$C40) -> 6 | H40: ='21.09'!H40+COUNTIF(H$8:H$38,$C40) -> 6
...

Sheet 05.10
B1: Расписание учебных занятий на первое полугодие 2026-2027 учебного года
B2: ТРЕНЕРСКИЙ ФАКУЛЬТЕТ, направление подготовки (образовательная программа)
B3: 49.03.04 Спорт *
B4: Курс 2, семестр 3, очная форма обучения
A5: группы С1-01А-25, С1-01Б-25, С1-02А-25, С1-02Б-25, С1-03-25, С1-04А-25, С1-04Б-25, С1-05А-25, С1-05Б-25
A6: День недели | B6: Дата | C6: Время | D6: 1 группа | E6: 2 группа | F6: 3 группа | G6: 4 группа | H6: 5 группа
D7: Баскетбол, гандбол, бейсбол, регби | E7: Волейбол, гонки дронов, компьютерный спорт | F7: Теннис, настольный теннис, бадминтон, бильярд | G7: Футбол | H7: Хоккей
A8: Понедельник | B8: 46300 | C8: 8.50-10.20 | D8: Пр. Теория и методика гандбола, бейсбола, регби Прил.1 | E8: Пр. Теория и методика волейбола, гонок дронов Прил.1; Пр. Методика реализации программ дополнительного образования в области ФКиС: компьютерный спорт Прил.1 | F8: Пр. Теория и методика тенниса, настольного тенниса, бадминтона, бильярда Прил.1 | G8: Пр. Физиология человека Белицкая Л.А. 240мбк, Андреева А.М. 238мбк | H8: Пр. Подвижные игры в спорте и образовании Дробышевская Н.В., Салахудинова Е.С. Модуль Б
C9: 10.40-12.10 | D9: Пр. Теория и методика гандбола, бейсбола, регби Прил.1 | E9: Пр. Теория и методика компьютерного спорта Прил.1; Пр. Методика реализации программ дополнительного образования в области ФКиС: волейбол, гонки дронов Прил.1 | F9: Пр. Теория и методика тенниса, настольного тенниса, бадминтона, бильярда Прил.1 | G9: Пр. Подвижные игры в спорте и образовании Дробышевская Н.В., Кузьмичева Е.В. Модуль Б | H9: Пр. Физиология человека Ширяева Т.П. 254мбк, Андреева А.М. 234мбк
C10: 13.00-14.30 | D10: Пр. Теория и методика баскетбола Прил.1 | E10: Пр. Теория и методика физической культуры Мачканова Е.В. 306 гл.к.
C11: 14.50-16.20 | D11: Пр. Теория и методика баскетбола Прил.1
C12: 16.40-18.10
A13: Вторник | B13: =B8+1 -> 46301 | C13: 8.50-10.20 | D13: Л. Теория и методика физической культуры Мачканова Е.В. 212 ауд.к. | E13: Л. Теория и методика физической культуры Мачканова Е.В. 212 ауд.к. | F13: Л. Теория и методика физической культуры Мачканова Е.В. 212 ауд.к. | G13: Л. Теория и методика физической культуры Мачканова Е.В. 212 ауд.к. | H13: Л. Теория и методика физической культуры Мачканова Е.В. 212 ауд.к.
C14: 10.40-12.10 | D14: Л. Физиология человека Ширяева Т.П. 212 ауд.к. | E14: Л. Физиология человека Ширяева Т.П. 212 ауд.к. | F14: Л. Физиология человека Ширяева Т.П. 212 ауд.к. | G14: Л. Физиология человека Ширяева Т.П. 212 ауд.к. | H14: Л. Физиология человека Ширяева Т.П. 212 ауд.к.
C15: 13.00-14.30 | D15: Пр. Подвижные игры в спорте и образовании Дробышевская Н.В., Салахудинова Е.С. Модуль Б | E15: Пр. Физиология человека Белицкая Л.А. 234мбк, Ширяева Т.П. 254мбк | G15: Пр. Теория и методика футбола Прил.1 | H15: Пр. Теория и методика хоккея Прил.1
C16: 14.50-16.20 | D16: Пр. Педагогика физической культуры и спорта Цакаев С.Ш. 439мбк | E16: Пр. Подвижные игры в спорте и образовании Дробышевская Н.В., Салахудинова Е.С. Модуль Б | G16: Пр. Теория и методика футбола Прил.1 | H16: Пр. Методика реализации программ дополнительного образования в области ФКиС Прил.1
C17: 16.40-18.10
C18: 18.30-20.00
A19: Среда | B19: =B13+1 -> 46302 | C19: 8.50-10.20 | D19: Пр. Плавание Шакина Е.Е., Чистова Н.А. бассейн УСЗК | E19: Пр. Плавание Колесов А.Д., Павлова Т.Н. бассейн УСЗК | F19: Пр. Подвижные игры в спорте и образовании Дробышевская Н.В. Модуль Б | G19: Пр. Теория и методика физической культуры Мачканова Е.В. 406ауд.к.
C20: 10.40-12.10 | D20: Пр. Плавание Шакина Е.Е., Чистова Н.А. бассейн УСЗК | E20: Пр. Плавание Колесов А.Д., Павлова Т.Н.. бассейн УСЗК | F20: Пр. Физиология человека Колесник О.В. 254мбк | G20: Пр. Педагогика физической культуры и спорта Цакаев С.Ш. 417мбк, Германов Г.Н. 445мбк | H20: Пр. Теория и методика физической культуры Мачканова Е.В. 406ауд.к.
C21: 13.00-14.30 | D21: Пр. Физиология человека Белицкая Л.А. 234мбк, Колесник О.В. 254мбк | E21: Пр. Педагогика физической культуры и спорта Цакаев С.Ш. 516мбк | F21: Пр. Самооборона (самбо) Марянян С.А. 14СК | H21: Пр. Теория и методика хоккея Прил.1
C22: 14.50-16.20 | D22: Пр. Теория и методика гандбола, бейсбола, регби Прил.1 | F22: Пр. Педагогика физической культуры и спорта Цакаев С.Ш. 419мбк | H22: Пр. Теория и методика хоккея Прил.1
C23: 16.40-18.10
A24: Четверг | B24: =B19+1 -> 46303 | C24: 8.50-10.20 | D24: Пр. Теория и методика баскетбола Прил.1 | E24: Пр. Физиология человека Белицкая Л.А. 234мбк, Ширяева Т.П. 254мбк | F24: Пр. Методика реализации программ дополнительного образования в области ФКиС Прил.1 | G24: Пр. Методика реализации программ дополнительного образования в области ФКиС Прил.1 | H24: Пр. Плавание Никитина С.М., Шакина Е.Е. бассейн УСЗК
C25: 10.40-12.10 | D25: Пр. Методика реализации программ дополнительного образования в области ФКиС Прил.1 | E25: Пр. Самооборона (самбо) Махмудов М.М., Иванченко М.М. 14СК | F25: Пр. Теория и методика тенниса, настольного тенниса, бадминтона, бильярда Прил.1 | G25: Пр. Теория и методика футбола Прил.1 | H25: Пр. Плавание Никитина С.М., Шакина Е.Е. бассейн УСЗК
C26: 13.00-14.30 | D26: Пр. Теория и методика физической культуры Мачканова Е.В. 306 гл.к. | F26: Пр. Методика преподавания предмета "физическая культура" в образовательных организациях Гасанова-Матвеева З.А. 309 гл.к. | G26: Пр. Элективные дисциплины по ФКиС: Фехтование Моисеев А.Б., Полишките К. 231СК, 246СК | H26: Пр. Методика преподавания предмета "физическая культура" в образовательных организациях Трунева Т.В. 308 гл.к.
C27: 14.50-16.20 | F27: Пр. Теория и методика физической культуры Мачканова Е.В. 308 гл.к. | G27: Пр. Методика преподавания предмета "физическая культура" в образовательных организациях Трунева Т.В. 306 гл.к. | H27: Пр. Элективные дисциплины по ФКиС: Фехтование Моисеев А.Б., Полишките К. 231СК, 246СК
C28: 16.40-18.10
A29: Пятница | B29: =B24+1 -> 46304 | C29: 8.50-10.20 | D29: Пр. Самооборона (самбо) Махмудов М.М., Марянян С.А. 14СК | E29: Пр. Элективные дисциплины по ФКиС: Фехтование Моисеев А.Б., Полишките К. 231СК, 246СК | F29: Пр. Плавание Шакина Е.Е. бассейн УСЗК | G29: Пр. Плавание Никитина С.М. , Павлова Т.Н. бассейн УСЗК
C30: 10.40-12.10 | D30: Пр. Физиология человека Белицкая Л.А. 234мбк, Колесник О.В. 238мбк | E30: Пр. Методика преподавания предмета "физическая культура" в образовательных организациях Гасанова-Матвеева З.А. 309 гл.к. | F30: Пр. Плавание Шакина Е.Е. бассейн УСЗК | G30: Пр. Плавание Никитина С.М. , Павлова Т.Н. бассейн УСЗК
C31: 13.00-14.30 | D31: Пр. Элективные дисциплины по ФКиС: Фехтование Моисеев А.Б., Полишките К. 231СК, 246СК | E31: Пр. Теория и методика волейбола, компьютерного спорта, гонок дронов Прил.1 | F31: Пр. Физиология человека Колесник О.В. 254мбк | G31: Пр. Физиология человека Белицкая Л.А. 237мбк, Андреева А.М. 238мбк | H31: Пр. Самооборона (самбо) Попов Д.В., Иванченко М.М. 27СК
C32: 14.50-16.20 | D32: Пр. Методика преподавания предмета "физическая культура" в образовательных организациях Гасанова-Матвеева З.А. 306 гл.к. | E32: Пр. Теория и методика волейбола, компьютерного спорта, гонок дронов Прил.1 | F32: Пр. Элективные дисциплины по ФКиС: Фехтование Полишките К. 231СК, 246СК | G32: Пр. Самооборона (самбо) Попов Д.В., Иванченко М.М. 27СК | H32: Пр. Физиология человека Ширяева Т.П. 254мбк, Андреева А.М. 234мбк
C33: 16.40-18.10
A34: Суббота | B34: =B29+1 -> 46305 | C34: 8.50-10.20
C35: 10.40-12.10
C36: 13.00-14.30
C37: 14.50-16.20
C38: 16.40-18.10
D39: * Профили (направленность) указанны на титульном листе
C40: ='01.09'!C39 -> *Л. Физиология человека* | D40: ='28.09'!D40+COUNTIF(D$8:D$38,$C40) -> 7 | E40: ='28.09'!E40+COUNTIF(E$8:E$38,$C40) -> 7 | F40: ='28.09'!F40+COUNTIF(F$8:F$38,$C40) -> 7 | G40: ='28.09'!G40+COUNTIF(G$8:G$38,$C40) -> 7 | H40: ='28.09'!H40+COUNTIF(H$8:H$38,$C40) -> 7
...

Sheet 12.10
B1: Расписание учебных занятий на первое полугодие 2026-2027 учебного года
B2: ТРЕНЕРСКИЙ ФАКУЛЬТЕТ, направление подготовки (образовательная программа)
B3: 49.03.04 Спорт *
B4: Курс 2, семестр 3, очная форма обучения
A5: группы С1-01А-25, С1-01Б-25, С1-02А-25, С1-02Б-25, С1-03-25, С1-04А-25, С1-04Б-25, С1-05А-25, С1-05Б-25
A6: День недели | B6: Дата | C6: Время | D6: 1 группа | E6: 2 группа | F6: 3 группа | G6: 4 группа | H6: 5 группа
D7: Баскетбол, гандбол, бейсбол, регби | E7: Волейбол, гонки дронов, компьютерный спорт | F7: Теннис, настольный теннис, бадминтон, бильярд | G7: Футбол | H7: Хоккей
A8: Понедельник | B8: 46307 | C8: 8.50-10.20 | D8: Пр. Теория и методика гандбола, бейсбола, регби Прил.1 | E8: Пр. Теория и методика волейбола, гонок дронов Прил.1; Пр. Методика реализации программ дополнительного образования в области ФКиС: компьютерный спорт Прил.1 | F8: Пр. Теория и методика тенниса, настольного тенниса, бадминтона, бильярда Прил.1 | G8: Пр. Физиология человека Белицкая Л.А. 240мбк, Андреева А.М. 238мбк | H8: Пр. Подвижные игры в спорте и образовании Дробышевская Н.В., Салахудинова Е.С. Модуль Б
C9: 10.40-12.10 | D9: Пр. Теория и методика гандбола, бейсбола, регби Прил.1 | E9: Пр. Теория и методика компьютерного спорта Прил.1; Пр. Методика реализации программ дополнительного образования в области ФКиС: волейбол, гонки дронов Прил.1 | F9: Пр. Теория и методика тенниса, настольного тенниса, бадминтона, бильярда Прил.1 | G9: Пр. Подвижные игры в спорте и образовании Дробышевская Н.В., Кузьмичева Е.В. Модуль Б | H9: Пр. Физиология человека Ширяева Т.П. 254мбк, Андреева А.М. 234мбк
C10: 13.00-14.30 | D10: Пр. Теория и методика баскетбола Прил.1 | E10: Пр. Теория и методика физической культуры Мачканова Е.В. 306 гл.к.
C11: 14.50-16.20 | D11: Пр. Теория и методика баскетбола Прил.1
C12: 16.40-18.10
