Workbook
Name SIGN: #REF!
Name SIGN: #REF!
Name SIGN: #REF!
Name SIGN: #REF!
Name SIGN: #REF!
Name SIGN: #REF!
Name SIGN: #REF!
Name SIGN: #REF!
Name SIGN_D: #REF!
Name SIGN_D: #REF!
Name SIGN_D: #REF!
Name SIGN_D: #REF!
Name SIGN_D: #REF!
Name SIGN_D: #REF!
Name SIGN_D: #REF!
Name SIGN_D: #REF!
Name Sign1: #REF!
Name Sign1: #REF!
Name Sign1: #REF!
Name Sign1: #REF!
Name Sign1: #REF!
Name Sign1: #REF!
Name Sign1: #REF!
Name Sign1: #REF!
Name и: #REF!
Name и: #REF!
Name и: #REF!
Name и: #REF!
Name и: #REF!
Name и: #REF!
Name и: #REF!
Name и: #REF!
Name Р1: #REF!
Name Р1: #REF!
Name Р1: #REF!
Name Р1: #REF!
Name Р1: #REF!
Name Р1: #REF!
Name Р1: #REF!
Name Р1: #REF!
Name ыва: #REF!
Name ыва: #REF!
Name ыва: #REF!
Name ыва: #REF!
Name ыва: #REF!
Name ыва: #REF!
Name ыва: #REF!
Name ыва: #REF!

Sheet титульный лист

Sheet Титул
H1: УТВЕРЖДАЮ
H2: Начальник учебно-методического управления
H3: Р.С. Халимулина
H4: _________________________________
H5: «____»____________________20___г.
A6: Расписание учебных занятий на первое полугодие 2026-2027 учебного года
A7: ТРЕНЕРСКИЙ ФАКУЛЬТЕТ, направление подготовки (образовательная программа)
A8: 49.03.04 Спорт, Профиль (направленность): Спортивная подготовка по видам спорта «бокс», «кикбоксинг». Педагогическая деятельность в области физической культуры и спорта; Спортивная подготовка в единоборствах. Педагогическая деятельность в области физической культуры и спорта; Спортивная подготовка в тхэквондо. Педагогическая деятельность в области физической культуры и спорта; Спортивная подготовка в тяжелоатлетических видах спорта. Педагогическая деятельность в области физической культуры и спорта; Спортивная подготовка в видах спорта «фехтование», «современное пятиборье» и «стрелковые виды спорта». Педагогическая деятельность в области физической культуры и спорта; Спортивная подготовка по видам спорта "каратэдо", "киокусинкай", "ушу". Педагогическая деятельность в области физической культуры и спорта; Спортивная подготовка по виду спорта «скалолазание». Педагогическая деятельность в области физической культуры и спорта; уровень образования бакалавриат
A9: Факультет адаптивной физической культуры, рекреации и туризма, направление подготовки (образовательная программа)
A10: 49.03.01 Физическая культура, Профиль (направленность) Физкультурно-оздоровительная деятельность и фитнес, уровень образования бакалавриат
A11: Курс 1, семестр 1, очная форма обучения
A12: группы С2-07-26, С2-08-26, С2-09-26, Т1-04-26
A14: № | B14: Наименование дисциплины (модуля), практика, научные исследования | C14: Кол-во часов (Л/П) | D14: Форма отчетности | E14: Учебные группы в соответствии с избранным видом спорта
E15: Физкультурно-оздоровительная деятельность и фитнес (ФОДиФ) | F15: Единоборства (армспорт, греко-римская борьба, вольная борьба, дзюдо, самбо, служебно-прикладные единоборства) | G15: киокусинкай, ушу, тхэквондо (ВТФ, ИТФ), тяжелоатлетические виды спорта | H15: Бокс, кикбоксинг, современное пятиборье, фехтование, стрелковые виды спорта, скалолазание
E16: Т1-04-26 | F16: 7 группа | G16: 8 группа | H16: 9 группа
E17: Ф.И.О. преподавателя
A18: 1 | B18: Иностранный язык | C18: 0/32 | D18: Б/о | E18: Литвинов С.В. | F18: Литвинов С.В. | G18: Литвинов С.В. | H18: Литвинов С.В.
E19: Переверзева Н.А. (русский язык как иностранный для иностранных граждан)
A20: 2 | B20: Речевое общение в профессиональной деятельности | C20: 10/22 | D20: Зачет | E20: Л - Капустина Ю.А.
E21: Капустина Ю.А. | F21: Капустина Ю.А. | G21: Капустина Ю.А. | H21: Капустина Ю.А.
A22: 3 | B22: Анатомия человека | C22: 8/24 | D22: Зачет | E22: Л - Силаева Л.В.
E23: Мештель А.В. | F23: Сироткина Ю.А. | G23: Мештель А.В. | H23: Гричанова Т.Г.
A24: 4 | B24: Физическая культура и спорт | C24: 10/10 | D24: Зачет | E24: Л - Мачканова Е.В.
E25: Трунева Т.В. | F25: Трунева Т.В. | G25: Трунева Т.В. | H25: Трунева Т.В.
A26: 5 | B26: Гимнастика | C26: 6/40 | D26: Зачет | E26: Л - Михалина Г.М., Ростовцева М.Ю., Парахин В.А.
A27: 5 | B27: Гимнастика | E27: Андреасян К.Б. | F27: Колесникова Е.С. | G27: Дубовицкая И.А. | H27: Дубовицкая И.А.
A28: 6 | B28: Информационные технологии в сфере физической культуры и спорта | C28: 4/28 | D28: Диф.зачет | E28: Л - Яшкина Е.Н.
E29: Яшкина Е.Н. | F29: Яшкина Е.Н. | G29: Яшкина Е.Н. | H29: Яшкина Е.Н.
A30: 7 | B30: Волейбол | C30: 2/46 | D30: Зачет | E30: Л - Ефимов А.С.
E31: Ефимов А.С. | F31: Ефимов А.С. | G31: Суханова А.В. | H31: Ананьин А.С.
A32: 8 | B32: Лыжные гонки | C32: 2/62 | D32: Зачет | E32: Л - Дубровинский С.С.
E33: Сенатская В.Г. | F33: Дубровинский С.С. | G33: Щукин А.В. | H33: Щукин А.В.
A34: 9 | B34: Использование электронной информационно-образовательной среды РУС "ГЦОЛИФК" | C34: 2/4 | D34: Зачет | E34: Л - Шевцов А.В.
E35: П - Мирошников А.Б., Кузнецова Н.А. | F35: П - Шевцов А.В., Кузнецова Н.А. | G35: П - Шевцов А.В., Кузнецова Н.А. | H35: П - Шевцов А.В., Кузнецова Н.А.
A36: 10 | B36: Элективные дисциплины по ФКиС: Подвижные игры | C36: 2/18 | D36: Зачет | E36: Л - Салахудинова Е.С.
E37: Салахудинова Е.С. | F37: Салахудинова Е.С. | G37: Дробышевская Н.В. | H37: Дробышевская Н.В.
A38: 11 | B38: Теория и методика избранного вида спорта | C38: 10/90 | D38: Зачет | E38: ФОДиФ | F38: Армспорт, Самбо | G38: Киокусинкай, ушу | H38: Бокс, кикбоксинг
E39: Л - Адамова И.В. | F39: Л - Махмудов М.М., Табаков С.Е. | G39: Л - Демченко Н.С., Багомедов Х.А. | H39: Л - Киселев В.А.
E40: П - Адамова И.В. | F40: П - Махмудов М.М., Табаков С.Е., Марянян С.А. | G40: П - Демченко Н.С., Багомедов Х.А. | H40: П - Киселев В.А.
F41: Греко-римская борьба, Дзюдо | G41: Тхэквондо (ВТФ, ИТФ) | H41: Фехтование, современное пятиборье
...

Sheet приложение1
A1: Приложение1 к расписанию учебных занятий на первое полугодие 2026-2027 учебного года
A2: ТРЕНЕРСКИЙ ФАКУЛЬТЕТ, направление подготовки (образовательная программа)
A3: 49.03.04 Спорт, Профиль (направленность): Спортивная подготовка по видам спорта «бокс», «кикбоксинг». Педагогическая деятельность в области физической культуры и спорта; Спортивная подготовка в единоборствах. Педагогическая деятельность в области физической культуры и спорта; Спортивная подготовка в тхэквондо. Педагогическая деятельность в области физической культуры и спорта; Спортивная подготовка в тяжелоатлетических видах спорта. Педагогическая деятельность в области физической культуры и спорта; Спортивная подготовка в видах спорта «фехтование», «современное пятиборье» и «стрелковые виды спорта». Педагогическая деятельность в области физической культуры и спорта; Спортивная подготовка по видам спорта "каратэдо", "киокусинкай", "ушу". Педагогическая деятельность в области физической культуры и спорта; Спортивная подготовка по виду спорта «скалолазание». Педагогическая деятельность в области физической культуры и спорта; уровень образования бакалавриат
A4: Факультет адаптивной физической культуры, рекреации и туризма, направление подготовки (образовательная программа)
A5: 49.03.01 Физическая культура, Профиль (направленность) Физкультурно-оздоровительная деятельность и фитнес, уровень образования бакалавриат
A6: Курс 1, семестр 1, очная форма обучения | M6: ТиМ бокса и кикбоксинга им.К.В. Градополова | N6: 21зал
A7: группы С2-07-26, С2-08-26, С2-09-26, Т1-04-26 | M7: ТиМ бокса и кикбоксинга им.К.В. Градополова | N7: 21зал
A8: № | B8: Наименование дисциплины (модуля): | C8: № аудитории | M8: ТиМ бокса и кикбоксинга им.К.В. Градополова | N8: 21зал
A9: 1 | B9: Теория и методика единоборств, профессионально-спортивное совершенствование (единоборства) | C9: 32СК, 27СК, 14СК, 34СК, 35СК, 28СК, 15СК, 36СК, 205мбк | M9: ТиМ велосипедного спорта | N9: модульБ, 210зал
A10: 2 | B10: Теория и методика тяжелоатлетических видов спорта, профессионально-спортивное совершенствование (тяжелоатлетические виды спорта) | C10: 42СК | M10: Спортивная гимнастика | N10: 205,209, 210залы
A11: 3 | B11: Теория и методика фехтования, современного пятиборья, стрелковых видов спорта, профессионально-спортивное совершенствование (фехтование, современное пятиборье, стрелковые виды спорта) | C11: 231СК, 246СК, №22 тир
A12: 4 | B12: Теория и методика каратэдо, киокусинкай, ушу, тхэквондо; профессионально-спортивное совершенствование (тхэквондо (ВТФ, ИТФ), киокусинкай, ушу) | C12: Тхэквондо ВТФ - 160мбк, модуль Г, л/а манеж; Тхэквондо ИТФ - 207 мбк; киокусинкай - модуль Г, 231СК, , л/а манеж; ушу - 159 мбк, модуль Г | M12: Художественная гимнастика | N12: 205,209, 210залы
A13: 5 | B13: Теория и методика бокса и кикбоксинга, профессионально-спортивное совершенствование (бокс и кикбоксинг) | C13: 20СК, 21СК, 23СК | M13: ТиМ индивидуально-игровых видов спорта | N13: МодульД, 223зал
A14: 6 | B14: Теория и методика физкультурно-оздоровительной деятельности и фитнеса, профессионально-физкультурное совершенствование | C14: вторник: фитнес-зал№83 теннисный центр; пятница - 213СК
A15: 7 | B15: Теория и методика скалолазания, профессионально-спортивное совершенствование (скалолазание) | C15: скалодром РУС "ГЦОЛИФК" | M15: конькобежного спорта | N15: УСЗК
A16: 8 | B16: Наименование дисциплины (модуля): Лыжные гонки | C16: 250 мбк, 282 мбк, л/а манеж, АНОСРФиС "АРТА-СПОРТ": г. Москва, Измайловский пр-д, д.15
A17: Условные обозначения:
A18: УСЗК - Универсальный спортивно-зрелищный комплекс | M18: Водное поло | N18: Бассейн РГУФК СМиТ
A19: МБК - медико-биологический корпус | M19: Синхронное плавание | N19: Бассейн РГУФК СМиТ
A20: СК - спортивный корпус | M20: ТиМ танцевального спорта | N20: 201зал
M21: ТиМ тенниса | N21: Тенисные корты
M22: ТиМ тяжелоатлетических видов спорта им.А.С. Медведева | N22: 42зал
M23: Фехтование | N23: 231зал
M24: Дзюдо | N24: 32зал
M25: Современное пятиборье | N25: 231зал
M26: Вольная борьба | N26: 14зал
M27: Тхэквандо ИТФ | N27: 29,42 зал
M28: Армспорт | N28: 14зал
M29: Ушу | N29: 308зал УСЗК
M30: Самбо | N30: 32,27 залы
M31: Айкило,Киокусинкай | N31: 308зал УСЗК
M32: Каратэдо | N32: МодульГ
... M43: Малая авиация и парашютный спорт | N43: 204ауд.

Sheet расписание ПСС, ПФС
B1: Расписание учебных занятий на первое полугодие 2026-2027 учебного года
B2: ТРЕНЕРСКИЙ ФАКУЛЬТЕТ, направление подготовки (образовательная программа)
A3: 49.03.04 Спорт, Профиль (направленность): Спортивная подготовка по видам спорта «бокс», «кикбоксинг». Педагогическая деятельность в области физической культуры и спорта; Спортивная подготовка в единоборствах. Педагогическая деятельность в области физической культуры и спорта; Спортивная подготовка в тхэквондо. Педагогическая деятельность в области физической культуры и спорта; Спортивная подготовка в тяжелоатлетических видах спорта. Педагогическая деятельность в области физической культуры и спорта; Спортивная подготовка в видах спорта «фехтование», «современное пятиборье» и «стрелковые виды спорта». Педагогическая деятельность в области физической культуры и спорта; Спортивная подготовка по видам спорта "каратэдо", "киокусинкай", "ушу". Педагогическая деятельность в области физической культуры и спорта; Спортивная подготовка по виду спорта «скалолазание». Педагогическая деятельность в области физической культуры и спорта; уровень образования бакалавриат
A4: Факультет адаптивной физической культуры, рекреации и туризма, направление подготовки (образовательная программа)
A5: 49.03.01 Физическая культура, Профиль (направленность) Физкультурно-оздоровительная деятельность и фитнес, уровень образования бакалавриат
A6: Курс 1, семестр 1, очная форма обучения
A7: группы С2-07-26, С2-08-26, С2-09-26, Т1-04-26
A8: с 01.09 по 26.12
A9: День недели | B9: Время | C9: Т1-04-26 | D9: 7 группа | E9: 8 группа | F9: 9 группа
C10: Физкультурно-оздоровительная деятельность и фитнес (ФОДиФ) | D10: Единоборства (армспорт, греко-римская борьба, вольная борьба, дзюдо, самбо, служебно-прикладные единоборства) | E10: киокусинкай, ушу, тхэквондо (ВТФ, ИТФ), тяжелоатлетические виды спорта | F10: Бокс, кикбоксинг, современное пятиборье, фехтование, стрелковые виды спорта, скалолазание
A11: Понедельник | B11: 8.50-10.20
B12: 10.40-12.10
B13: 13.00-14.30
B14: 14.50-16.20
B15: 16.40-18.10
B16: 18.30-20.00
B17: 19.30-21.00
A18: Вторник | B18: 07.10-08.30 | C18: ПФС 213СК 12.10 по 26.12 (2 п/группа) | E18: ПСС киокусинкай л/а манеж, модуль Г, 231СК
B19: 08.50-10.20 | C19: ПФС 213СК 12.10 по 26.12 (1 п/группа)
B20: 10.40-12.10
B21: 13.00-14.30
B22: 14.50-16.20
B23: 16.40-18.10 | D23: ПСС Армспорт, Самбо 14СК, 27СК; ПСС Греко-римская борьба, Дзюдо 14СК, 32СК; ПСС Вольная борьба, Служебно-прикладные единоборства 14СК, 27СК | E23: ПСС ушу 16.40-18.10 модуль Г, 159мбк | F23: ПСС современное пятиборье, фехтование 246СК
B24: 18.30-20.00
B25: 20:20-21:50
A26: Среда | B26: 8.50-10.20
B27: 10.40-12.10
B28: 13.00-14.30
B29: 14.50-16.20
B30: 16.40-18.10
B31: 18:30-20:00
B32: 20:20-21:50
A33: Четверг | B33: 8.50-10.20
B34: 10.40-12.10 | C34: ПФС фитнес-зал№83 теннисный центр 10.09 - 22.10 | F34: 1к ПСС скалолазание 05.10 по 29.10 скалодром РУС ГЦОЛИФК
B35: 13.00-14.30 | F35: 1к ПСС скалолазание 05.10 по 29.10 скалодром РУС ГЦОЛИФК
B36: 14.50-16.20
B37: 16.40-18.10 | F37: Бокс, кикбоксинг ПСС 16.45-18.15 20СК, 21СК 03.09-26.12
B38: 18:30-20:00 | E38: ПСС тхэквондо ВТФ 18.30-20.00 л/а манеж, модуль Г, 160мбк
B39: 20:20-21:50
A40: Пятница | B40: 8.50-10.20
...

Sheet Иностр язык (русский язык)
B1: Расписание учебных занятий на первое полугодие 2026-2027 учебного года
B2: ТРЕНЕРСКИЙ ФАКУЛЬТЕТ, направление подготовки (образовательная программа)
A3: 49.03.04 Спорт, Профиль (направленность): Спортивная подготовка по видам спорта «бокс», «кикбоксинг». Педагогическая деятельность в области физической культуры и спорта; Спортивная подготовка в единоборствах. Педагогическая деятельность в области физической культуры и спорта; Спортивная подготовка в тхэквондо. Педагогическая деятельность в области физической культуры и спорта; Спортивная подготовка в тяжелоатлетических видах спорта. Педагогическая деятельность в области физической культуры и спорта; Спортивная подготовка в видах спорта «фехтование», «современное пятиборье» и «стрелковые виды спорта». Педагогическая деятельность в области физической культуры и спорта; Спортивная подготовка по видам спорта "каратэдо", "киокусинкай", "ушу". Педагогическая деятельность в области физической культуры и спорта; Спортивная подготовка по виду спорта «скалолазание». Педагогическая деятельность в области физической культуры и спорта; уровень образования бакалавриат
A4: Факультет адаптивной физической культуры, рекреации и туризма, направление подготовки (образовательная программа)
A5: 49.03.01 Физическая культура, Профиль (направленность) Физкультурно-оздоровительная деятельность и фитнес, уровень образования бакалавриат
B6: Курс 1, семестр 1, очная форма обучения
B7: группы С2-07-26, С2-08-26, С2-09-26, Т1-04-26
A8: День недели | B8: Дата | C8: Время | D8: Т1-04-26 | E8: 7 группа | F8: 8 группа | G8: 9 группа
D9: Физкультурно-оздоровительная деятельность и фитнес (ФОДиФ) | E9: Единоборства (армспорт, греко-римская борьба, вольная борьба, дзюдо, самбо, служебно-прикладные единоборства) | F9: киокусинкай, ушу, тхэквондо (ВТФ, ИТФ), тяжелоатлетические виды спорта | G9: Бокс, кикбоксинг, современное пятиборье, фехтование, стрелковые виды спорта, скалолазание
A10: Понедельник | C10: 8.50-10.20
C11: 10.40-12.10
C12: 13.00-14.30
C13: 14.50-16.20
C14: 16.40-18.10
A15: Вторник | C15: 8.50-10.20
C16: 10.40-12.10
C17: 13.00-14.30
C18: 14.50-16.20
C19: 16.40-18.10
A20: Среда | C20: 8.50-10.20
C21: 10.40-12.10
C22: 13.00-14.30
C23: 14.50-16.20
C24: 16.40-18.10
A25: Четверг | C25: 8.50-10.20 | D25: Пр. Иностранный язык Переверзева Н.А. - 508 гл.к. (русский язык как иностранный для иностранных граждан: Т1-04-26, С2-08-26, С2-09-26) - 10.09, 17.09, 24.09, 01.10, 08.10, 15.10, 22.10, 29.10, 05.11, 12.11, 19.11, 26.11, 03.12, 10.12, 17.12, 24.12
C26: 10.40-12.10 | D26: Пр. Иностранный язык Переверзева Н.А. - 511 гл.к. (русский язык как иностранный для иностранных граждан: С2-07-26) - 10.09, 17.09, 24.09, 01.10, 08.10, 15.10, 22.10, 29.10, 05.11, 12.11, 19.11, 26.11, 03.12, 10.12, 17.12, 24.12
C27: 13.00-14.30
C28: 14.50-16.20
C29: 16.40-18.10
A30: Пятница | C30: 8.50-10.20
C31: 10.40-12.10
C32: 13.00-14.30
C33: 14.50-16.20
C34: 16.40-18.10
A35: Суббота | C35: 8.50-10.20
C36: 10.40-12.10
C37: 13.00-14.30
C38: 14.50-16.20
C39: 16.40-18.10

Sheet 01.09
B1: Расписание учебных занятий на первое полугодие 2026-2027 учебного года
B2: ТРЕНЕРСКИЙ ФАКУЛЬТЕТ, направление подготовки (образовательная программа)
A3: 49.03.04 Спорт, Профиль (направленность): Спортивная подготовка по видам спорта «бокс», «кикбоксинг». Педагогическая деятельность в области физической культуры и спорта; Спортивная подготовка в единоборствах. Педагогическая деятельность в области физической культуры и спорта; Спортивная подготовка в тхэквондо. Педагогическая деятельность в области физической культуры и спорта; Спортивная подготовка в тяжелоатлетических видах спорта. Педагогическая деятельность в области физической культуры и спорта; Спортивная подготовка в видах спорта «фехтование», «современное пятиборье» и «стрелковые виды спорта». Педагогическая деятельность в области физической культуры и спорта; Спортивная подготовка по видам спорта "каратэдо", "киокусинкай", "ушу". Педагогическая деятельность в области физической культуры и спорта; Спортивная подготовка по виду спорта «скалолазание». Педагогическая деятельность в области физической культуры и спорта; уровень образования бакалавриат
A4: Факультет адаптивной физической культуры, рекреации и туризма, направление подготовки (образовательная программа)
A5: 49.03.01 Физическая культура, Профиль (направленность) Физкультурно-оздоровительная деятельность и фитнес, уровень образования бакалавриат
B6: Курс 1, семестр 1, очная форма обучения
B7: группы С2-07-26, С2-08-26, С2-09-26, Т1-04-26
A9: День недели | B9: Дата | C9: Время | D9: Т1-04-26 | E9: 7 группа | F9: 8 группа | G9: 9 группа
D10: Физкультурно-оздоровительная деятельность и фитнес (ФОДиФ) | E10: Единоборства (армспорт, греко-римская борьба, вольная борьба, дзюдо, самбо, служебно-прикладные единоборства) | F10: киокусинкай, ушу, тхэквондо (ВТФ, ИТФ), тяжелоатлетические виды спорта | G10: Бокс, кикбоксинг, современное пятиборье, фехтование, стрелковые виды спорта, скалолазание
A11: Понедельник | B11: 46265 | C11: 8.50-10.20
C12: 10.40-12.10
C13: 13.00-14.30
C14: 14.50-16.20
C15: 16.40-18.10
A16: Вторник | B16: =B11+1 -> 46266 | C16: 8.50-10.20
C17: 10.40-12.10 | D17: Л. Использование электронной информационно-образовательной среды РУС "ГЦОЛИФК" Шевцов А.В. (для направления 49.03.04 Спорт) - Арена УСЗК (Универсальный спортивно-зрелищный комплекс), Мирошников А.Б. (для направления 49.03.01 Физическая культура) - 220 ауд.к.
C18: 13.00-14.30 | D18: Л. Теория и методика физкультурно-оздоровительной деятельности и фитнеса 516мбк | E18: Л. Теория и методика единоборств Прил.1 | F18: Л. Теория и методика каратэ, тхэквондо, киокусинкай, ушу, тяжелоатлетических видов спорта Прил.1 | G18: Л. Теория и методика бокса, кикбоксинга, фехтования, современного пятиборья, стрелковых видов спорта, скалолазания Прил.1
C19: 14.50-16.20
C20: 16.40-18.10
A21: Среда | B21: =B16+1 -> 46267 | C21: 8.50-10.20 | D21: Л. Волейбол Ефимов А.С. 214ауд.к. | E21: Л. Волейбол Ефимов А.С. 214ауд.к. | F21: Л. Волейбол Ефимов А.С. 214ауд.к. | G21: Л. Волейбол Ефимов А.С. 214ауд.к.
C22: 10.40-12.10 | D22: Л. Элективные дисциплины по ФКиС: Подвижные игры Салахудинова Е.С. 214ауд.к. | E22: Л. Элективные дисциплины по ФКиС: Подвижные игры Салахудинова Е.С. 214ауд.к. | F22: Л. Элективные дисциплины по ФКиС: Подвижные игры Салахудинова Е.С. 214ауд.к. | G22: Л. Элективные дисциплины по ФКиС: Подвижные игры Салахудинова Е.С. 214ауд.к.
C23: 13.00-14.30
C24: 14.50-16.20
C25: 16.40-18.10
A26: Четверг | B26: =B21+1 -> 46268 | C26: 8.50-10.20 | D26: Л. Гимнастика Михалина Г.М. 214ауд.к. | E26: Л. Гимнастика Михалина Г.М. 214ауд.к. | F26: Л. Гимнастика Михалина Г.М. 214ауд.к. | G26: Л. Гимнастика Михалина Г.М. 214ауд.к.
C27: 10.40-12.10 | D27: Л. Гимнастика Ростовцева М.Ю. 214ауд.к. | E27: Л. Гимнастика Ростовцева М.Ю. 214ауд.к. | F27: Л. Гимнастика Ростовцева М.Ю. 214ауд.к. | G27: Л. Гимнастика Ростовцева М.Ю. 214ауд.к.
C28: 13.00-14.30 | D28: Л. Информационные технологии в сфере физической культуры и спорта Яшкина Е.Н. 214ауд.к. | E28: Л. Информационные технологии в сфере физической культуры и спорта Яшкина Е.Н. 214ауд.к. | F28: Л. Информационные технологии в сфере физической культуры и спорта Яшкина Е.Н. 214ауд.к. | G28: Л. Информационные технологии в сфере физической культуры и спорта Яшкина Е.Н. 214ауд.к.
C29: 14.50-16.20 | D29: Л. Информационные технологии в сфере физической культуры и спорта Яшкина Е.Н. 214ауд.к. | E29: Л. Информационные технологии в сфере физической культуры и спорта Яшкина Е.Н. 214ауд.к. | F29: Л. Информационные технологии в сфере физической культуры и спорта Яшкина Е.Н. 214ауд.к. | G29: Л. Информационные технологии в сфере физической культуры и спорта Яшкина Е.Н. 214ауд.к.
C30: 16.40-18.10
A31: Пятница | B31: =B26+1 -> 46269 | C31: 8.50-10.20
C32: 10.40-12.10 | D32: Л. Речевое общение в профессиональной деятельности Капустина Ю.А. 214 ауд.к. | E32: Л. Речевое общение в профессиональной деятельности Капустина Ю.А. 214 ауд.к. | F32: Л. Речевое общение в профессиональной деятельности Капустина Ю.А. 214 ауд.к. | G32: Л. Речевое общение в профессиональной деятельности Капустина Ю.А. 214 ауд.к.
C33: 13.00-14.30 | D33: Л. Физическая культура и спорт Мачканова Е.В. 214 ауд.к. | E33: Л. Физическая культура и спорт Мачканова Е.В. 214 ауд.к. | F33: Л. Физическая культура и спорт Мачканова Е.В. 214 ауд.к. | G33: Л. Физическая культура и спорт Мачканова Е.В. 214 ауд.к.
C34: 14.50-16.20 | D34: Л. Гимнастика Парахин В.А. 214 ауд.к. | E34: Л. Гимнастика Парахин В.А. 214 ауд.к. | F34: Л. Гимнастика Парахин В.А. 214 ауд.к. | G34: Л. Гимнастика Парахин В.А. 214 ауд.к.
C35: 16.40-18.10
A36: Суббота | B36: =B31+1 -> 46270 | C36: 8.50-10.20
C37: 10.40-12.10
C38: 13.00-14.30
C39: 14.50-16.20
C40: 16.40-18.10
B42: 10 | C42: *Л. Речевое общение в профессиональной деятельности* | D42: =COUNTIF(D$11:D$40,$C42) -> 1 | E42: =COUNTIF(E$11:E$40,$C42) -> 1 | F42: =COUNTIF(F$11:F$40,$C42) -> 1 | G42: =COUNTIF(G$11:G$40,$C42) -> 1
...

Sheet 07.09
B1: Расписание учебных занятий на первое полугодие 2026-2027 учебного года
B2: ТРЕНЕРСКИЙ ФАКУЛЬТЕТ, направление подготовки (образовательная программа)
A3: 49.03.04 Спорт*
B4: Факультет адаптивной физической культуры, рекреации и туризма, направление подготовки (образовательная программа)
B5: 49.03.01 Физическая культура*
B6: Курс 1, семестр 1, очная форма обучения
B7: группы С2-07-26, С2-08-26, С2-09-26, Т1-04-26
A9: День недели | B9: Дата | C9: Время | D9: Т1-04-26 | E9: 7 группа | F9: 8 группа | G9: 9 группа
D10: Физкультурно-оздоровительная деятельность и фитнес (ФОДиФ) | E10: Единоборства (армспорт, греко-римская борьба, вольная борьба, дзюдо, самбо, служебно-прикладные единоборства) | F10: киокусинкай, ушу, тхэквондо (ВТФ, ИТФ), тяжелоатлетические виды спорта | G10: Бокс, кикбоксинг, современное пятиборье, фехтование, стрелковые виды спорта, скалолазание
A11: Понедельник | B11: 46272 | C11: 8.50-10.20 | D11: Пр. Информационные технологии в сфере физической культуры и спорта Яшкина Е.Н. 277мбк | E11: Пр. Волейбол Ефимов А.С. 230СК
C12: 10.40-12.10 | D12: Л. Анатомия человека Силаева Л.В. 220 ауд.к. | E12: Л. Анатомия человека Силаева Л.В. 220 ауд.к. | F12: Л. Анатомия человека Силаева Л.В. 220 ауд.к. | G12: Л. Анатомия человека Силаева Л.В. 220 ауд.к.
C13: 13.00-14.30 | D13: Л. Речевое общение в профессиональной деятельности Капустина Ю.А. 214 ауд.к. | E13: Л. Речевое общение в профессиональной деятельности Капустина Ю.А. 214 ауд.к. | F13: Л. Речевое общение в профессиональной деятельности Капустина Ю.А. 214 ауд.к. | G13: Л. Речевое общение в профессиональной деятельности Капустина Ю.А. 214 ауд.к.
C14: 14.50-16.20 | D14: Л. Физическая культура и спорт Мачканова Е.В. 220 ауд.к. | E14: Л. Физическая культура и спорт Мачканова Е.В. 220 ауд.к. | F14: Л. Физическая культура и спорт Мачканова Е.В. 220 ауд.к. | G14: Л. Физическая культура и спорт Мачканова Е.В. 220 ауд.к.
C15: 16.40-18.10
A16: Вторник | B16: =B11+1 -> 46273 | C16: 8.50-10.20 | D16: Пр. Теория и методика физкультурно-оздоровительной деятельности и фитнеса Прил.1 | E16: Пр. Теория и методика единоборств Прил.1 | F16: Пр. Теория и методика каратэ, тхэквондо, киокусинкай, ушу, тяжелоатлетических видов спорта Прил.1 | G16: Пр. Теория и методика бокса, кикбоксинга, фехтования, современного пятиборья, стрелковых видов спорта, скалолазания Прил.1
C17: 10.40-12.10 | D17: Пр. Теория и методика физкультурно-оздоровительной деятельности и фитнеса Прил.1 | E17: Пр. Теория и методика единоборств Прил.1 | F17: Пр. Теория и методика каратэ, тхэквондо, киокусинкай, ушу, тяжелоатлетических видов спорта Прил.1 | G17: Пр. Теория и методика бокса, кикбоксинга, фехтования, современного пятиборья, стрелковых видов спорта, скалолазания Прил.1
C18: 13.00-14.30 | D18: Пр. Иностранный язык Литвинов С.В. 512гл.к. | E18: Пр. Волейбол Ефимов А.С. 230СК | G18: Пр. Гимнастика Дубовицкая И.А. 210СК
C19: 14.50-16.20 | D19: Пр. Волейбол Ефимов А.С. 230СК | E19: Пр. Иностранный язык Литвинов С.В. 512гл.к.
C20: 16.40-18.10
A21: Среда | B21: =B16+1 -> 46274 | C21: 8.50-10.20 | F21: Пр. Гимнастика Дубовицкая И.А. 210СК | G21: Пр. Информационные технологии в сфере физической культуры и спорта Яшкина Е.Н. 277мбк
C22: 10.40-12.10 | E22: Пр. Гимнастика Колесникова Е.С. 206СК | F22: Пр. Информационные технологии в сфере физической культуры и спорта Яшкина Е.Н. 277мбк | G22: Пр. Элективные дисциплины по ФКиС: Подвижные игры Дробышевская Н.В. Модуль Б
C23: 13.00-14.30 | D23: Пр. Элективные дисциплины по ФКиС: Подвижные игры Салахудинова Е.С. Модуль Б | E23: Пр. Информационные технологии в сфере физической культуры и спорта Яшкина Е.Н. 277мбк | F23: Пр. Иностранный язык Литвинов С.В. 508гл.к. | G23: Пр. Волейбол Ананьин А.С. 230СК
C24: 14.50-16.20 | D24: Пр. Волейбол Ефимов А.С. 230СК | E24: Пр. Элективные дисциплины по ФКиС: Подвижные игры Салахудинова Е.С. Модуль Б | G24: Пр. Иностранный язык Литвинов С.В. 508гл.к.
C25: 16.40-18.10
A26: Четверг | B26: =B21+1 -> 46275 | C26: 8.50-10.20
C27: 10.40-12.10
C28: 13.00-14.30 | F28: Пр. Элективные дисциплины по ФКиС: Подвижные игры Дробышевская Н.В. Модуль Б
C29: 14.50-16.20 | F29: Пр. Волейбол Суханова А.В. 230СК
C30: 16.40-18.10
A31: Пятница | B31: =B26+1 -> 46276 | C31: 8.50-10.20
C32: 10.40-12.10 | D32: Пр. Гимнастика Андреасян К.Б. 205СК | E32: Пр. Гимнастика Колесникова Е.С. 206СК | F32: Пр. Волейбол Суханова А.В. 230СК | G32: Пр. Волейбол Ананьин А.С. 230СК
C33: 13.00-14.30 | D33: Пр. Теория и методика физкультурно-оздоровительной деятельности и фитнеса Прил.1 | E33: Пр. Теория и методика единоборств Прил.1 | F33: Пр. Теория и методика каратэ, тхэквондо, киокусинкай, ушу, тяжелоатлетических видов спорта Прил.1 | G33: Пр. Теория и методика бокса, кикбоксинга, фехтования, современного пятиборья, стрелковых видов спорта, скалолазания Прил.1
C34: 14.50-16.20 | D34: Пр. Теория и методика физкультурно-оздоровительной деятельности и фитнеса Прил.1 | E34: Пр. Теория и методика единоборств Прил.1 | F34: Пр. Теория и методика каратэ, тхэквондо, киокусинкай, ушу, тяжелоатлетических видов спорта Прил.1 | G34: Пр. Теория и методика бокса, кикбоксинга, фехтования, современного пятиборья, стрелковых видов спорта, скалолазания Прил.1
C35: 16.40-18.10
A36: Суббота | B36: =B31+1 -> 46277 | C36: 8.50-10.20
C37: 10.40-12.10
C38: 13.00-14.30
C39: 14.50-16.20
C40: 16.40-18.10
D41: * Профили (направленность) указанны на титульном листе
...

Sheet 14.09
B1: Расписание учебных занятий на второе полугодие 2025-2026 учебного года
B2: ТРЕНЕРСКИЙ ФАКУЛЬТЕТ, направление подготовки (образовательная программа)
A3: 49.03.04 Спорт*
B4: Факультет адаптивной физической культуры, рекреации и туризма, направление подготовки (образовательная программа)
B5: 49.03.01 Физическая культура*
B6: Курс 1, семестр 2, очная форма обучения
B7: группы С2-07-26, С2-08-26, С2-09-26, Т1-04-26
A9: День недели | B9: Дата | C9: Время | D9: Т1-04-26 | E9: 7 группа | F9: 8 группа | G9: 9 группа
D10: Физкультурно-оздоровительная деятельность и фитнес (ФОДиФ) | E10: Единоборства (армспорт, греко-римская борьба, вольная борьба, дзюдо, самбо, служебно-прикладные единоборства) | F10: киокусинкай, ушу, тхэквондо (ВТФ, ИТФ), тяжелоатлетические виды спорта | G10: Бокс, кикбоксинг, современное пятиборье, фехтование, стрелковые виды спорта, скалолазание
A11: Понедельник | B11: 46279 | C11: 8.50-10.20 | D11: Пр. Информационные технологии в сфере физической культуры и спорта Яшкина Е.Н. 277мбк | E11: Пр. Волейбол Ефимов А.С. 230СК
C12: 10.40-12.10 | D12: Л. Анатомия человека Силаева Л.В. 220 ауд.к. | E12: Л. Анатомия человека Силаева Л.В. 220 ауд.к. | F12: Л. Анатомия человека Силаева Л.В. 220 ауд.к. | G12: Л. Анатомия человека Силаева Л.В. 220 ауд.к.
C13: 13.00-14.30 | D13: Л. Речевое общение в профессиональной деятельности Капустина Ю.А. 220 ауд.к. | E13: Л. Речевое общение в профессиональной деятельности Капустина Ю.А. 220 ауд.к. | F13: Л. Речевое общение в профессиональной деятельности Капустина Ю.А. 220 ауд.к. | G13: Л. Речевое общение в профессиональной деятельности Капустина Ю.А. 220 ауд.к.
C14: 14.50-16.20 | D14: Л. Физическая культура и спорт Мачканова Е.В. 220 ауд.к. | E14: Л. Физическая культура и спорт Мачканова Е.В. 220 ауд.к. | F14: Л. Физическая культура и спорт Мачканова Е.В. 220 ауд.к. | G14: Л. Физическая культура и спорт Мачканова Е.В. 220 ауд.к.
C15: 16.40-18.10
A16: Вторник | B16: =B11+1 -> 46280 | C16: 8.50-10.20 | D16: Пр. Теория и методика физкультурно-оздоровительной деятельности и фитнеса Прил.1 | E16: Пр. Теория и методика единоборств Прил.1 | F16: Пр. Теория и методика каратэ, тхэквондо, киокусинкай, ушу, тяжелоатлетических видов спорта Прил.1 | G16: Пр. Теория и методика бокса, кикбоксинга, фехтования, современного пятиборья, стрелковых видов спорта, скалолазания Прил.1
C17: 10.40-12.10 | D17: Пр. Теория и методика физкультурно-оздоровительной деятельности и фитнеса Прил.1 | E17: Пр. Теория и методика единоборств Прил.1 | F17: Пр. Теория и методика каратэ, тхэквондо, киокусинкай, ушу, тяжелоатлетических видов спорта Прил.1 | G17: Пр. Теория и методика бокса, кикбоксинга, фехтования, современного пятиборья, стрелковых видов спорта, скалолазания Прил.1
C18: 13.00-14.30 | D18: Пр. Иностранный язык Литвинов С.В. 512гл.к. | E18: Пр. Волейбол Ефимов А.С. 230СК | G18: Пр. Гимнастика Дубовицкая И.А. 210СК
C19: 14.50-16.20 | D19: Пр. Волейбол Ефимов А.С. 230СК | E19: Пр. Иностранный язык Литвинов С.В. 512гл.к.
C20: 16.40-18.10
A21: Среда | B21: =B16+1 -> 46281 | C21: 8.50-10.20 | F21: Пр. Гимнастика Дубовицкая И.А. 210СК | G21: Пр. Информационные технологии в сфере физической культуры и спорта Яшкина Е.Н. 277мбк
C22: 10.40-12.10 | E22: Пр. Гимнастика Колесникова Е.С. 206СК | F22: Пр. Информационные технологии в сфере физической культуры и спорта Яшкина Е.Н. 277мбк | G22: Пр. Элективные дисциплины по ФКиС: Подвижные игры Дробышевская Н.В. Модуль Б
C23: 13.00-14.30 | D23: Пр. Элективные дисциплины по ФКиС: Подвижные игры Салахудинова Е.С. Модуль Б | E23: Пр. Информационные технологии в сфере физической культуры и спорта Яшкина Е.Н. 277мбк | F23: Пр. Иностранный язык Литвинов С.В. 508гл.к. | G23: Пр. Волейбол Ананьин А.С. 230СК
C24: 14.50-16.20 | D24: Пр. Волейбол Ефимов А.С. 230СК | E24: Пр. Элективные дисциплины по ФКиС: Подвижные игры Салахудинова Е.С. Модуль Б | G24: Пр. Иностранный язык Литвинов С.В. 508гл.к.
C25: 16.40-18.10
A26: Четверг | B26: =B21+1 -> 46282 | C26: 8.50-10.20
C27: 10.40-12.10
C28: 13.00-14.30 | F28: Пр. Элективные дисциплины по ФКиС: Подвижные игры Дробышевская Н.В. Модуль Б
C29: 14.50-16.20 | F29: Пр. Волейбол Суханова А.В. 230СК
C30: 16.40-18.10
A31: Пятница | B31: =B26+1 -> 46283 | C31: 8.50-10.20
C32: 10.40-12.10 | D32: Пр. Гимнастика Андреасян К.Б. 205СК | E32: Пр. Гимнастика Колесникова Е.С. 206СК | F32: Пр. Волейбол Суханова А.В. 230СК | G32: Пр. Волейбол Ананьин А.С. 230СК
C33: 13.00-14.30 | D33: Пр. Теория и методика физкультурно-оздоровительной деятельности и фитнеса Прил.1 | E33: Пр. Теория и методика единоборств Прил.1 | F33: Пр. Теория и методика каратэ, тхэквондо, киокусинкай, ушу, тяжелоатлетических видов спорта Прил.1 | G33: Пр. Теория и методика бокса, кикбоксинга, фехтования, современного пятиборья, стрелковых видов спорта, скалолазания Прил.1
C34: 14.50-16.20 | D34: Пр. Теория и методика физкультурно-оздоровительной деятельности и фитнеса Прил.1 | E34: Пр. Теория и методика единоборств Прил.1 | F34: Пр. Теория и методика каратэ, тхэквондо, киокусинкай, ушу, тяжелоатлетических видов спорта Прил.1 | G34: Пр. Теория и методика бокса, кикбоксинга, фехтования, современного пятиборья, стрелковых видов спорта, скалолазания Прил.1
C35: 16.40-18.10
A36: Суббота | B36: =B31+1 -> 46284 | C36: 8.50-10.20
C37: 10.40-12.10
C38: 13.00-14.30
C39: 14.50-16.20
C40: 16.40-18.10
D41: * Профили (направленность) указанны на титульном листе
...

Sheet 21.09
B1: Расписание учебных занятий на второе полугодие 2025-2026 учебного года
B2: ТРЕНЕРСКИЙ ФАКУЛЬТЕТ, направление подготовки (образовательная программа)
A3: 49.03.04 Спорт*
B4: Факультет адаптивной физической культуры, рекреации и туризма, направление подготовки (образовательная программа)
B5: 49.03.01 Физическая культура*
B6: Курс 1, семестр 2, очная форма обучения
B7: группы С2-07-26, С2-08-26, С2-09-26, Т1-04-26
A9: День недели | B9: Дата | C9: Время | D9: Т1-04-26 | E9: 7 группа | F9: 8 группа | G9: 9 группа
D10: Физкультурно-оздоровительная деятельность и фитнес (ФОДиФ) | E10: Единоборства (армспорт, греко-римская борьба, вольная борьба, дзюдо, самбо, служебно-прикладные единоборства) | F10: киокусинкай, ушу, тхэквондо (ВТФ, ИТФ), тяжелоатлетические виды спорта | G10: Бокс, кикбоксинг, современное пятиборье, фехтование, стрелковые виды спорта, скалолазание
A11: Понедельник | B11: 46286 | C11: 8.50-10.20 | D11: Пр. Информационные технологии в сфере физической культуры и спорта Яшкина Е.Н. 277мбк | E11: Пр. Волейбол Ефимов А.С. 230СК
C12: 10.40-12.10 | D12: Л. Анатомия человека Силаева Л.В. 216 ауд.к. | E12: Л. Анатомия человека Силаева Л.В. 216 ауд.к. | F12: Л. Анатомия человека Силаева Л.В. 216 ауд.к. | G12: Л. Анатомия человека Силаева Л.В. 216 ауд.к.
C13: 13.00-14.30 | D13: Л. Речевое общение в профессиональной деятельности Капустина Ю.А. 216 ауд.к. | E13: Л. Речевое общение в профессиональной деятельности Капустина Ю.А. 216 ауд.к. | F13: Л. Речевое общение в профессиональной деятельности Капустина Ю.А. 216 ауд.к. | G13: Л. Речевое общение в профессиональной деятельности Капустина Ю.А. 216 ауд.к.
C14: 14.50-16.20 | D14: Л. Физическая культура и спорт Мачканова Е.В. 216 ауд.к. | E14: Л. Физическая культура и спорт Мачканова Е.В. 216 ауд.к. | F14: Л. Физическая культура и спорт Мачканова Е.В. 216 ауд.к. | G14: Л. Физическая культура и спорт Мачканова Е.В. 216 ауд.к.
C15: 16.40-18.10
A16: Вторник | B16: =B11+1 -> 46287 | C16: 8.50-10.20 | D16: Пр. Теория и методика физкультурно-оздоровительной деятельности и фитнеса Прил.1 | E16: Пр. Теория и методика единоборств Прил.1 | F16: Пр. Теория и методика каратэ, тхэквондо, киокусинкай, ушу, тяжелоатлетических видов спорта Прил.1 | G16: Пр. Теория и методика бокса, кикбоксинга, фехтования, современного пятиборья, стрелковых видов спорта, скалолазания Прил.1
C17: 10.40-12.10 | D17: Пр. Теория и методика физкультурно-оздоровительной деятельности и фитнеса Прил.1 | E17: Пр. Теория и методика единоборств Прил.1 | F17: Пр. Теория и методика каратэ, тхэквондо, киокусинкай, ушу, тяжелоатлетических видов спорта Прил.1 | G17: Пр. Теория и методика бокса, кикбоксинга, фехтования, современного пятиборья, стрелковых видов спорта, скалолазания Прил.1
C18: 13.00-14.30 | D18: Пр. Иностранный язык Литвинов С.В. 512гл.к. | E18: Пр. Волейбол Ефимов А.С. 230СК | G18: Пр. Гимнастика Дубовицкая И.А. 210СК
C19: 14.50-16.20 | D19: Пр. Волейбол Ефимов А.С. 230СК | E19: Пр. Иностранный язык Литвинов С.В. 512гл.к.
C20: 16.40-18.10
A21: Среда | B21: =B16+1 -> 46288 | C21: 8.50-10.20 | F21: Пр. Гимнастика Дубовицкая И.А. 210СК | G21: Пр. Информационные технологии в сфере физической культуры и спорта Яшкина Е.Н. 277мбк
C22: 10.40-12.10 | E22: Пр. Гимнастика Колесникова Е.С. 206СК | F22: Пр. Информационные технологии в сфере физической культуры и спорта Яшкина Е.Н. 277мбк | G22: Пр. Элективные дисциплины по ФКиС: Подвижные игры Дробышевская Н.В. Модуль Б
C23: 13.00-14.30 | D23: Пр. Элективные дисциплины по ФКиС: Подвижные игры Салахудинова Е.С. Модуль Б | E23: Пр. Информационные технологии в сфере физической культуры и спорта Яшкина Е.Н. 277мбк | F23: Пр. Иностранный язык Литвинов С.В. 508гл.к. | G23: Пр. Волейбол Ананьин А.С. 230СК
C24: 14.50-16.20 | D24: Пр. Волейбол Ефимов А.С. 230СК | E24: Пр. Элективные дисциплины по ФКиС: Подвижные игры Салахудинова Е.С. Модуль Б | G24: Пр. Иностранный язык Литвинов С.В. 508гл.к.
C25: 16.40-18.10
A26: Четверг | B26: =B21+1 -> 46289 | C26: 8.50-10.20
C27: 10.40-12.10
C28: 13.00-14.30 | F28: Пр. Элективные дисциплины по ФКиС: Подвижные игры Дробышевская Н.В. Модуль Б
C29: 14.50-16.20 | F29: Пр. Волейбол Суханова А.В. 230СК
C30: 16.40-18.10
A31: Пятница | B31: =B26+1 -> 46290 | C31: 8.50-10.20
C32: 10.40-12.10 | D32: Пр. Гимнастика Андреасян К.Б. 205СК | E32: Пр. Гимнастика Колесникова Е.С. 206СК | F32: Пр. Волейбол Суханова А.В. 230СК | G32: Пр. Волейбол Ананьин А.С. 230СК
C33: 13.00-14.30 | D33: Пр. Теория и методика физкультурно-оздоровительной деятельности и фитнеса Прил.1 | E33: Пр. Теория и методика единоборств Прил.1 | F33: Пр. Теория и методика каратэ, тхэквондо, киокусинкай, ушу, тяжелоатлетических видов спорта Прил.1 | G33: Пр. Теория и методика бокса, кикбоксинга, фехтования, современного пятиборья, стрелковых видов спорта, скалолазания Прил.1
C34: 14.50-16.20 | D34: Пр. Теория и методика физкультурно-оздоровительной деятельности и фитнеса Прил.1 | E34: Пр. Теория и методика единоборств Прил.1 | F34: Пр. Теория и методика каратэ, тхэквондо, киокусинкай, ушу, тяжелоатлетических видов спорта Прил.1 | G34: Пр. Теория и методика бокса, кикбоксинга, фехтования, современного пятиборья, стрелковых видов спорта, скалолазания Прил.1
C35: 16.40-18.10
A36: Суббота | B36: =B31+1 -> 46291 | C36: 8.50-10.20
C37: 10.40-12.10
C38: 13.00-14.30
C39: 14.50-16.20
C40: 16.40-18.10
D41: * Профили (направленность) указанны на титульном листе
...

Sheet 28.09
B1: Расписание учебных занятий на второе полугодие 2025-2026 учебного года
B2: ТРЕНЕРСКИЙ ФАКУЛЬТЕТ, направление подготовки (образовательная программа)
A3: 49.03.04 Спорт*
B4: Факультет адаптивной физической культуры, рекреации и туризма, направление подготовки (образовательная программа)
B5: 49.03.01 Физическая культура*
B6: Курс 1, семестр 2, очная форма обучения
B7: группы С2-07-26, С2-08-26, С2-09-26, Т1-04-26
A9: День недели | B9: Дата | C9: Время | D9: Т1-04-26 | E9: 7 группа | F9: 8 группа | G9: 9 группа
D10: Физкультурно-оздоровительная деятельность и фитнес (ФОДиФ) | E10: Единоборства (армспорт, греко-римская борьба, вольная борьба, дзюдо, самбо, служебно-прикладные единоборства) | F10: киокусинкай, ушу, тхэквондо (ВТФ, ИТФ), тяжелоатлетические виды спорта | G10: Бокс, кикбоксинг, современное пятиборье, фехтование, стрелковые виды спорта, скалолазание
A11: Понедельник | B11: 46293 | C11: 8.50-10.20 | D11: Пр. Информационные технологии в сфере физической культуры и спорта Яшкина Е.Н. 277мбк | E11: Пр. Волейбол Ефимов А.С. 230СК | F11: Пр. Физическая культура и спорт Трунева Т.В. 308 гл.к.- только 28.09
C12: 10.40-12.10 | D12: Л. Анатомия человека Силаева Л.В. 216 ауд.к. | E12: Л. Анатомия человека Силаева Л.В. 216 ауд.к. | F12: Л. Анатомия человека Силаева Л.В. 216 ауд.к. | G12: Л. Анатомия человека Силаева Л.В. 216 ауд.к.
C13: 13.00-14.30 | D13: Л. Речевое общение в профессиональной деятельности Капустина Ю.А. 216 ауд.к. | E13: Л. Речевое общение в профессиональной деятельности Капустина Ю.А. 216 ауд.к. | F13: Л. Речевое общение в профессиональной деятельности Капустина Ю.А. 216 ауд.к. | G13: Л. Речевое общение в профессиональной деятельности Капустина Ю.А. 216 ауд.к.
C14: 14.50-16.20 | D14: Л. Физическая культура и спорт Мачканова Е.В. 216 ауд.к. | E14: Л. Физическая культура и спорт Мачканова Е.В. 216 ауд.к. | F14: Л. Физическая культура и спорт Мачканова Е.В. 216 ауд.к. | G14: Л. Физическая культура и спорт Мачканова Е.В. 216 ауд.к.
C15: 16.40-18.10
A16: Вторник | B16: =B11+1 -> 46294 | C16: 8.50-10.20 | D16: Пр. Теория и методика физкультурно-оздоровительной деятельности и фитнеса Прил.1 | E16: Пр. Теория и методика единоборств Прил.1 | F16: Пр. Теория и методика каратэ, тхэквондо, киокусинкай, ушу, тяжелоатлетических видов спорта Прил.1 | G16: Пр. Теория и методика бокса, кикбоксинга, фехтования, современного пятиборья, стрелковых видов спорта, скалолазания Прил.1
C17: 10.40-12.10 | D17: Пр. Теория и методика физкультурно-оздоровительной деятельности и фитнеса Прил.1 | E17: Пр. Теория и методика единоборств Прил.1 | F17: Пр. Теория и методика каратэ, тхэквондо, киокусинкай, ушу, тяжелоатлетических видов спорта Прил.1 | G17: Пр. Теория и методика бокса, кикбоксинга, фехтования, современного пятиборья, стрелковых видов спорта, скалолазания Прил.1
C18: 13.00-14.30 | D18: Пр. Иностранный язык Литвинов С.В. 512гл.к. | E18: Пр. Волейбол Ефимов А.С. 230СК | G18: Пр. Гимнастика Дубовицкая И.А. 210СК
C19: 14.50-16.20 | D19: Пр. Волейбол Ефимов А.С. 230СК | E19: Пр. Иностранный язык Литвинов С.В. 512гл.к.
C20: 16.40-18.10
A21: Среда | B21: =B16+1 -> 46295 | C21: 8.50-10.20 | D21: Пр. Гимнастика Андреасян К.Б. 205СК | E21: Пр. Физическая культура и спорт Трунева Т.В. 308 гл.к. - только 30.09 | F21: Пр. Гимнастика Дубовицкая И.А. 210СК | G21: Пр. Информационные технологии в сфере физической культуры и спорта Яшкина Е.Н. 277мбк
C22: 10.40-12.10 | D22: Пр. Физическая культура и спорт Трунева Т.В. 308 гл.к. | E22: Пр. Гимнастика Колесникова Е.С. 206СК | F22: Пр. Информационные технологии в сфере физической культуры и спорта Яшкина Е.Н. 277мбк | G22: Пр. Элективные дисциплины по ФКиС: Подвижные игры Дробышевская Н.В. Модуль Б
C23: 13.00-14.30 | D23: Пр. Элективные дисциплины по ФКиС: Подвижные игры Салахудинова Е.С. Модуль Б | E23: Пр. Информационные технологии в сфере физической культуры и спорта Яшкина Е.Н. 277мбк | F23: Пр. Иностранный язык Литвинов С.В. 508гл.к. | G23: Пр. Волейбол Ананьин А.С. 230СК
C24: 14.50-16.20 | D24: Пр. Волейбол Ефимов А.С. 230СК | E24: Пр. Элективные дисциплины по ФКиС: Подвижные игры Салахудинова Е.С. Модуль Б | F24: Пр. Использование электронной информационно-образовательной среды РУС "ГЦОЛИФК" Шевцов А.В. 218 ауд.к. | G24: Пр. Иностранный язык Литвинов С.В. 508гл.к.
C25: 16.40-18.10 | G25: Пр. Физическая культура и спорт Трунева Т.В. 308 гл.к. - только 30.09
A26: Четверг | B26: =B21+1 -> 46296 | C26: 8.50-10.20
C27: 10.40-12.10
C28: 13.00-14.30 | F28: Пр. Элективные дисциплины по ФКиС: Подвижные игры Дробышевская Н.В. Модуль Б
C29: 14.50-16.20 | F29: Пр. Волейбол Суханова А.В. 230СК
C30: 16.40-18.10
A31: Пятница | B31: =B26+1 -> 46297 | C31: 8.50-10.20 | D31: Пр. Использование электронной информационно-образовательной среды РУС "ГЦОЛИФК" Мирошников А.Б. 214 ауд.к.
C32: 10.40-12.10 | D32: Пр. Гимнастика Андреасян К.Б. 205СК | E32: Пр. Гимнастика Колесникова Е.С. 206СК | F32: Пр. Волейбол Суханова А.В. 230СК | G32: Пр. Волейбол Ананьин А.С. 230СК
C33: 13.00-14.30 | D33: Л. Теория и методика физкультурно-оздоровительной деятельности и фитнеса 514мбк | E33: Л. Теория и методика единоборств Прил.1 | F33: Л. Теория и методика каратэ, тхэквондо, киокусинкай, ушу, тяжелоатлетических видов спорта Прил.1 | G33: Л. Теория и методика бокса, кикбоксинга, фехтования, современного пятиборья, стрелковых видов спорта, скалолазания Прил.1
C34: 14.50-16.20 | D34: Пр. Теория и методика физкультурно-оздоровительной деятельности и фитнеса Прил.1 | E34: Пр. Теория и методика единоборств Прил.1 | F34: Пр. Теория и методика каратэ, тхэквондо, киокусинкай, ушу, тяжелоатлетических видов спорта Прил.1 | G34: Пр. Теория и методика бокса, кикбоксинга, фехтования, современного пятиборья, стрелковых видов спорта, скалолазания Прил.1
C35: 16.40-18.10
A36: Суббота | B36: =B31+1 -> 46298 | C36: 8.50-10.20
C37: 10.40-12.10
C38: 13.00-14.30
C39: 14.50-16.20
C40: 16.40-18.10
D41: * Профили (направленность) указанны на титульном листе
...

Sheet 05.10
B1: Расписание учебных занятий на второе полугодие 2025-2026 учебного года
B2: ТРЕНЕРСКИЙ ФАКУЛЬТЕТ, направление подготовки (образовательная программа)
A3: 49.03.04 Спорт*
B4: Факультет адаптивной физической культуры, рекреации и туризма, направление подготовки (образовательная программа)
B5: 49.03.01 Физическая культура*
B6: Курс 1, семестр 2, очная форма обучения
B7: группы С2-07-26, С2-08-26, С2-09-26, Т1-04-26
A9: День недели | B9: Дата | C9: Время | D9: Т1-04-26 | E9: 7 группа | F9: 8 группа | G9: 9 группа
D10: Физкультурно-оздоровительная деятельность и фитнес (ФОДиФ) | E10: Единоборства (армспорт, греко-римская борьба, вольная борьба, дзюдо, самбо, служебно-прикладные единоборства) | F10: киокусинкай, ушу, тхэквондо (ВТФ, ИТФ), тяжелоатлетические виды спорта | G10: Бокс, кикбоксинг, современное пятиборье, фехтование, стрелковые виды спорта, скалолазание
A11: Понедельник | B11: 46300 | C11: 8.50-10.20 | D11: Пр. Информационные технологии в сфере физической культуры и спорта Яшкина Е.Н. 277мбк | E11: Пр. Волейбол Ефимов А.С. 230СК | G11: Пр. Физическая культура и спорт Трунева Т.В. 308 гл.к.
C12: 10.40-12.10 | D12: Пр. Анатомия человека Мештель А.В. 154мбк | E12: Пр. Физическая культура и спорт Трунева Т.В. 406 ауд.к. | F12: Пр. Речевое общение в профессиональной деятельности Капустина Ю.А. 513 гл.к. | G12: Пр. Анатомия человека Гричанова Т.Г. 151мбк
C13: 13.00-14.30 | E13: Пр. Речевое общение в профессиональной деятельности Капустина Ю.А. 406 ауд.к. | F13: Пр. Физическая культура и спорт Трунева Т.В. 308 гл.к. | G13: Пр. Гимнастика Дубовицкая И.А. 210СК
C14: 14.50-16.20 | F14: Пр. Гимнастика Дубовицкая И.А. 210СК | G14: Пр. Использование электронной информационно-образовательной среды РУС "ГЦОЛИФК" Шевцов А.В. 220ауд.к.
C15: 16.40-18.10
A16: Вторник | B16: =B11+1 -> 46301 | C16: 8.50-10.20 | E16: Пр. Теория и методика единоборств Прил.1 | F16: Пр. Теория и методика каратэ, тхэквондо, киокусинкай, ушу, тяжелоатлетических видов спорта Прил.1 | G16: Пр. Теория и методика бокса, кикбоксинга, фехтования, современного пятиборья, стрелковых видов спорта, скалолазания Прил.1
C17: 10.40-12.10 | D17: Пр. Теория и методика физкультурно-оздоровительной деятельности и фитнеса Прил.1 | E17: Пр. Теория и методика единоборств Прил.1 | F17: Пр. Теория и методика каратэ, тхэквондо, киокусинкай, ушу, тяжелоатлетических видов спорта Прил.1 | G17: Пр. Теория и методика бокса, кикбоксинга, фехтования, современного пятиборья, стрелковых видов спорта, скалолазания Прил.1
C18: 13.00-14.30 | D18: Пр. Иностранный язык Литвинов С.В. 512гл.к. | E18: Пр. Волейбол Ефимов А.С. 230СК | F18: Пр. Анатомия человека Мештель А.В. 72мбк | G18: Пр. Гимнастика Дубовицкая И.А. 210СК
C19: 14.50-16.20 | D19: Пр. Волейбол Ефимов А.С. 230СК | E19: Пр. Иностранный язык Литвинов С.В. 512гл.к. | F19: Пр. Использование электронной информационно-образовательной среды РУС "ГЦОЛИФК" Кузнецова Н.А. 216ауд.к.
C20: 16.40-18.10
A21: Среда | B21: =B16+1 -> 46302 | C21: 8.50-10.20 | D21: Пр. Гимнастика Андреасян К.Б. 205СК | F21: Пр. Гимнастика Дубовицкая И.А. 210СК | G21: Пр. Информационные технологии в сфере физической культуры и спорта Яшкина Е.Н. 277мбк
C22: 10.40-12.10 | D22: Пр. Физическая культура и спорт Трунева Т.В. 308 гл.к. | E22: Пр. Гимнастика Колесникова Е.С. 206СК | F22: Пр. Информационные технологии в сфере физической культуры и спорта Яшкина Е.Н. 277мбк | G22: Пр. Элективные дисциплины по ФКиС: Подвижные игры Дробышевская Н.В. Модуль Б
C23: 13.00-14.30 | D23: Пр. Элективные дисциплины по ФКиС: Подвижные игры Салахудинова Е.С. Модуль Б | E23: Пр. Информационные технологии в сфере физической культуры и спорта Яшкина Е.Н. 277мбк | F23: Пр. Иностранный язык Литвинов С.В. 508гл.к. | G23: Пр. Волейбол Ананьин А.С. 230СК
C24: 14.50-16.20 | D24: Пр. Волейбол Ефимов А.С. 230СК | E24: Пр. Элективные дисциплины по ФКиС: Подвижные игры Салахудинова Е.С. Модуль Б | G24: Пр. Иностранный язык Литвинов С.В. 508гл.к.
C25: 16.40-18.10
A26: Четверг | B26: =B21+1 -> 46303 | C26: 8.50-10.20
C27: 10.40-12.10
C28: 13.00-14.30 | F28: Пр. Элективные дисциплины по ФКиС: Подвижные игры Дробышевская Н.В. Модуль Б
C29: 14.50-16.20 | F29: Пр. Волейбол Суханова А.В. 230СК
C30: 16.40-18.10
A31: Пятница | B31: =B26+1 -> 46304 | C31: 8.50-10.20 | D31: Пр. Речевое общение в профессиональной деятельности Капустина Ю.А. 410 гл.к. | G31: Пр. Волейбол Ананьин А.С. 230СК
C32: 10.40-12.10 | D32: Пр. Гимнастика Андреасян К.Б. 205СК | E32: Пр. Анатомия человека Сироткина Ю.А. 154мбк | F32: Пр. Волейбол Суханова А.В. 230СК | G32: Пр. Речевое общение в профессиональной деятельности Капустина Ю.А. 410 гл.к.
C33: 13.00-14.30 | D33: Пр. Теория и методика физкультурно-оздоровительной деятельности и фитнеса Прил.1 | E33: Пр. Теория и методика единоборств Прил.1 | F33: Пр. Теория и методика каратэ, тхэквондо, киокусинкай, ушу, тяжелоатлетических видов спорта Прил.1 | G33: Пр. Теория и методика бокса, кикбоксинга, фехтования, современного пятиборья, стрелковых видов спорта, скалолазания Прил.1
C34: 14.50-16.20 | D34: Л. Теория и методика физкультурно-оздоровительной деятельности и фитнеса 516мбк | E34: Л. Теория и методика единоборств Прил.1 | F34: Л. Теория и методика каратэ, тхэквондо, киокусинкай, ушу, тяжелоатлетических видов спорта Прил.1 | G34: Л. Теория и методика бокса, кикбоксинга, фехтования, современного пятиборья, стрелковых видов спорта, скалолазания Прил.1
C35: 16.40-18.10
A36: Суббота | B36: =B31+1 -> 46305 | C36: 8.50-10.20
C37: 10.40-12.10
C38: 13.00-14.30
C39: 14.50-16.20
C40: 16.40-18.10
D41: * Профили (направленность) указанны на титульном листе
...

Sheet 12.10
B1: Расписание учебных занятий на второе полугодие 2025-2026 учебного года
B2: ТРЕНЕРСКИЙ ФАКУЛЬТЕТ, направление подготовки (образовательная программа)
A3: 49.03.04 Спорт*
B4: Факультет адаптивной физической культуры, рекреации и туризма, направление подготовки (образовательная программа)
B5: 49.03.01 Физическая культура*
B6: Курс 1, семестр 2, очная форма обучения
B7: группы С2-07-26, С2-08-26, С2-09-26, Т1-04-26
A9: День недели | B9: Дата | C9: Время | D9: Т1-04-26 | E9: 7 группа | F9: 8 группа | G9: 9 группа
D10: Физкультурно-оздоровительная деятельность и фитнес (ФОДиФ) | E10: Единоборства (армспорт, греко-римская борьба, вольная борьба, дзюдо, самбо, служебно-прикладные единоборства) | F10: киокусинкай, ушу, тхэквондо (ВТФ, ИТФ), тяжелоатлетические виды спорта | G10: Бокс, кикбоксинг, современное пятиборье, фехтование, стрелковые виды спорта, скалолазание
A11: Понедельник | B11: 46307 | C11: 8.50-10.20 | D11: Пр. Информационные технологии в сфере физической культуры и спорта Яшкина Е.Н. 277мбк | E11: Пр. Волейбол Ефимов А.С. 230СК | G11: Пр. Физическая культура и спорт Трунева Т.В. 308 гл.к.
C12: 10.40-12.10 | D12: Пр. Анатомия человека Мештель А.В. 154мбк | E12: Пр. Физическая культура и спорт Трунева Т.В. 406 ауд.к. | F12: Пр. Речевое общение в профессиональной деятельности Капустина Ю.А. 513 гл.к. | G12: Пр. Анатомия человека Гричанова Т.Г. 151мбк
C13: 13.00-14.30 | D13: Пр. Речевое общение в профессиональной деятельности Капустина Ю.А. 406 ауд.к. | F13: Пр. Физическая культура и спорт Трунева Т.В. 308 гл.к. | G13: Пр. Гимнастика Дубовицкая И.А. 210СК
C14: 14.50-16.20 | F14: Пр. Гимнастика Дубовицкая И.А. 210СК | G14: Пр. Элективные дисциплины по ФКиС: Подвижные игры Дробышевская Н.В. Модуль А - только 12.10
C15: 16.40-18.10
A16: Вторник | B16: =B11+1 -> 46308 | C16: 8.50-10.20 | E16: Пр. Теория и методика единоборств Прил.1 | F16: Пр. Теория и методика каратэ, тхэквондо, киокусинкай, ушу, тяжелоатлетических видов спорта Прил.1 | G16: Пр. Теория и методика бокса, кикбоксинга, скалолазания Прил.1
C17: 10.40-12.10 | D17: Пр. Теория и методика физкультурно-оздоровительной деятельности и фитнеса фитнес-зал№83 теннисный центр (2 п/группа) | E17: Пр. Теория и методика единоборств Прил.1 | F17: Пр. Теория и методика каратэ, тхэквондо, киокусинкай, ушу, тяжелоатлетических видов спорта Прил.1 | G17: Пр. Теория и методика бокса, кикбоксинга, фехтования, современного пятиборья, стрелковых видов спорта, скалолазания Прил.1
C18: 13.00-14.30 | D18: Пр. Иностранный язык Литвинов С.В. 512гл.к. | E18: Пр. Волейбол Ефимов А.С. 230СК | F18: Пр. Анатомия человека Мештель А.В. 72мбк | G18: Пр. Гимнастика Дубовицкая И.А. 210СК
C19: 14.50-16.20 | D19: Пр. Волейбол Ефимов А.С. 230СК | E19: Пр. Иностранный язык Литвинов С.В. 512гл.к. | G19: Пр. Использование электронной информационно-образовательной среды РУС "ГЦОЛИФК" Кузнецова Н.А. 216 ауд.к.
C20: 16.40-18.10
A21: Среда | B21: =B16+1 -> 46309 | C21: 8.50-10.20 | D21: Пр. Гимнастика Андреасян К.Б. 205СК | F21: Пр. Гимнастика Дубовицкая И.А. 210СК | G21: Пр. Информационные технологии в сфере физической культуры и спорта Яшкина Е.Н. 277мбк
C22: 10.40-12.10 | D22: Пр. Физическая культура и спорт Трунева Т.В. 308 гл.к. | E22: Пр. Гимнастика Колесникова Е.С. 206СК | F22: Пр. Информационные технологии в сфере физической культуры и спорта Яшкина Е.Н. 277мбк | G22: Пр. Элективные дисциплины по ФКиС: Подвижные игры Дробышевская Н.В. Модуль Б
C23: 13.00-14.30 | D23: Пр. Элективные дисциплины по ФКиС: Подвижные игры Салахудинова Е.С. Модуль Б | E23: Пр. Информационные технологии в сфере физической культуры и спорта Яшкина Е.Н. 277мбк | F23: Пр. Иностранный язык Литвинов С.В. 508гл.к. | G23: Пр. Волейбол Ананьин А.С. 230СК
C24: 14.50-16.20 | D24: Пр. Волейбол Ефимов А.С. 230СК | E24: Пр. Элективные дисциплины по ФКиС: Подвижные игры Салахудинова Е.С. Модуль Б | F24: Пр. Элективные дисциплины по ФКиС: Подвижные игры Дробышевская Н.В. Модуль В - только 14.10 | G24: Пр. Иностранный язык Литвинов С.В. 508гл.к.
C25: 16.40-18.10
A26: Четверг | B26: =B21+1 -> 46310 | C26: 8.50-10.20
C27: 10.40-12.10
C28: 13.00-14.30 | F28: Пр. Элективные дисциплины по ФКиС: Подвижные игры Дробышевская Н.В. Модуль Б
C29: 14.50-16.20 | F29: Пр. Волейбол Суханова А.В. 230СК
C30: 16.40-18.10
A31: Пятница | B31: =B26+1 -> 46311 | C31: 8.50-10.20 | D31: Пр. Теория и методика физкультурно-оздоровительной деятельности и фитнеса 213СК (2 п/группа) | E31: Пр. Речевое общение в профессиональной деятельности Капустина Ю.А. 410 гл.к. | G31: Пр. Волейбол Ананьин А.С. 230СК
C32: 10.40-12.10 | D32: Пр. Гимнастика Андреасян К.Б. 205СК | E32: Пр. Анатомия человека Сироткина Ю.А. 154мбк | F32: Пр. Волейбол Суханова А.В. 230СК | G32: Пр. Речевое общение в профессиональной деятельности Капустина Ю.А. 410 гл.к.
C33: 13.00-14.30 | D33: Пр. Теория и методика физкультурно-оздоровительной деятельности и фитнеса 213СК (1 п/группа) | E33: Пр. Теория и методика единоборств Прил.1 | F33: Пр. Теория и методика каратэ, тхэквондо, киокусинкай, ушу, тяжелоатлетических видов спорта Прил.1 | G33: Пр. Теория и методика бокса, кикбоксинга, фехтования, современного пятиборья, стрелковых видов спорта, скалолазания Прил.1
C34: 14.50-16.20 | D34: Пр. Теория и методика физкультурно-оздоровительной деятельности и фитнеса 213СК (1 п/группа) | E34: Пр. Использование электронной информационно-образовательной среды РУС "ГЦОЛИФК" Шевцов А.В. 220 ауд.к. | G34: Пр. Теория и методика фехтования, современного пятиборья, стрелковых видов спорта Прил.1
C35: 16.40-18.10
A36: Суббота | B36: =B31+1 -> 46312 | C36: 8.50-10.20 | D36: Пр. Теория и методика физкультурно-оздоровительной деятельности и фитнеса 213СК (2 п/группа)
C37: 10.40-12.10 | D37: Пр. Теория и методика физкультурно-оздоровительной деятельности и фитнеса 213СК (1 п/группа)
C38: 13.00-14.30
C39: 14.50-16.20
C40: 16.40-18.10
D41: * Профили (направленность) указанны на титульном листе
...

Sheet 19.10
B1: Расписание учебных занятий на второе полугодие 2025-2026 учебного года
B2: ТРЕНЕРСКИЙ ФАКУЛЬТЕТ, направление подготовки (образовательная программа)
A3: 49.03.04 Спорт*
B4: Факультет адаптивной физической культуры, рекреации и туризма, направление подготовки (образовательная программа)
B5: 49.03.01 Физическая культура*
B6: Курс 1, семестр 2, очная форма обучения
B7: группы С2-07-26, С2-08-26, С2-09-26, Т1-04-26
A9: День недели | B9: Дата | C9: Время | D9: Т1-04-26 | E9: 7 группа | F9: 8 группа | G9: 9 группа
D10: Физкультурно-оздоровительная деятельность и фитнес (ФОДиФ) | E10: Единоборства (армспорт, греко-римская борьба, вольная борьба, дзюдо, самбо, служебно-прикладные единоборства) | F10: киокусинкай, ушу, тхэквондо (ВТФ, ИТФ), тяжелоатлетические виды спорта | G10: Бокс, кикбоксинг, современное пятиборье, фехтование, стрелковые виды спорта, скалолазание
A11: Понедельник | B11: 46314 | C11: 8.50-10.20 | D11: Пр. Информационные технологии в сфере физической культуры и спорта Яшкина Е.Н. 277мбк | E11: Пр. Волейбол Ефимов А.С. 230СК | G11: Пр. Физическая культура и спорт Трунева Т.В. 308 гл.к.
C12: 10.40-12.10 | D12: Пр. Анатомия человека Мештель А.В. 154мбк | E12: Пр. Физическая культура и спорт Трунева Т.В. 406 ауд.к. | F12: Пр. Речевое общение в профессиональной деятельности Капустина Ю.А. 513 гл.к. | G12: Пр. Анатомия человека Гричанова Т.Г. 151мбк
C13: 13.00-14.30 | D13: Пр. Речевое общение в профессиональной деятельности Капустина Ю.А. 406 ауд.к. | F13: Пр. Физическая культура и спорт Трунева Т.В. 308 гл.к. | G13: Пр. Гимнастика Дубовицкая И.А. 210СК
C14: 14.50-16.20 | D14: Пр. Использование электронной информационно-образовательной среды РУС "ГЦОЛИФК" Кузнецова Н.А. | F14: Пр. Гимнастика Дубовицкая И.А. 210СК
C15: 16.40-18.10
A16: Вторник | B16: =B11+1 -> 46315 | C16: 8.50-10.20 | E16: Пр. Теория и методика единоборств Прил.1 | F16: Пр. Теория и методика каратэ, тхэквондо, киокусинкай, ушу, тяжелоатлетических видов спорта Прил.1 | G16: Пр. Теория и методика бокса, кикбоксинга, скалолазания Прил.1
C17: 10.40-12.10 | D17: Пр. Теория и методика физкультурно-оздоровительной деятельности и фитнеса фитнес-зал№83 теннисный центр (2 п/группа) | E17: Л. Теория и методика единоборств Прил.1 | F17: Л. Теория и методика каратэ, тхэквондо, киокусинкай, ушу, тяжелоатлетических видов спорта Прил.1 | G17: Л. Теория и методика бокса, кикбоксинга, фехтования, современного пятиборья, стрелковых видов спорта, скалолазания Прил.1
C18: 13.00-14.30 | D18: Пр. Иностранный язык Литвинов С.В. 512гл.к. | E18: Пр. Волейбол Ефимов А.С. 230СК | F18: Пр. Анатомия человека Мештель А.В. 72мбк | G18: Пр. Гимнастика Дубовицкая И.А. 210СК
C19: 14.50-16.20 | D19: Пр. Волейбол Ефимов А.С. 230СК | E19: Пр. Иностранный язык Литвинов С.В. 512гл.к.
C20: 16.40-18.10
A21: Среда | B21: =B16+1 -> 46316 | C21: 8.50-10.20 | D21: Пр. Гимнастика Андреасян К.Б. 205СК | E21: Пр. Использование электронной информационно-образовательной среды РУС "ГЦОЛИФК" Кузнецова Н.А. | F21: Пр. Гимнастика Дубовицкая И.А. 210СК | G21: Пр. Информационные технологии в сфере физической культуры и спорта Яшкина Е.Н. 277мбк
C22: 10.40-12.10 | D22: Пр. Физическая культура и спорт Трунева Т.В. 308 гл.к. | E22: Пр. Гимнастика Колесникова Е.С. 206СК | F22: Пр. Информационные технологии в сфере физической культуры и спорта Яшкина Е.Н. 277мбк | G22: Пр. Элективные дисциплины по ФКиС: Подвижные игры Дробышевская Н.В. Модуль Б
C23: 13.00-14.30 | D23: Пр. Элективные дисциплины по ФКиС: Подвижные игры Салахудинова Е.С. Модуль Б | E23: Пр. Информационные технологии в сфере физической культуры и спорта Яшкина Е.Н. 277мбк | F23: Пр. Иностранный язык Литвинов С.В. 508гл.к. | G23: Пр. Волейбол Ананьин А.С. 230СК
C24: 14.50-16.20 | D24: Пр. Волейбол Ефимов А.С. 230СК | E24: Пр. Элективные дисциплины по ФКиС: Подвижные игры Салахудинова Е.С. Модуль Б | G24: Пр. Иностранный язык Литвинов С.В. 508гл.к.
C25: 16.40-18.10
A26: Четверг | B26: =B21+1 -> 46317 | C26: 8.50-10.20
C27: 10.40-12.10
C28: 13.00-14.30 | F28: Пр. Элективные дисциплины по ФКиС: Подвижные игры Дробышевская Н.В. Модуль Б
C29: 14.50-16.20 | F29: Пр. Волейбол Суханова А.В. 230СК
