Workbook
Name SIGN: #REF!
Name SIGN: #REF!
Name SIGN: #REF!
Name SIGN: #REF!
Name SIGN: #REF!
Name SIGN: #REF!
Name SIGN_D: #REF!
Name SIGN_D: #REF!
Name SIGN_D: #REF!
Name SIGN_D: #REF!
Name SIGN_D: #REF!
Name SIGN_D: #REF!
Name Sign1: #REF!
Name Sign1: #REF!
Name Sign1: #REF!
Name Sign1: #REF!
Name Sign1: #REF!
Name Sign1: #REF!
Name и: #REF!
Name и: #REF!
Name и: #REF!
Name и: #REF!
Name и: #REF!
Name и: #REF!
Name оо: #REF!
Name оо: #REF!
Name оо: #REF!
Name оо: #REF!
Name оо: #REF!
Name Р1: #REF!
Name Р1: #REF!
Name Р1: #REF!
Name Р1: #REF!
Name Р1: #REF!
Name Р1: #REF!
Name ыва: #REF!
Name ыва: #REF!
Name ыва: #REF!
Name ыва: #REF!
Name ыва: #REF!
Name ыва: #REF!

Sheet титульный лист

Sheet Титул
J1: УТВЕРЖДАЮ
J2: Начальник учебно-методического управления
J3: Р.С. Халимулина
J4: _________________________________
J5: «____»____________________20___г.
A7: Расписание учебных занятий на первое полугодие 2026-2027 учебного года
A8: ТРЕНЕРСКИЙ ФАКУЛЬТЕТ, направление подготовки (образовательная программа)
A9: 49.03.04 Спорт, Профиль (направленность): Спортивная подготовка по виду спорта «баскетбол». Педагогическая деятельность в области физической культуры и спорта; Спортивная подготовка по виду спорта «волейбол». Педагогическая деятельность в области физической культуры и спорта; Спортивная подготовка по видам спорта «гандбол», «бейсбол», «регби». Педагогическая деятельность в области физической культуры и спорта; Спортивная подготовка в интеллектуальных и технологичных видах спорта. Педагогическая деятельность в области физической культуры и спорта; Спортивная подготовка по виду спорта «теннис». Педагогическая деятельность в области физической культуры и спорта; Спортивная подготовка по виду спорта «хоккей». Педагогическая деятельность в области физической культуры и спорта; Спортивная подготовка по виду спорта «футбол». Педагогическая деятельность в области физической культуры и спорта; Спортивная подготовка по видам спорта "настольный теннис", "бадминтон", "бильярд", "сквош". Педагогическая деятельность в области физической культуры и спорта; уровень образования бакалавриат
B10: Курс 1, семестр 1, очная форма обучения
B11: группы С1-01-26, С1-02-26, С1-03-26, С1-04А-26, С1-04Б-26, С1-05А-26, С1-05Б-26, С1-06-26
A12: № | B12: Наименование дисциплины (модуля), практика, научные исследования | C12: Кол-во часов (Л/П) | D12: Форма отчетности | E12: Учебные группы в соответствии с избранным видом спорта
E14: Баскетбол | F14: Волейбол, гандбол, бейсбол, регби | G14: Интеллектуальные и технологичные виды спорта (шахматы, гонки дронов, компьютерный спорт,страйкбол) | H14: Теннис, настольный теннис, бадминтон, бильярд, сквош | I14: Футбол | J14: Хоккей
E15: 1 группа | F15: 2 группа | G15: 3 группа | H15: 4 группа | I15: 5 группа | J15: 6 группа
E16: Ф.И.О. преподавателя
A17: 1 | B17: Иностранный язык | C17: 0/32 | D17: Б/о | E17: Комова Е.В. | F17: Комова Е.В. | G17: Комова Е.В. | H17: Комова Е.В., Удалова М.Ю. | I17: Комова Е.В., Варичев А.М. 02.10, с 05.10 Бабель Т.А. | J17: Комова Е.В.
E18: Переверзева Н.А. (русский язык как иностранный для иностранных граждан)
A19: 2 | B19: Речевое общение в профессиональной деятельности | C19: 10/22 | D19: Зачет | E19: Л - Волкова М.С.
E20: Волкова М.С. | F20: Волкова М.С. | G20: Волкова М.С. | H20: Волкова М.С. | I20: Волкова М.С. | J20: Волкова М.С.
A21: 3 | B21: Анатомия человека | C21: 8/24 | D21: Зачет | E21: Л - Силаева Л.В.
E22: Гричанова Т.Г. | F22: Сироткина Ю.А. | G22: Мештель А.В. | H22: Силаева Л.В., Мештель А.В. | I22: Силаева Л.В., Мештель А.В. | J22: Силаева Л.В.
A23: 4 | B23: Физическая культура и спорт | C23: 10/10 | D23: Зачет | E23: Л - Ким Т.К.
E24: Кривенков А.А. | F24: Кривенков А.А. | G24: Кривенков А.А. | H24: Кривенков А.А. | I24: Кривенков А.А. | J24: Кривенков А.А.
A25: 5 | B25: Информационные технологии в сфере физической культуры и спорта | C25: 4/28 | D25: Диф.зачет | E25: Л - Яшкина Е.Н.
E26: Яшкина Е.Н. | F26: Яшкина Е.Н. | G26: Яшкина Е.Н. | H26: Яшкина Е.Н., Попов Г.И. | I26: Яшкина Е.Н., Попов Г.И. | J26: Яшкина Е.Н.
A27: 6 | B27: Волейбол | C27: 2/46 | D27: Зачет | E27: Л - Ананьин А.С.
E28: Ефимов А.С. | F28: Ананьин А.С. | G28: Суханова А.В. | H28: Суханова А.В., Пшеничная А.М. | I28: Ефимов А.С., Пшеничная А.М. | J28: Ефимов А.С.
A29: 7 | B29: Гимнастика | C29: 6/40 | D29: Зачет | E29: Л - Михалина Г.М., Ростовцева М.Ю., Парахин В.А.
A30: 7 | B30: Гимнастика | E30: Андреасян К.Б. | F30: Кувшинникова С.А. | G30: Андреасян К.Б. | H30: Андреасян К.Б., Козлов В.В. До 09.10, Михалина Г.М. с 12.10 | I30: Кувшинникова С.А., Дубовицкая И.А. | J30: Кувшинникова С.А.
A31: 8 | B31: Лыжные гонки | C31: 2/62 | D31: Зачет | E31: Л - Дубровинский С.С.
E32: Дзунович А.С. | F32: Дзунович А.С. | G32: Сенатская В.Г. | H32: Хитрова А.А., Дзунович А.С. | I32: Щукин А.В., Дубровинский С.С. | J32: Хитрова А.А.
A33: 9 | B33: Элективные дисциплины по ФКиС: Силовая подготовка | C33: 2/18 | D33: Зачет | E33: Л - Атлас А.А.
E34: Смирнов В.Е. | F34: Громов В.А. | G34: Атлас А.А. | H34: Громов В.А. | I34: Атлас А.А. | J34: Атлас А.А.
A35: 10 | B35: Использование электронной информационно-образовательной среды РУС "ГЦОЛИФК" | C35: 2/4 | D35: Зачет | E35: Л - Шевцов А.В.
E36: Шевцов А.В., Кузнецова Н.А. | F36: Шевцов А.В., Кузнецова Н.А. | G36: Шевцов А.В., Кузнецова Н.А. | H36: Шевцов А.В., Кузнецова Н.А. | I36: Шевцов А.В., Кузнецова Н.А. | J36: Шевцов А.В., Кузнецова Н.А.
A37: 11 | B37: Теория и методика избранного вида спорта | C37: 10/90 | D37: Зачет | E37: Баскетбол | F37: Волейбол | G37: Интеллектуальные и технологичные виды спорта | H37: Теннис | I37: Футбол | J37: Хоккей
E38: Л - Лапшин Н.А. | F38: Л - Григорьев В.А. | G38: Л - Новоселов М.А., Чигров А.С., Габбазова А.Я., Антонова Н.П., Акимушкин Р.В. | H38: Л - Степанова М.Е. | I38: Л - Шагин Н.И., Диванкулиев Д.Г. | J38: Л - Урюпин Н.Н.
E39: П - Лапшин Н.А., Сорокин С.А., Чернов С.В. до 09.10, с 12.10 Каменев А.Л. | F39: П - Григорьев В.А., Пшеничная А.М. | G39: П - Новоселов М.А., Чигров А.С., Габбазова А.Я., Антонова Н.П., Акимушкин Р.В. | H39: П - Мельничук К.Н., Пикалова А.В. | I39: П - Шагин Н.И., Орлов А.В., Несмелов А.А., Диванкулиев Д.Г. | J39: П - Костичкин П.В., Урюпин Н.Н.
F40: Гандбол, бейсбол, регби | H40: Настольный теннис, бадминтон, бильярд, сквош
F41: Л - Фурукина М.С. | H41: Л - Ракитина М.А.
F42: П - Фурукина М.С. | H42: П - Ракитина М.А., Шабанова А.В.
...

Sheet приложение1
A1: Приложение1 к расписанию учебных занятий на первое полугодие 2026-2027 учебного года
A2: ТРЕНЕРСКИЙ ФАКУЛЬТЕТ, направление подготовки (образовательная программа)
A3: 49.03.04 Спорт, Профиль (направленность): Спортивная подготовка по виду спорта «баскетбол». Педагогическая деятельность в области физической культуры и спорта; Спортивная подготовка по виду спорта «волейбол». Педагогическая деятельность в области физической культуры и спорта; Спортивная подготовка по видам спорта «гандбол», «бейсбол», «регби». Педагогическая деятельность в области физической культуры и спорта; Спортивная подготовка в интеллектуальных и технологичных видах спорта. Педагогическая деятельность в области физической культуры и спорта; Спортивная подготовка по виду спорта «теннис». Педагогическая деятельность в области физической культуры и спорта; Спортивная подготовка по виду спорта «хоккей». Педагогическая деятельность в области физической культуры и спорта; Спортивная подготовка по виду спорта «футбол». Педагогическая деятельность в области физической культуры и спорта; Спортивная подготовка по видам спорта "настольный теннис", "бадминтон", "бильярд", "сквош". Педагогическая деятельность в области физической культуры и спорта; уровень образования бакалавриат
A4: Курс 1, семестр 1, очная форма обучения
A5: группы С1-01-26, С1-02-26, С1-03-26, С1-04А-26, С1-04Б-26, С1-05А-26, С1-05Б-26, С1-06-26
A6: № | B6: Наименование дисциплины (модуля): | C6: № аудитории
A7: 1 | B7: Теория и методика баскетбола, профессионально-спортивное совершенствование (баскетбол) | C7: 224СК, 238СК, 9-10СК
A8: 2 | B8: Теория и методика настольного тенниса, бадминтона, бильярда, сквоша, профессионально-спортивное совершенствование (настольный теннис, бадминтон, бильярд, сквош) | C8: вторник: 08.50-10.20 -15 МБК, 223 СК, модуль Д, 10.40-12.10 - 15 МБК, 223 СК; четверг: 15 МБК, 223 СК
A9: 3 | B9: Теория и методика волейбола, профессионально-спортивное совершенствование (волейбол) | C9: 230СК, 54СК
A10: 4 | B10: Теория и методика гандбол, бейсбол, регби, профессионально-спортивное совершенствование (гандбол, бейсбол, регби) | C10: универсальный зал УСЗК, каб. 12 УСЗК
A11: 5 | B11: Теория и методика интеллектуальных и технологичных видов спорта, профессионально-спортивное совершенствование (шахматы, гонки дронов, компьютерный спорт, страйкбол) | C11: 228 гл.к., л/а манеж, 217мбк, 415 ауд.к., 416 ауд.к. (страйкбол: четверг - 213СК)
A12: 6 | B12: Теория и методика тенниса, профессионально-спортивное совершенствование (теннис) | C12: Теннисный центр 70ауд., 1 и 2 корт
A13: 7 | B13: Теория и методика футбола, профессионально-спортивное совершенствование (футбол) | C13: 252СК, 61СК, 62СК, 65СК, открытый стадион
A14: 8 | B14: Теория и методика хоккея, профессионально-спортивное совершенствование (хоккей) | C14: ауд.9 УСЗК, ауд.16-17 УСЗК, Ледовая арена УСЗК
A15: 9 | B15: Наименование дисциплины (модуля): Лыжные гонки | C15: 250 мбк, 282 мбк, л/а манеж, АНОСРФиС "АРТА-СПОРТ": г. Москва, Измайловский пр-д, д.15
A16: Условные обозначения:
A17: УСЗК - универсальный спортивно-зрелищный комплекс
A18: МБК - медико-биологический корпус
A19: СК - спортивный корпус

Sheet расписание ПСС
B1: Расписание учебных занятий на первое полугодие 2026-2027 учебного года
B2: ТРЕНЕРСКИЙ ФАКУЛЬТЕТ, направление подготовки (образовательная программа)
A3: 49.03.04 Спорт, Профиль (направленность): Спортивная подготовка по виду спорта «баскетбол». Педагогическая деятельность в области физической культуры и спорта; Спортивная подготовка по виду спорта «волейбол». Педагогическая деятельность в области физической культуры и спорта; Спортивная подготовка по видам спорта «гандбол», «бейсбол», «регби». Педагогическая деятельность в области физической культуры и спорта; Спортивная подготовка в интеллектуальных и технологичных видах спорта. Педагогическая деятельность в области физической культуры и спорта; Спортивная подготовка по виду спорта «теннис». Педагогическая деятельность в области физической культуры и спорта; Спортивная подготовка по виду спорта «хоккей». Педагогическая деятельность в области физической культуры и спорта; Спортивная подготовка по виду спорта «футбол». Педагогическая деятельность в области физической культуры и спорта; Спортивная подготовка по видам спорта "настольный теннис", "бадминтон", "бильярд", "сквош". Педагогическая деятельность в области физической культуры и спорта; уровень образования бакалавриат
A4: Курс 1, семестр 1, очная форма обучения
A5: группы С1-01-26, С1-02-26, С1-03-26, С1-04А-26, С1-04Б-26, С1-05А-26, С1-05Б-26, С1-06-26
A6: с 01.09 по 26.12
A7: День недели | B7: Время | C7: 1 группа | D7: 2 группа | E7: 3 группа | F7: 4 группа | G7: 5 группа | H7: 6 группа
C8: Баскетбол | D8: Волейбол, гандбол, бейсбол, регби | E8: Интеллектуальные и технологичные виды спорта (шахматы, гонки дронов, компьютерный спорт, страйкбол) | F8: Теннис, настольный теннис, бадминтон, бильярд, сквош | G8: Футбол | H8: Хоккей
A9: Понедельник | B9: 8.50-10.20 | F9: ПСС Теннис 1 и 2 корт с 21.09
B10: 10.40-12.10 | F10: ПСС Теннис 1 и 2 корт 07.09-18.09
B11: 13.00-14.30
B12: 14.50-16.20
B13: 16.40-18.10 | D13: ПСС Волейбол 16.30-18.00 230СК, 54СК
B14: 18.30-20.00
A15: Вторник | B15: 8.50-10.20
B16: 10.40-12.10
B17: 13.00-14.30
B18: 14.50-16.20
B19: 16.40-18.10 | C19: ПСС баскетбол 224СК | D19: ПСС гандбол, бейсбол, регби - Арена УСЗК / каб.12 УСЗК с 07.09
B20: 18.30-20.00
B21: 20.20-21.50
A22: Среда | B22: 8.50-10.20
B23: 10.40-12.10
B24: 13.00-14.30
B25: 14.50-16.20
B26: 16.40-18.10 | H26: ПСС хоккей Ледовая площадка УСЗК с 09.09
B27: 20.20-21.50
A28: Четверг | B28: 8.50-10.20
B29: 10.40-12.10
B30: 13.00-14.30
B31: 14.50-16.20
B32: 16.40-18.10 | E32: ПСС шахматы 415 ауд.к., 416 ауд.к.; ПСС страйкбол, компьютерный спорт 213СК
B33: 18.30-20.00
B34: 20.20-21.50 | E34: ПСС гонки дронов 20.20-21.00- 228 гл.к., 21.00-21.50 - л/а манеж
A35: Пятница | B35: 8.50-10.20
B36: 10.40-12.10
B37: 13.00-14.30
B38: 14.50-16.20
B39: 16.40-18.10
A40: Суббота | B40: 8.50-10.20
...

Sheet Иностр язык (русский язык)
C1: Расписание учебных занятий на первое полугодие 2026-2027 учебного года
C2: ТРЕНЕРСКИЙ ФАКУЛЬТЕТ, направление подготовки (образовательная программа)
B3: 49.03.04 Спорт, Профиль (направленность): Спортивная подготовка по виду спорта «баскетбол». Педагогическая деятельность в области физической культуры и спорта; Спортивная подготовка по виду спорта «волейбол». Педагогическая деятельность в области физической культуры и спорта; Спортивная подготовка по видам спорта «гандбол», «бейсбол», «регби». Педагогическая деятельность в области физической культуры и спорта; Спортивная подготовка в интеллектуальных и технологичных видах спорта. Педагогическая деятельность в области физической культуры и спорта; Спортивная подготовка по виду спорта «теннис». Педагогическая деятельность в области физической культуры и спорта; Спортивная подготовка по виду спорта «хоккей». Педагогическая деятельность в области физической культуры и спорта; Спортивная подготовка по виду спорта «футбол». Педагогическая деятельность в области физической культуры и спорта; Спортивная подготовка по видам спорта "настольный теннис", "бадминтон", "бильярд", "сквош". Педагогическая деятельность в области физической культуры и спорта; уровень образования бакалавриат
B4: Курс 1, семестр 1, очная форма обучения
B5: группы С1-01-26, С1-02-26, С1-03-26, С1-04А-26, С1-04Б-26, С1-05А-26, С1-05Б-26, С1-06-26
A6: День недели | B6: Дата | C6: Время | D6: 1 группа | E6: 2 группа | F6: 3 группа | G6: 4 группа | H6: 5 группа | I6: 6 группа
D7: Баскетбол | E7: Волейбол, гандбол, бейсбол, регби | F7: Интеллектуальные и технологичные виды спорта (шахматы, гонки дронов, компьютерный спорт, страйкбол) | G7: Теннис, настольный теннис, бадминтон, бильярд, сквош | H7: Футбол | I7: Хоккей
A8: Понедельник | C8: 8.50-10.20
C9: 10.40-12.10
C10: 13.00-14.30
C11: 14.50-16.20
C12: 16.40-18.10
A13: Вторник | C13: 8.50-10.20
C14: 10.40-12.10
C15: 13.00-14.30
C16: 14.50-16.20
C17: 16.40-18.10
A18: Среда | C18: 8.50-10.20
C19: 10.40-12.10
C20: 13.00-14.30
C21: 14.50-16.20
C22: 16.40-18.10
A23: Четверг | C23: 8.50-10.20 | D23: Пр. Иностранный язык Переверзева Н.А. 508 гл.к. - (русский язык как иностранный для иностранных граждан: С1-03-26, С1-02-26, С1-04Б-26) - 10.09, 17.09, 24.09, 01.10, 08.10, 15.10, 22.10, 29.10, 05.11, 12.11, 19.11, 26.11, 03.12, 10.12, 17.12, 24.12
C24: 10.40-12.10 | D24: Пр. Иностранный язык Переверзева Н.А. 511 гл.к. - (русский язык как иностранный для иностранных граждан: С1-01-26, С1-04А-26, С1-05А-26, С1-05Б-26) - 10.09, 17.09, 24.09, 01.10, 08.10, 15.10, 22.10, 29.10, 05.11, 12.11, 19.11, 26.11, 03.12, 10.12, 17.12, 24.12
C25: 13.00-14.30
C26: 14.50-16.20
C27: 16.40-18.10
A28: Пятница | C28: 8.50-10.20
C29: 10.40-12.10
C30: 13.00-14.30
C31: 14.50-16.20
C32: 16.40-18.10
A33: Суббота | C33: 8.50-10.20
C34: 10.40-12.10
C35: 13.00-14.30
C36: 14.50-16.20
C37: 16.40-18.10

Sheet 01.09
B1: Расписание учебных занятий на первое полугодие 2026-2027 учебного года
B2: ТРЕНЕРСКИЙ ФАКУЛЬТЕТ, направление подготовки (образовательная программа)
A3: 49.03.04 Спорт, Профиль (направленность): Спортивная подготовка по виду спорта «баскетбол». Педагогическая деятельность в области физической культуры и спорта; Спортивная подготовка по виду спорта «волейбол». Педагогическая деятельность в области физической культуры и спорта; Спортивная подготовка по видам спорта «гандбол», «бейсбол», «регби». Педагогическая деятельность в области физической культуры и спорта; Спортивная подготовка в интеллектуальных и технологичных видах спорта. Педагогическая деятельность в области физической культуры и спорта; Спортивная подготовка по виду спорта «теннис». Педагогическая деятельность в области физической культуры и спорта; Спортивная подготовка по виду спорта «хоккей». Педагогическая деятельность в области физической культуры и спорта; Спортивная подготовка по виду спорта «футбол». Педагогическая деятельность в области физической культуры и спорта; Спортивная подготовка по видам спорта "настольный теннис", "бадминтон", "бильярд", "сквош". Педагогическая деятельность в области физической культуры и спорта; уровень образования бакалавриат
A4: Курс 1, семестр 1, очная форма обучения
A5: группы С1-01-26, С1-02-26, С1-03-26, С1-04А-26, С1-04Б-26, С1-05А-26, С1-05Б-26, С1-06-26
A6: День недели | B6: Дата | C6: Время | D6: 1 группа | E6: 2 группа | F6: 3 группа | G6: 4 группа | H6: 5 группа | I6: 6 группа
D7: Баскетбол | E7: Волейбол, гандбол, бейсбол, регби | F7: Интеллектуальные и технологичные виды спорта (шахматы, гонки дронов, компьютерный спорт, страйкбол) | G7: Теннис, настольный теннис, бадминтон, бильярд, сквош | H7: Футбол | I7: Хоккей
A8: Понедельник | B8: 46265 | C8: 8.50-10.20 | K8: Лекция. Информатика. Яшкина Е.Н. 277МБК
C9: 10.40-12.10 | K9: Пр. Информатика. Яшкина Е.Н. 277МБК
C10: 13.00-14.30 | K10: Лекция. Русский язык и культура речи. Гордиенко В.Е. | L10: 5лекций
C11: 14.50-16.20 | K11: Лекция. Русский язык и культура речи.Волкова М.С. | L11: 2лекции
C12: 16.40-18.10 | K12: Пр. Русский язык и культура речи. Уткина Е.Л. 410ауд.к | M12: 2группы
A13: Вторник | B13: =B8+1 -> 46266 | C13: 8.50-10.20 | K13: Пр. Русский язык и культура речи. Ишина Л.М. 409 ауд.к. | M13: 1группа
C14: 10.40-12.10 | D14: Л. Использование электронной информационно-образовательной среды РУС "ГЦОЛИФК" Шевцов А.В. - Арена УСЗК (Универсальный спортивно-зрелищный комплекс) | K14: Пр. Русский язык и культура речи. Гордиенко В.Е. 408 ауд.к. | M14: две гр
C15: 13.00-14.30 | D15: Л. Теория и методика баскетбола Прил.1 | E15: Л. Теория и методика волейбола, гандбола, бейсбола, регби Прил.1 | F15: Л. Теория и методика интеллектуальных и технологичных видов спорта Прил.1 | G15: Л. Теория и методика тенниса, настольного тенниса, бадминтона, бильярда, сквоша Прил.1 | H15: Л. Теория и методика футбола Прил.1 | I15: Л. Теория и методика хоккея Прил.1 | K15: Пр. Русский язык и культура речи. Капустина Ю.А. 409ауд.к. | M15: одна гр.
C16: 14.50-16.20 | K16: Лекция. Анатомия человека. Павлычева Л.А. 162 МБК | M16: 2,4,6 гр
C17: 16.40-18.10 | K17: Лекция. Анатомия человека. Титова Е.П. 161 МБК | M17: 1,5 гр
A18: Среда | B18: =B13+1 -> 46267 | C18: 8.50-10.20 | D18: Л. Гимнастика Михалина Г.М. 162мбк | E18: Л. Гимнастика Михалина Г.М. 162мбк | F18: Л. Гимнастика Михалина Г.М. 162мбк | G18: Л. Гимнастика Михалина Г.М. 162мбк | H18: Л. Гимнастика Михалина Г.М. 162мбк | I18: Л. Гимнастика Михалина Г.М. 162мбк | K18: Пр. Анатомия человека. Титова Е.П. 154МБК | M18: 1,5 гр
C19: 10.40-12.10 | D19: Л. Гимнастика Ростовцева М.Ю. 162мбк | E19: Л. Гимнастика Ростовцева М.Ю. 162мбк | F19: Л. Гимнастика Ростовцева М.Ю. 162мбк | G19: Л. Гимнастика Ростовцева М.Ю. 162мбк | H19: Л. Гимнастика Ростовцева М.Ю. 162мбк | I19: Л. Гимнастика Ростовцева М.Ю. 162мбк | K19: Пр. Анатомия человека. Павлычева Л.А. 131 МБК | M19: 2,4,6 гр
C20: 13.00-14.30 | D20: Л. Информационные технологии в сфере физической культуры и спорта Яшкина Е.Н. 162мбк | E20: Л. Информационные технологии в сфере физической культуры и спорта Яшкина Е.Н. 162мбк | F20: Л. Информационные технологии в сфере физической культуры и спорта Яшкина Е.Н. 162мбк | G20: Л. Информационные технологии в сфере физической культуры и спорта Яшкина Е.Н. 162мбк | H20: Л. Информационные технологии в сфере физической культуры и спорта Яшкина Е.Н. 162мбк | I20: Л. Информационные технологии в сфере физической культуры и спорта Яшкина Е.Н. 162мбк | K20: Лекция. ТиМ избранного вида спорта. ауд.прил.1.
C21: 14.50-16.20 | D21: Л. Информационные технологии в сфере физической культуры и спорта Яшкина Е.Н. 162мбк | E21: Л. Информационные технологии в сфере физической культуры и спорта Яшкина Е.Н. 162мбк | F21: Л. Информационные технологии в сфере физической культуры и спорта Яшкина Е.Н. 162мбк | G21: Л. Информационные технологии в сфере физической культуры и спорта Яшкина Е.Н. 162мбк | H21: Л. Информационные технологии в сфере физической культуры и спорта Яшкина Е.Н. 162мбк | I21: Л. Информационные технологии в сфере физической культуры и спорта Яшкина Е.Н. 162мбк | K21: Пр. ТиМ избранного вида спорта. ауд.прил.1.
C22: 16.40-18.10 | K22: Лекция. Тяжелоатлетические виды спорта. Баюрин А.П.161МБК
A23: Четверг | B23: =B18+1 -> 46268 | C23: 8.50-10.20 | D23: Л. Волейбол Ананьин А.С. 162мбк | E23: Л. Волейбол Ананьин А.С. 162мбк | F23: Л. Волейбол Ананьин А.С. 162мбк | G23: Л. Волейбол Ананьин А.С. 162мбк | H23: Л. Волейбол Ананьин А.С. 162мбк | I23: Л. Волейбол Ананьин А.С. 162мбк | K23: Пр. Тяжелоатлетические виды спорта. Соловьев В.Б. ауд.прил.1.
C24: 10.40-12.10 | D24: Л. Элективные дисциплины по ФКиС: Силовая подготовка Атлас А.А. 162мбк | E24: Л. Элективные дисциплины по ФКиС: Силовая подготовка Атлас А.А. 162мбк | F24: Л. Элективные дисциплины по ФКиС: Силовая подготовка Атлас А.А. 162мбк | G24: Л. Элективные дисциплины по ФКиС: Силовая подготовка Атлас А.А. 162мбк | H24: Л. Элективные дисциплины по ФКиС: Силовая подготовка Атлас А.А. 162мбк | I24: Л. Элективные дисциплины по ФКиС: Силовая подготовка Атлас А.А. 162мбк | K24: Лекция. Баскетбол. Андрющенко Л.Б.
C25: 13.00-14.30 | E25: Пр. Теория и методика волейбола, гандбола, бейсбола, регби Прил.1 | F25: Пр. Теория и методика интеллектуальных и технологичных видов спорта Прил.1 | G25: Пр. Теория и методика тенниса, настольного тенниса, бадминтона, бильярда, сквоша Прил.1 - только 03.09 | H25: Пр. Теория и методика футбола Прил.1 - только 03.09 | K25: Пр. Баскетбол. Лосева И.В., Мартынова А.В., Никонов Д.Н., Лаптев С.О., Аверясова Ю.О.
C26: 14.50-16.20 | E26: Пр. Теория и методика волейбола, гандбола, бейсбола, регби Прил.1 | F26: Пр. Теория и методика интеллектуальных и технологичных видов спорта Прил.1 | G26: Пр. Теория и методика тенниса, настольного тенниса, бадминтона, бильярда, сквоша Прил.1 | H26: Пр. Теория и методика футбола Прил.1 - только 03.09 | K26: Лекция . Лыжные гонки. Сенатская В.Г. 212ауд.к.
C27: 16.40-18.10 | K27: Пр. Лыжные гонки.
A28: Пятница | B28: =B23+1 -> 46269 | C28: 8.50-10.20 | K28: Пр. Гимнастика
C29: 10.40-12.10 | D29: Л. Речевое общение в профессиональной деятельности Волкова М.С. 162мбк | E29: Л. Речевое общение в профессиональной деятельности Волкова М.С. 162мбк | F29: Л. Речевое общение в профессиональной деятельности Волкова М.С. 162мбк | G29: Л. Речевое общение в профессиональной деятельности Волкова М.С. 162мбк | H29: Л. Речевое общение в профессиональной деятельности Волкова М.С. 162мбк | I29: Л. Речевое общение в профессиональной деятельности Волкова М.С. 162мбк | K29: Лекция. Физическая культура и спорт. Еремин М.В.
C30: 13.00-14.30 | D30: Л. Гимнастика Парахин В.А. 162мбк | E30: Л. Гимнастика Парахин В.А. 162мбк | F30: Л. Гимнастика Парахин В.А. 162мбк | G30: Л. Гимнастика Парахин В.А. 162мбк | H30: Л. Гимнастика Парахин В.А. 162мбк | I30: Л. Гимнастика Парахин В.А. 162мбк | K30: Пр. Спортивно-педагогическое совершенствование. ауд.прил.1.
C31: 14.50-16.20 | D31: Л. Физическая культура и спорт Ким Т.К. 162мбк | E31: Л. Физическая культура и спорт Ким Т.К. 162мбк | F31: Л. Физическая культура и спорт Ким Т.К. 162мбк | G31: Л. Физическая культура и спорт Ким Т.К. 162мбк | H31: Л. Физическая культура и спорт Ким Т.К. 162мбк | I31: Л. Физическая культура и спорт Ким Т.К. 162мбк | K31: Пр. Элективные дисциплины по физ.культуре и спорту. Подвижные игры. Томашевич А.М. Модуль Д | L31: 1гр,3гр
C32: 16.40-18.10 | K32: Пр. Элективные дисциплины по физ.культуре и спорту. Подвижные игры.Салахудинова Е.С. Модуль Б | L32: 2гр.,4гр
A33: Суббота | B33: =B28+1 -> 46270 | C33: 8.50-10.20 | K33: Пр. Гимнастика
C34: 10.40-12.10 | K34: Лекция. Физическая культура и спорт. Еремин М.В.
C35: 13.00-14.30 | K35: Пр. Спортивно-педагогическое совершенствование. ауд.прил.1.
C36: 14.50-16.20 | K36: Пр. Элективные дисциплины по физ.культуре и спорту. Подвижные игры. Томашевич А.М. Модуль Д | L36: 1гр,3гр
C37: 16.40-18.10 | K37: Пр. Элективные дисциплины по физ.культуре и спорту. Подвижные игры.Салахудинова Е.С. Модуль Б | L37: 2гр.,4гр
B39: 10 | C39: *Л. Речевое общение в профессиональной деятельности* | D39: =COUNTIF(D$8:D$37,$C39) -> 1 | E39: =COUNTIF(E$8:E$37,$C39) -> 1 | F39: =COUNTIF(F$8:F$37,$C39) -> 1 | G39: =COUNTIF(G$8:G$37,$C39) -> 1 | H39: =COUNTIF(H$8:H$37,$C39) -> 1 | I39: =COUNTIF(I$8:I$37,$C39) -> 1
B40: 22 | C40: *Пр. Речевое общение в профессиональной деятельности* | D40: =COUNTIF(D$8:D$37,$C40) -> 0 | E40: =COUNTIF(E$8:E$37,$C40) -> 0 | F40: =COUNTIF(F$8:F$37,$C40) -> 0 | G40: =COUNTIF(G$8:G$37,$C40) -> 0 | H40: =COUNTIF(H$8:H$37,$C40) -> 0 | I40: =COUNTIF(I$8:I$37,$C40) -> 0
B41: 2 | C41: *Л. Элективные дисциплины по ФКиС: Силовая подготовка* | D41: =COUNTIF(D$8:D$37,$C41) -> 1 | E41: =COUNTIF(E$8:E$37,$C41) -> 1 | F41: =COUNTIF(F$8:F$37,$C41) -> 1 | G41: =COUNTIF(G$8:G$37,$C41) -> 1 | H41: =COUNTIF(H$8:H$37,$C41) -> 1 | I41: =COUNTIF(I$8:I$37,$C41) -> 1
...

Sheet 07.09
B1: Расписание учебных занятий на первое полугодие 2026-2027 учебного года
B2: ТРЕНЕРСКИЙ ФАКУЛЬТЕТ, направление подготовки (образовательная программа)
B3: 49.03.04 Спорт *
B4: Курс 1, семестр 1, очная форма обучения
A5: группы С1-01-26, С1-02-26, С1-03-26, С1-04А-26, С1-04Б-26, С1-05А-26, С1-05Б-26, С1-06-26
A6: День недели | B6: Дата | C6: Время | D6: 1 группа | E6: 2 группа | F6: 3 группа | G6: 4 группа | H6: 5 группа | I6: 6 группа
D7: Баскетбол | E7: Волейбол, гандбол, бейсбол, регби | F7: Интеллектуальные и технологичные виды спорта (шахматы, гонки дронов, компьютерный спорт, страйкбол) | G7: Теннис, настольный теннис, бадминтон, бильярд, сквош | H7: Футбол | I7: Хоккей
A8: Понедельник | B8: 46272 | C8: 8.50-10.20 | D8: Пр. Иностранный язык Комова Е.В. 508 гл.к.
C9: 10.40-12.10 | D9: Пр. Информационные технологии в сфере физической культуры и спорта Яшкина Е.Н. 277мбк | E9: Пр. Элективные дисциплины по ФКиС: Силовая подготовка Громов В.А. 42СК | H9: Пр. Волейбол Ефимов А.С., Пшеничная А.М. 230СК
C10: 13.00-14.30 | D10: Пр. Гимнастика Андреасян К.Б. 205СК | E10: Пр. Иностранный язык Комова Е.В. 508 гл.к. | G10: Пр. Информационные технологии в сфере физической культуры и спорта Яшкина Е.Н. 277мбк, Попов Г.И. 246мбк | H10: Пр. Теория и методика футбола Прил.1 | I10: Пр. Волейбол Ефимов А.С. 230СК
C11: 14.50-16.20 | D11: Пр. Волейбол Ефимов А.С. 230СК | E11: Пр. Информационные технологии в сфере физической культуры и спорта Яшкина Е.Н. 277мбк | G11: Пр. Гимнастика Андреасян К.Б. 205СК (группа С1-04А-26), Козлов В.В. 205СК (группа С1-04Б-26) | H11: Пр. Теория и методика футбола Прил.1 | I11: Пр. Иностранный язык Комова Е.В. 508 гл.к.
C12: 16.40-18.10
A13: Вторник | B13: =B8+1 -> 46273 | C13: 8.50-10.20 | D13: Пр. Теория и методика баскетбола Прил.1 | F13: Пр. Теория и методика интеллектуальных и технологичных видов спорта Прил.1 | G13: Пр. Теория и методика тенниса, настольного тенниса, бадминтона, бильярда, сквоша Прил.1
C14: 10.40-12.10 | D14: Пр. Теория и методика баскетбола Прил.1 | E14: Пр. Теория и методика волейбола, гандбола, бейсбола, регби Прил.1 | F14: Пр. Теория и методика интеллектуальных и технологичных видов спорта Прил.1 | G14: Пр. Теория и методика тенниса, настольного тенниса, бадминтона, бильярда, сквоша Прил.1 | H14: Пр. Иностранный язык Комова Е.В. 508 гл.к., Варичев А.М. 511 гл.к. | I14: Пр. Гимнастика Кувшинникова С.А.205СК
C15: 13.00-14.30 | E15: Пр. Гимнастика Кувшинникова С.А. 205СК | F15: Пр. Иностранный язык Комова Е.В. 508 гл.к. | H15: Пр. Элективные дисциплины по ФКиС: Силовая подготовка Атлас А.А. 42СК | I15: Пр. Теория и методика хоккея Прил.1
C16: 14.50-16.20 | F16: Пр. Элективные дисциплины по ФКиС: Силовая подготовка Атлас А.А. 42СК | I16: Пр. Теория и методика хоккея Прил.1
C17: 16.40-18.10
C18: 18.30-20.00
A19: Среда | B19: =B13+1 -> 46274 | C19: 8.50-10.20 | H19: Пр. Волейбол Ефимов А.С., Пшеничная А.М. 230СК
C20: 10.40-12.10 | D20: Пр. Элективные дисциплины по ФКиС: Силовая подготовка Смирнов В.Е. 42СК | H20: Пр. Гимнастика Кувшинникова С.А., Дубовицкая И.А. 205СК | I20: Пр. Волейбол Ефимов А.С. 230СК
C21: 13.00-14.30 | D21: Пр. Волейбол Ефимов А.С. 230СК | E21: Пр. Гимнастика Кувшинникова С.А. 205СК | I21: Пр. Теория и методика хоккея Прил.1
C22: 14.50-16.20 | E22: Пр. Волейбол Ананьин А.С. 230СК | I22: Пр. Теория и методика хоккея Прил.1
C23: 16.40-18.10
A24: Четверг | B24: =B19+1 -> 46275 | C24: 8.50-10.20
C25: 10.40-12.10 | F25: Пр. Информационные технологии в сфере физической культуры и спорта Яшкина Е.Н. 277мбк | G25: Пр. Элективные дисциплины по ФКиС: Силовая подготовка Громов В.А. 42СК | I25: Пр. Гимнастика Кувшинникова С.А.205СК
C26: 13.00-14.30 | D26: Пр. Теория и методика баскетбола Прил.1 | E26: Пр. Теория и методика волейбола, гандбола, бейсбола, регби Прил.1 | F26: Пр. Волейбол Суханова А.В. 230СК | G26: Пр. Иностранный язык Комова Е.В. 508 гл.к., Удалова М.Ю. 511 гл.к. | H26: Пр. Гимнастика Кувшинникова С.А., Дубовицкая И.А. 205СК | I26: Пр. Информационные технологии в сфере физической культуры и спорта Яшкина Е.Н. 277мбк
C27: 14.50-16.20 | D27: Пр. Теория и методика баскетбола Прил.1 | E27: Пр. Теория и методика волейбола, гандбола, бейсбола, регби Прил.1 | F27: Пр. Теория и методика интеллектуальных и технологичных видов спорта Прил.1 | G27: Пр. Теория и методика тенниса, настольного тенниса, бадминтона, бильярда, сквоша Прил.1 | H27: Пр. Информационные технологии в сфере физической культуры и спорта Яшкина Е.Н. 277мбк, Попов Г.И. 246мбк
C28: 16.40-18.10
A29: Пятница | B29: =B24+1 -> 46276 | C29: 8.50-10.20 | E29: Пр. Волейбол Ананьин А.С. 230СК | F29: Пр. Гимнастика Андреасян К.Б. 205СК | G29: Пр. Волейбол Суханова А.В. 230СК | H29: Пр. Теория и методика футбола Прил.1 | I29: Пр. Элективные дисциплины по ФКиС: Силовая подготовка Атлас А.А. 42СК
C30: 10.40-12.10 | D30: Л. Речевое общение в профессиональной деятельности Волкова М.С. 162мбк | E30: Л. Речевое общение в профессиональной деятельности Волкова М.С. 162мбк | F30: Л. Речевое общение в профессиональной деятельности Волкова М.С. 162мбк | G30: Л. Речевое общение в профессиональной деятельности Волкова М.С. 162мбк | H30: Л. Речевое общение в профессиональной деятельности Волкова М.С. 162мбк | I30: Л. Речевое общение в профессиональной деятельности Волкова М.С. 162мбк
C31: 13.00-14.30 | D31: Л. Анатомия человека Силаева Л.В. 162мбк | E31: Л. Анатомия человека Силаева Л.В. 162мбк | F31: Л. Анатомия человека Силаева Л.В. 162мбк | G31: Л. Анатомия человека Силаева Л.В. 162мбк | H31: Л. Анатомия человека Силаева Л.В. 162мбк | I31: Л. Анатомия человека Силаева Л.В. 162мбк
C32: 14.50-16.20 | D32: Л. Физическая культура и спорт Ким Т.К. 162мбк | E32: Л. Физическая культура и спорт Ким Т.К. 162мбк | F32: Л. Физическая культура и спорт Ким Т.К. 162мбк | G32: Л. Физическая культура и спорт Ким Т.К. 162мбк | H32: Л. Физическая культура и спорт Ким Т.К. 162мбк | I32: Л. Физическая культура и спорт Ким Т.К. 162мбк
C33: 16.40-18.10
A34: Суббота | B34: =B29+1 -> 46277 | C34: 8.50-10.20
C35: 10.40-12.10
C36: 13.00-14.30
C37: 14.50-16.20
C38: 16.40-18.10
D39: * Профили (направленность) указанны на титульном листе
C40: ='01.09'!C39 -> *Л. Речевое общение в профессиональной деятельности* | D40: ='01.09'!D39+COUNTIF(D$8:D$38,$C40) -> 2 | E40: ='01.09'!E39+COUNTIF(E$8:E$38,$C40) -> 2 | F40: ='01.09'!F39+COUNTIF(F$8:F$38,$C40) -> 2 | G40: ='01.09'!G39+COUNTIF(G$8:G$38,$C40) -> 2 | H40: ='01.09'!H39+COUNTIF(H$8:H$38,$C40) -> 2 | I40: ='01.09'!I39+COUNTIF(I$8:I$38,$C40) -> 2
...

Sheet 14.09
B1: Расписание учебных занятий на первое полугодие 2026-2027 учебного года
B2: ТРЕНЕРСКИЙ ФАКУЛЬТЕТ, направление подготовки (образовательная программа)
B3: 49.03.04 Спорт *
B4: Курс 1, семестр 1, очная форма обучения
A5: группы С1-01-26, С1-02-26, С1-03-26, С1-04А-26, С1-04Б-26, С1-05А-26, С1-05Б-26, С1-06-26
A6: День недели | B6: Дата | C6: Время | D6: 1 группа | E6: 2 группа | F6: 3 группа | G6: 4 группа | H6: 5 группа | I6: 6 группа
D7: Баскетбол | E7: Волейбол, гандбол, бейсбол, регби | F7: Интеллектуальные и технологичные виды спорта (шахматы, гонки дронов, компьютерный спорт, страйкбол) | G7: Теннис, настольный теннис, бадминтон, бильярд, сквош | H7: Футбол | I7: Хоккей
A8: Понедельник | B8: 46279 | C8: 8.50-10.20 | D8: Пр. Иностранный язык Комова Е.В. 508 гл.к.
C9: 10.40-12.10 | D9: Пр. Информационные технологии в сфере физической культуры и спорта Яшкина Е.Н. 277мбк | E9: Пр. Элективные дисциплины по ФКиС: Силовая подготовка Громов В.А. 42СК | H9: Пр. Волейбол Ефимов А.С., Пшеничная А.М. 230СК
C10: 13.00-14.30 | D10: Пр. Гимнастика Андреасян К.Б. 205СК | E10: Пр. Иностранный язык Комова Е.В. 508 гл.к. | G10: Пр. Информационные технологии в сфере физической культуры и спорта Яшкина Е.Н. 277мбк, Попов Г.И. 246мбк | H10: Пр. Теория и методика футбола Прил.1 | I10: Пр. Волейбол Ефимов А.С. 230СК
C11: 14.50-16.20 | D11: Пр. Волейбол Ефимов А.С. 230СК | E11: Пр. Информационные технологии в сфере физической культуры и спорта Яшкина Е.Н. 277мбк | G11: Пр. Гимнастика Андреасян К.Б. 205СК (группа С1-04А-26), Козлов В.В. 205СК (группа С1-04Б-26) | H11: Пр. Теория и методика футбола Прил.1 | I11: Пр. Иностранный язык Комова Е.В. 508 гл.к.
C12: 16.40-18.10
A13: Вторник | B13: =B8+1 -> 46280 | C13: 8.50-10.20 | D13: Пр. Теория и методика баскетбола Прил.1 | F13: Пр. Теория и методика интеллектуальных и технологичных видов спорта Прил.1 | G13: Пр. Теория и методика тенниса, настольного тенниса, бадминтона, бильярда, сквоша Прил.1
C14: 10.40-12.10 | D14: Пр. Теория и методика баскетбола Прил.1 | E14: Пр. Теория и методика волейбола, гандбола, бейсбола, регби Прил.1 | F14: Пр. Теория и методика интеллектуальных и технологичных видов спорта Прил.1 | G14: Пр. Теория и методика тенниса, настольного тенниса, бадминтона, бильярда, сквоша Прил.1 | H14: Пр. Иностранный язык Комова Е.В. 508 гл.к., Варичев А.М. 511 гл.к. | I14: Пр. Гимнастика Кувшинникова С.А.205СК
C15: 13.00-14.30 | E15: Пр. Гимнастика Кувшинникова С.А. 205СК | F15: Пр. Иностранный язык Комова Е.В. 508 гл.к. | G15: Пр. Волейбол Суханова А.В., Пшеничная А.М. 230СК | H15: Пр. Элективные дисциплины по ФКиС: Силовая подготовка Атлас А.А. 42СК | I15: Пр. Теория и методика хоккея Прил.1
C16: 14.50-16.20 | F16: Пр. Элективные дисциплины по ФКиС: Силовая подготовка Атлас А.А. 42СК | I16: Пр. Теория и методика хоккея Прил.1
C17: 16.40-18.10
C18: 18.30-20.00
A19: Среда | B19: =B13+1 -> 46281 | C19: 8.50-10.20 | H19: Пр. Волейбол Ефимов А.С., Пшеничная А.М. 230СК
C20: 10.40-12.10 | D20: Пр. Элективные дисциплины по ФКиС: Силовая подготовка Смирнов В.Е. 42СК | H20: Пр. Гимнастика Кувшинникова С.А., Дубовицкая И.А. 205СК | I20: Пр. Волейбол Ефимов А.С. 230СК
C21: 13.00-14.30 | D21: Пр. Волейбол Ефимов А.С. 230СК | E21: Пр. Гимнастика Кувшинникова С.А. 205СК | I21: Пр. Теория и методика хоккея Прил.1
C22: 14.50-16.20 | E22: Пр. Волейбол Ананьин А.С. 230СК | I22: Пр. Теория и методика хоккея Прил.1
C23: 16.40-18.10
A24: Четверг | B24: =B19+1 -> 46282 | C24: 8.50-10.20
C25: 10.40-12.10 | F25: Пр. Информационные технологии в сфере физической культуры и спорта Яшкина Е.Н. 277мбк | G25: Пр. Элективные дисциплины по ФКиС: Силовая подготовка Громов В.А. 42СК | I25: Пр. Гимнастика Кувшинникова С.А.205СК
C26: 13.00-14.30 | D26: Пр. Теория и методика баскетбола Прил.1 | E26: Пр. Теория и методика волейбола, гандбола, бейсбола, регби Прил.1 | F26: Пр. Волейбол Суханова А.В. 230СК | G26: Пр. Иностранный язык Комова Е.В. 508 гл.к., Удалова М.Ю. 511 гл.к. | H26: Пр. Гимнастика Кувшинникова С.А., Дубовицкая И.А. 205СК | I26: Пр. Информационные технологии в сфере физической культуры и спорта Яшкина Е.Н. 277мбк
C27: 14.50-16.20 | D27: Пр. Теория и методика баскетбола Прил.1 | E27: Пр. Теория и методика волейбола, гандбола, бейсбола, регби Прил.1 | F27: Пр. Теория и методика интеллектуальных и технологичных видов спорта Прил.1 | G27: Пр. Теория и методика тенниса, настольного тенниса, бадминтона, бильярда, сквоша Прил.1 | H27: Пр. Информационные технологии в сфере физической культуры и спорта Яшкина Е.Н. 277мбк, Попов Г.И. 246мбк
C28: 16.40-18.10
A29: Пятница | B29: =B24+1 -> 46283 | C29: 8.50-10.20 | E29: Пр. Волейбол Ананьин А.С. 230СК | F29: Пр. Гимнастика Андреасян К.Б. 205СК | H29: Пр. Теория и методика футбола Прил.1 | I29: Пр. Элективные дисциплины по ФКиС: Силовая подготовка Атлас А.А. 42СК
C30: 10.40-12.10 | D30: Л. Речевое общение в профессиональной деятельности Волкова М.С. 162мбк | E30: Л. Речевое общение в профессиональной деятельности Волкова М.С. 162мбк | F30: Л. Речевое общение в профессиональной деятельности Волкова М.С. 162мбк | G30: Л. Речевое общение в профессиональной деятельности Волкова М.С. 162мбк | H30: Л. Речевое общение в профессиональной деятельности Волкова М.С. 162мбк | I30: Л. Речевое общение в профессиональной деятельности Волкова М.С. 162мбк
C31: 13.00-14.30 | D31: Л. Анатомия человека Силаева Л.В. 162мбк | E31: Л. Анатомия человека Силаева Л.В. 162мбк | F31: Л. Анатомия человека Силаева Л.В. 162мбк | G31: Л. Анатомия человека Силаева Л.В. 162мбк | H31: Л. Анатомия человека Силаева Л.В. 162мбк | I31: Л. Анатомия человека Силаева Л.В. 162мбк
C32: 14.50-16.20 | D32: Л. Физическая культура и спорт Ким Т.К. 162мбк | E32: Л. Физическая культура и спорт Ким Т.К. 162мбк | F32: Л. Физическая культура и спорт Ким Т.К. 162мбк | G32: Л. Физическая культура и спорт Ким Т.К. 162мбк | H32: Л. Физическая культура и спорт Ким Т.К. 162мбк | I32: Л. Физическая культура и спорт Ким Т.К. 162мбк
C33: 16.40-18.10
A34: Суббота | B34: =B29+1 -> 46284 | C34: 8.50-10.20
C35: 10.40-12.10
C36: 13.00-14.30
C37: 14.50-16.20
C38: 16.40-18.10
D39: * Профили (направленность) указанны на титульном листе
C40: ='01.09'!C39 -> *Л. Речевое общение в профессиональной деятельности* | D40: ='07.09'!D40+COUNTIF(D$8:D$38,$C40) -> 3 | E40: ='07.09'!E40+COUNTIF(E$8:E$38,$C40) -> 3 | F40: ='07.09'!F40+COUNTIF(F$8:F$38,$C40) -> 3 | G40: ='07.09'!G40+COUNTIF(G$8:G$38,$C40) -> 3 | H40: ='07.09'!H40+COUNTIF(H$8:H$38,$C40) -> 3 | I40: ='07.09'!I40+COUNTIF(I$8:I$38,$C40) -> 3
...

Sheet 21.09
B1: Расписание учебных занятий на первое полугодие 2026-2027 учебного года
B2: ТРЕНЕРСКИЙ ФАКУЛЬТЕТ, направление подготовки (образовательная программа)
B3: 49.03.04 Спорт *
B4: Курс 1, семестр 1, очная форма обучения
A5: группы С1-01-26, С1-02-26, С1-03-26, С1-04А-26, С1-04Б-26, С1-05А-26, С1-05Б-26, С1-06-26
A6: День недели | B6: Дата | C6: Время | D6: 1 группа | E6: 2 группа | F6: 3 группа | G6: 4 группа | H6: 5 группа | I6: 6 группа
D7: Баскетбол | E7: Волейбол, гандбол, бейсбол, регби | F7: Интеллектуальные и технологичные виды спорта (шахматы, гонки дронов, компьютерный спорт, страйкбол) | G7: Теннис, настольный теннис, бадминтон, бильярд, сквош | H7: Футбол | I7: Хоккей
A8: Понедельник | B8: 46286 | C8: 8.50-10.20 | D8: Пр. Иностранный язык Комова Е.В. 508 гл.к.
C9: 10.40-12.10 | D9: Пр. Информационные технологии в сфере физической культуры и спорта Яшкина Е.Н. 277мбк | G9: Пр. Элективные дисциплины по ФКиС: Силовая подготовка Громов В.А. 42СК | H9: Пр. Волейбол Ефимов А.С., Пшеничная А.М. 230СК
C10: 13.00-14.30 | D10: Пр. Гимнастика Андреасян К.Б. 205СК | E10: Пр. Иностранный язык Комова Е.В. 508 гл.к. | G10: Пр. Информационные технологии в сфере физической культуры и спорта Яшкина Е.Н. 277мбк, Попов Г.И. 246мбк | H10: Пр. Теория и методика футбола Прил.1 | I10: Пр. Волейбол Ефимов А.С. 230СК
C11: 14.50-16.20 | D11: Пр. Волейбол Ефимов А.С. 230СК | E11: Пр. Информационные технологии в сфере физической культуры и спорта Яшкина Е.Н. 277мбк | H11: Пр. Теория и методика футбола Прил.1 | I11: Пр. Иностранный язык Комова Е.В. 508 гл.к.
C12: 16.40-18.10
A13: Вторник | B13: =B8+1 -> 46287 | C13: 8.50-10.20 | D13: Пр. Теория и методика баскетбола Прил.1 | F13: Пр. Теория и методика интеллектуальных и технологичных видов спорта Прил.1 | G13: Пр. Теория и методика тенниса, настольного тенниса, бадминтона, бильярда, сквоша Прил.1
C14: 10.40-12.10 | D14: Пр. Теория и методика баскетбола Прил.1 | E14: Пр. Теория и методика волейбола, гандбола, бейсбола, регби Прил.1 | F14: Пр. Теория и методика интеллектуальных и технологичных видов спорта Прил.1 | G14: Пр. Теория и методика тенниса, настольного тенниса, бадминтона, бильярда, сквоша Прил.1 | H14: Пр. Иностранный язык Комова Е.В. 508 гл.к., Варичев А.М. 511 гл.к. | I14: Пр. Гимнастика Кувшинникова С.А.205СК
C15: 13.00-14.30 | E15: Пр. Гимнастика Кувшинникова С.А. 205СК | F15: Пр. Иностранный язык Комова Е.В. 508 гл.к. | G15: Пр. Волейбол Суханова А.В., Пшеничная А.М. 230СК | H15: Пр. Элективные дисциплины по ФКиС: Силовая подготовка Атлас А.А. 42СК | I15: Пр. Теория и методика хоккея Прил.1
C16: 14.50-16.20 | F16: Пр. Элективные дисциплины по ФКиС: Силовая подготовка Атлас А.А. 42СК | I16: Пр. Теория и методика хоккея Прил.1
C17: 16.40-18.10
C18: 18.30-20.00
A19: Среда | B19: =B13+1 -> 46288 | C19: 8.50-10.20 | H19: Пр. Волейбол Ефимов А.С., Пшеничная А.М. 230СК
C20: 10.40-12.10 | D20: Пр. Элективные дисциплины по ФКиС: Силовая подготовка Смирнов В.Е. 42СК | G20: Пр. Гимнастика Андреасян К.Б. 205СК (группа С1-04А-26), Козлов В.В. 205СК (группа С1-04Б-26) | H20: Пр. Гимнастика Кувшинникова С.А., Дубовицкая И.А. 205СК | I20: Пр. Волейбол Ефимов А.С. 230СК
C21: 13.00-14.30 | D21: Пр. Волейбол Ефимов А.С. 230СК | E21: Пр. Гимнастика Кувшинникова С.А. 205СК | G21: Пр. Элективные дисциплины по ФКиС: Силовая подготовка Громов В.А. 42СК - только 23.09, 30.09 | I21: Пр. Теория и методика хоккея Прил.1
C22: 14.50-16.20 | E22: Пр. Волейбол Ананьин А.С. 230СК | I22: Пр. Теория и методика хоккея Прил.1
C23: 16.40-18.10
A24: Четверг | B24: =B19+1 -> 46289 | C24: 8.50-10.20
C25: 10.40-12.10 | E25: Пр. Элективные дисциплины по ФКиС: Силовая подготовка Громов В.А. 42СК | F25: Пр. Информационные технологии в сфере физической культуры и спорта Яшкина Е.Н. 277мбк | G25: Пр. Теория и методика настольного тенниса, бадминтона, бильярда, сквоша Прил.1 | I25: Пр. Гимнастика Кувшинникова С.А.205СК
C26: 13.00-14.30 | D26: Пр. Теория и методика баскетбола Прил.1 | E26: Пр. Теория и методика волейбола, гандбола, бейсбола, регби Прил.1 | F26: Пр. Волейбол Суханова А.В. 230СК | G26: Пр. Иностранный язык Комова Е.В. 508 гл.к., Удалова М.Ю. 511 гл.к. | H26: Пр. Гимнастика Кувшинникова С.А., Дубовицкая И.А. 205СК | I26: Пр. Информационные технологии в сфере физической культуры и спорта Яшкина Е.Н. 277мбк
C27: 14.50-16.20 | D27: Пр. Теория и методика баскетбола Прил.1 | E27: Пр. Теория и методика волейбола, гандбола, бейсбола, регби Прил.1 | F27: Пр. Теория и методика интеллектуальных и технологичных видов спорта Прил.1 | G27: Пр. Теория и методика тенниса Прил.1 | H27: Пр. Информационные технологии в сфере физической культуры и спорта Яшкина Е.Н. 138мбк, Попов Г.И. 246мбк
C28: 16.40-18.10
A29: Пятница | B29: =B24+1 -> 46290 | C29: 8.50-10.20 | E29: Пр. Волейбол Ананьин А.С. 230СК | F29: Пр. Гимнастика Андреасян К.Б. 205СК | H29: Пр. Теория и методика футбола Прил.1 | I29: Пр. Элективные дисциплины по ФКиС: Силовая подготовка Атлас А.А. 42СК
C30: 10.40-12.10 | D30: Л. Речевое общение в профессиональной деятельности Волкова М.С. 212 ауд.к. | E30: Л. Речевое общение в профессиональной деятельности Волкова М.С. 212 ауд.к. | F30: Л. Речевое общение в профессиональной деятельности Волкова М.С. 212 ауд.к. | G30: Л. Речевое общение в профессиональной деятельности Волкова М.С. 212 ауд.к. | H30: Л. Речевое общение в профессиональной деятельности Волкова М.С. 212 ауд.к. | I30: Л. Речевое общение в профессиональной деятельности Волкова М.С. 212 ауд.к.
C31: 13.00-14.30 | D31: Л. Анатомия человека Силаева Л.В. 161мбк | E31: Л. Анатомия человека Силаева Л.В. 161мбк | F31: Л. Анатомия человека Силаева Л.В. 161мбк | G31: Л. Анатомия человека Силаева Л.В. 161мбк | H31: Л. Анатомия человека Силаева Л.В. 161мбк | I31: Л. Анатомия человека Силаева Л.В. 161мбк
C32: 14.50-16.20 | D32: Л. Физическая культура и спорт Ким Т.К. 220 ауд.к. | E32: Л. Физическая культура и спорт Ким Т.К. 220 ауд.к. | F32: Л. Физическая культура и спорт Ким Т.К. 220 ауд.к. | G32: Л. Физическая культура и спорт Ким Т.К. 220 ауд.к. | H32: Л. Физическая культура и спорт Ким Т.К. 220 ауд.к. | I32: Л. Физическая культура и спорт Ким Т.К. 220 ауд.к.
C33: 16.40-18.10
A34: Суббота | B34: =B29+1 -> 46291 | C34: 8.50-10.20
C35: 10.40-12.10
C36: 13.00-14.30
C37: 14.50-16.20
C38: 16.40-18.10
D39: * Профили (направленность) указанны на титульном листе
C40: ='01.09'!C39 -> *Л. Речевое общение в профессиональной деятельности* | D40: ='14.09'!D40+COUNTIF(D$8:D$38,$C40) -> 4 | E40: ='14.09'!E40+COUNTIF(E$8:E$38,$C40) -> 4 | F40: ='14.09'!F40+COUNTIF(F$8:F$38,$C40) -> 4 | G40: ='14.09'!G40+COUNTIF(G$8:G$38,$C40) -> 4 | H40: ='14.09'!H40+COUNTIF(H$8:H$38,$C40) -> 4 | I40: ='14.09'!I40+COUNTIF(I$8:I$38,$C40) -> 4
...

Sheet 28.09
B1: Расписание учебных занятий на первое полугодие 2026-2027 учебного года
B2: ТРЕНЕРСКИЙ ФАКУЛЬТЕТ, направление подготовки (образовательная программа)
B3: 49.03.04 Спорт *
B4: Курс 1, семестр 1, очная форма обучения
A5: группы С1-01-26, С1-02-26, С1-03-26, С1-04А-26, С1-04Б-26, С1-05А-26, С1-05Б-26, С1-06-26
A6: День недели | B6: Дата | C6: Время | D6: 1 группа | E6: 2 группа | F6: 3 группа | G6: 4 группа | H6: 5 группа | I6: 6 группа
D7: Баскетбол | E7: Волейбол, гандбол, бейсбол, регби | F7: Интеллектуальные и технологичные виды спорта (шахматы, гонки дронов, компьютерный спорт, страйкбол) | G7: Теннис, настольный теннис, бадминтон, бильярд, сквош | H7: Футбол | I7: Хоккей
A8: Понедельник | B8: 46293 | C8: 8.50-10.20 | D8: Пр. Иностранный язык Комова Е.В. 508 гл.к.
C9: 10.40-12.10 | D9: Пр. Информационные технологии в сфере физической культуры и спорта Яшкина Е.Н. 277мбк | G9: Пр. Элективные дисциплины по ФКиС: Силовая подготовка Громов В.А. 42СК | H9: Пр. Волейбол Ефимов А.С., Пшеничная А.М. 230СК
C10: 13.00-14.30 | D10: Пр. Гимнастика Андреасян К.Б. 205СК | E10: Пр. Иностранный язык Комова Е.В. 508 гл.к. | G10: Пр. Информационные технологии в сфере физической культуры и спорта Яшкина Е.Н. 277мбк, Попов Г.И. 246мбк | H10: Пр. Теория и методика футбола Прил.1 | I10: Пр. Волейбол Ефимов А.С. 230СК
C11: 14.50-16.20 | D11: Пр. Волейбол Ефимов А.С. 230СК | E11: Пр. Информационные технологии в сфере физической культуры и спорта Яшкина Е.Н. 277мбк | G11: Пр. Использование электронной информационно-образовательной среды РУС "ГЦОЛИФК" Шевцов А.В. 220ауд.к. | H11: Пр. Теория и методика футбола Прил.1 | I11: Пр. Иностранный язык Комова Е.В. 508 гл.к.
C12: 16.40-18.10
A13: Вторник | B13: =B8+1 -> 46294 | C13: 8.50-10.20 | D13: Пр. Теория и методика баскетбола Прил.1 | F13: Пр. Теория и методика интеллектуальных и технологичных видов спорта Прил.1 | G13: Пр. Теория и методика тенниса, настольного тенниса, бадминтона, бильярда, сквоша Прил.1 | H13: Пр. Использование электронной информационно-образовательной среды РУС "ГЦОЛИФК" Шевцов А.В. 216ауд.к.
C14: 10.40-12.10 | D14: Пр. Теория и методика баскетбола Прил.1 | E14: Пр. Теория и методика волейбола, гандбола, бейсбола, регби Прил.1 | F14: Пр. Теория и методика интеллектуальных и технологичных видов спорта Прил.1 | G14: Пр. Теория и методика тенниса, настольного тенниса, бадминтона, бильярда, сквоша Прил.1 | H14: Пр. Иностранный язык Комова Е.В. 508 гл.к., Варичев А.М. 511 гл.к. | I14: Пр. Гимнастика Кувшинникова С.А.205СК
C15: 13.00-14.30 | E15: Пр. Гимнастика Кувшинникова С.А. 205СК | F15: Пр. Иностранный язык Комова Е.В. 508 гл.к. | G15: Пр. Волейбол Суханова А.В., Пшеничная А.М. 230СК | H15: Пр. Элективные дисциплины по ФКиС: Силовая подготовка Атлас А.А. 42СК | I15: Пр. Физическая культура и спорт Кривенков А.А. 309 гл.к.
C16: 14.50-16.20 | F16: Пр. Элективные дисциплины по ФКиС: Силовая подготовка Атлас А.А. 42СК | H16: Пр. Физическая культура и спорт Кривенков А.А. 306 гл.к.
C17: 16.40-18.10
C18: 18.30-20.00
A19: Среда | B19: =B13+1 -> 46295 | C19: 8.50-10.20 | G19: Пр. Физическая культура и спорт Кривенков А.А. 404 ауд.к. | H19: Пр. Волейбол Ефимов А.С., Пшеничная А.М. 230СК
C20: 10.40-12.10 | D20: Пр. Элективные дисциплины по ФКиС: Силовая подготовка Смирнов В.Е. 42СК | E20: Пр. Физическая культура и спорт Кривенков А.А. 404 ауд.к. | G20: Пр. Гимнастика Андреасян К.Б. 205СК (группа С1-04А-26), Козлов В.В. 205СК (группа С1-04Б-26) | H20: Пр. Гимнастика Кувшинникова С.А., Дубовицкая И.А. 205СК | I20: Пр. Волейбол Ефимов А.С. 230СК
C21: 13.00-14.30 | D21: Пр. Волейбол Ефимов А.С. 230СК | E21: Пр. Гимнастика Кувшинникова С.А. 205СК | F21: Пр. Физическая культура и спорт Кривенков А.А. 306 гл.к. | G21: Пр. Элективные дисциплины по ФКиС: Силовая подготовка Громов В.А. 42СК - только 30.09 | H21: Пр. Использование электронной информационно-образовательной среды РУС "ГЦОЛИФК" Кузнецова Н.А. 403 ауд.к. | I21: Пр. Теория и методика хоккея Прил.1
C22: 14.50-16.20 | D22: Пр. Физическая культура и спорт Кривенков А.А. 306 гл.к. | E22: Пр. Волейбол Ананьин А.С. 230СК | F22: Пр. Гимнастика Андреасян К.Б. 205СК | G22: Пр. Использование электронной информационно-образовательной среды РУС "ГЦОЛИФК" Кузнецова Н.А. 403 ауд.к. | I22: Пр. Теория и методика хоккея Прил.1
C23: 16.40-18.10
A24: Четверг | B24: =B19+1 -> 46296 | C24: 8.50-10.20
C25: 10.40-12.10 | E25: Пр. Элективные дисциплины по ФКиС: Силовая подготовка Громов В.А. 42СК | F25: Пр. Информационные технологии в сфере физической культуры и спорта Яшкина Е.Н. 277мбк | G25: Пр. Теория и методика настольного тенниса, бадминтона, бильярда, сквоша Прил.1 | I25: Пр. Гимнастика Кувшинникова С.А.205СК
C26: 13.00-14.30 | D26: Л. Теория и методика баскетбола Прил.1 | E26: Пр. Теория и методика волейбола, гандбола, бейсбола, регби Прил.1 | F26: Пр. Волейбол Суханова А.В. 230СК | G26: Пр. Иностранный язык Комова Е.В. 508 гл.к., Удалова М.Ю. 511 гл.к. | H26: Пр. Гимнастика Кувшинникова С.А., Дубовицкая И.А. 205СК | I26: Пр. Информационные технологии в сфере физической культуры и спорта Яшкина Е.Н. 277мбк
C27: 14.50-16.20 | D27: Пр. Теория и методика баскетбола Прил.1 | E27: Пр. Теория и методика волейбола, гандбола, бейсбола, регби Прил.1 | F27: Пр. Теория и методика интеллектуальных и технологичных видов спорта Прил.1 | G27: Пр. Теория и методика тенниса Прил.1 | H27: Пр. Информационные технологии в сфере физической культуры и спорта Яшкина Е.Н. 277мбк, Попов Г.И. 246мбк
C28: 16.40-18.10
A29: Пятница | B29: =B24+1 -> 46297 | C29: 8.50-10.20 | E29: Пр. Волейбол Ананьин А.С. 230СК | F29: Пр. Гимнастика Андреасян К.Б. 205СК | H29: Пр. Теория и методика футбола Прил.1 | I29: Пр. Элективные дисциплины по ФКиС: Силовая подготовка Атлас А.А. 42СК
C30: 10.40-12.10 | D30: Л. Речевое общение в профессиональной деятельности Волкова М.С. 212 ауд.к. | E30: Л. Речевое общение в профессиональной деятельности Волкова М.С. 212 ауд.к. | F30: Л. Речевое общение в профессиональной деятельности Волкова М.С. 212 ауд.к. | G30: Л. Речевое общение в профессиональной деятельности Волкова М.С. 212 ауд.к. | H30: Л. Речевое общение в профессиональной деятельности Волкова М.С. 212 ауд.к. | I30: Л. Речевое общение в профессиональной деятельности Волкова М.С. 212 ауд.к.
C31: 13.00-14.30 | D31: Л. Анатомия человека Силаева Л.В. 161мбк | E31: Л. Анатомия человека Силаева Л.В. 161мбк | F31: Л. Анатомия человека Силаева Л.В. 161мбк | G31: Л. Анатомия человека Силаева Л.В. 161мбк | H31: Л. Анатомия человека Силаева Л.В. 161мбк | I31: Л. Анатомия человека Силаева Л.В. 161мбк
C32: 14.50-16.20 | D32: Л. Физическая культура и спорт Ким Т.К. 220 ауд.к. | E32: Л. Физическая культура и спорт Ким Т.К. 220 ауд.к. | F32: Л. Физическая культура и спорт Ким Т.К. 220 ауд.к. | G32: Л. Физическая культура и спорт Ким Т.К. 220 ауд.к. | H32: Л. Физическая культура и спорт Ким Т.К. 220 ауд.к. | I32: Л. Физическая культура и спорт Ким Т.К. 220 ауд.к.
C33: 16.40-18.10
A34: Суббота | B34: =B29+1 -> 46298 | C34: 8.50-10.20
C35: 10.40-12.10
C36: 13.00-14.30
C37: 14.50-16.20
C38: 16.40-18.10
D39: * Профили (направленность) указанны на титульном листе
C40: ='01.09'!C39 -> *Л. Речевое общение в профессиональной деятельности* | D40: ='21.09'!D40+COUNTIF(D$8:D$38,$C40) -> 5 | E40: ='21.09'!E40+COUNTIF(E$8:E$38,$C40) -> 5 | F40: ='21.09'!F40+COUNTIF(F$8:F$38,$C40) -> 5 | G40: ='21.09'!G40+COUNTIF(G$8:G$38,$C40) -> 5 | H40: ='21.09'!H40+COUNTIF(H$8:H$38,$C40) -> 5 | I40: ='21.09'!I40+COUNTIF(I$8:I$38,$C40) -> 5
...

Sheet 05.10
B1: Расписание учебных занятий на первое полугодие 2026-2027 учебного года
B2: ТРЕНЕРСКИЙ ФАКУЛЬТЕТ, направление подготовки (образовательная программа)
B3: 49.03.04 Спорт *
B4: Курс 1, семестр 1, очная форма обучения
A5: группы С1-01-26, С1-02-26, С1-03-26, С1-04А-26, С1-04Б-26, С1-05А-26, С1-05Б-26, С1-06-26
A6: День недели | B6: Дата | C6: Время | D6: 1 группа | E6: 2 группа | F6: 3 группа | G6: 4 группа | H6: 5 группа | I6: 6 группа
D7: Баскетбол | E7: Волейбол, гандбол, бейсбол, регби | F7: Интеллектуальные и технологичные виды спорта (шахматы, гонки дронов, компьютерный спорт, страйкбол) | G7: Теннис, настольный теннис, бадминтон, бильярд, сквош | H7: Футбол | I7: Хоккей
A8: Понедельник | B8: 46300 | C8: 8.50-10.20 | D8: Пр. Иностранный язык Комова Е.В. 508 гл.к.
C9: 10.40-12.10 | D9: Пр. Информационные технологии в сфере физической культуры и спорта Яшкина Е.Н. 277мбк | G9: Пр. Элективные дисциплины по ФКиС: Силовая подготовка Громов В.А. 42СК | H9: Пр. Волейбол Ефимов А.С., Пшеничная А.М. 230СК
C10: 13.00-14.30 | D10: Пр. Гимнастика Андреасян К.Б. 205СК | E10: Пр. Иностранный язык Комова Е.В. 508 гл.к. | G10: Пр. Информационные технологии в сфере физической культуры и спорта Яшкина Е.Н. 277мбк, Попов Г.И. 246мбк | H10: Л. Теория и методика футбола Прил.1 | I10: Пр. Волейбол Ефимов А.С. 230СК
C11: 14.50-16.20 | D11: Пр. Волейбол Ефимов А.С. 230СК | E11: Пр. Информационные технологии в сфере физической культуры и спорта Яшкина Е.Н. 277мбк | G11: Пр. Гимнастика Андреасян К.Б. 205СК (группа С1-04А-26) | H11: Пр. Теория и методика футбола Прил.1 | I11: Пр. Иностранный язык Комова Е.В. 508 гл.к.
C12: 16.40-18.10
A13: Вторник | B13: =B8+1 -> 46301 | C13: 8.50-10.20 | F13: Л. Теория и методика интеллектуальных и технологичных видов спорта Прил.1 | G13: Пр. Теория и методика тенниса, настольного тенниса, бадминтона, бильярда, сквоша Прил.1 | I13: Пр. Использование электронной информационно-образовательной среды РУС "ГЦОЛИФК" Шевцов А.В. 216ауд.к.
C14: 10.40-12.10 | D14: Пр. Теория и методика баскетбола Прил.1 | E14: Л. Теория и методика волейбола, гандбола, бейсбола, регби Прил.1 | F14: Пр. Теория и методика интеллектуальных и технологичных видов спорта Прил.1 | G14: Пр. Теория и методика тенниса, настольного тенниса, бадминтона, бильярда, сквоша Прил.1 | H14: Пр. Иностранный язык Комова Е.В. 508 гл.к., Бабель Т.А. 511 гл.к. | I14: Пр. Гимнастика Кувшинникова С.А.205СК
C15: 13.00-14.30 | D15: Пр. Анатомия человека Гричанова Т.Г. 154мбк | E15: Пр. Гимнастика Кувшинникова С.А. 205СК - только 06.10 | F15: Пр. Иностранный язык Комова Е.В. 508 гл.к. | G15: Пр. Волейбол Суханова А.В., Пшеничная А.М. 230СК | H15: Пр. Элективные дисциплины по ФКиС: Силовая подготовка Атлас А.А. 42СК | I15: Пр. Физическая культура и спорт Кривенков А.А. 309 гл.к.
C16: 14.50-16.20 | D16: Пр. Речевое общение в профессиональной деятельности Волкова М.С. 513 гл.к. | F16: Пр. Элективные дисциплины по ФКиС: Силовая подготовка Атлас А.А. 42СК | H16: Пр. Физическая культура и спорт Кривенков А.А. 306 гл.к.
C17: 16.40-18.10
C18: 18.30-20.00
A19: Среда | B19: =B13+1 -> 46302 | C19: 8.50-10.20 | E19: Пр. Речевое общение в профессиональной деятельности Волкова М.С. 410 гл.к.- только 07.10 | G19: Пр. Физическая культура и спорт Кривенков А.А. 404 ауд.к. | H19: Пр. Волейбол Ефимов А.С., Пшеничная А.М. 230СК
C20: 10.40-12.10 | D20: Пр. Элективные дисциплины по ФКиС: Силовая подготовка Смирнов В.Е. 42СК | E20: Пр. Физическая культура и спорт Кривенков А.А. 404 ауд.к. | F20: Пр. Анатомия человека Мештель А.В. 154мбк | G20: Пр. Гимнастика Андреасян К.Б. 205СК (группа С1-04А-26), Козлов В.В. 205СК (группа С1-04Б-26) | H20: Пр. Гимнастика Кувшинникова С.А., Дубовицкая И.А. 205СК | I20: Пр. Волейбол Ефимов А.С. 230СК
C21: 13.00-14.30 | D21: Пр. Волейбол Ефимов А.С. 230СК | E21: Пр. Гимнастика Кувшинникова С.А. 205СК | F21: Пр. Физическая культура и спорт Кривенков А.А. 403 ауд.к. | I21: Л. Теория и методика хоккея Прил.1
C22: 14.50-16.20 | D22: Пр. Физическая культура и спорт Кривенков А.А. 403 ауд.к. | E22: Пр. Волейбол Ананьин А.С. 230СК | F22: Пр. Гимнастика Андреасян К.Б. 205СК | I22: Пр. Теория и методика хоккея Прил.1
C23: 16.40-18.10
A24: Четверг | B24: =B19+1 -> 46303 | C24: 8.50-10.20
C25: 10.40-12.10 | E25: Пр. Элективные дисциплины по ФКиС: Силовая подготовка Громов В.А. 42СК | F25: Пр. Информационные технологии в сфере физической культуры и спорта Яшкина Е.Н. 277мбк | G25: Пр. Теория и методика настольного тенниса, бадминтона, бильярда, сквоша Прил.1 | I25: Пр. Речевое общение в профессиональной деятельности Волкова М.С. 513 гл.к.
C26: 13.00-14.30 | D26: Пр. Теория и методика баскетбола Прил.1 | E26: Пр. Теория и методика волейбола, гандбола, бейсбола, регби Прил.1 | F26: Пр. Волейбол Суханова А.В. 230СК | G26: Пр. Иностранный язык Комова Е.В. 508 гл.к., Удалова М.Ю. 511 гл.к. | H26: Пр. Гимнастика Кувшинникова С.А., Дубовицкая И.А. 205СК - только 08.10 | I26: Пр. Информационные технологии в сфере физической культуры и спорта Яшкина Е.Н. 277мбк
C27: 14.50-16.20 | D27: Пр. Теория и методика баскетбола Прил.1 | E27: Пр. Теория и методика волейбола, гандбола, бейсбола, регби Прил.1 | F27: Пр. Теория и методика интеллектуальных и технологичных видов спорта Прил.1 | G27: Пр. Теория и методика тенниса Прил.1 | H27: Пр. Информационные технологии в сфере физической культуры и спорта Яшкина Е.Н. 277мбк, Попов Г.И. 246мбк
C28: 16.40-18.10 | H28: Пр. Речевое общение в профессиональной деятельности Волкова М.С. (группа С1-05А-26) 513 гл.к.- только 08.10
A29: Пятница | B29: =B24+1 -> 46304 | C29: 8.50-10.20 | E29: Пр. Анатомия человека Сироткина Ю.А. 151мбк | F29: Пр. Гимнастика Андреасян К.Б. 205СК | H29: Пр. Теория и методика футбола Прил.1 | I29: Пр. Элективные дисциплины по ФКиС: Силовая подготовка Атлас А.А. 42СК
C30: 10.40-12.10 | E30: Пр. Волейбол Ананьин А.С. 230СК | F30: Пр. Речевое общение в профессиональной деятельности Волкова М.С. 513 гл.к. | H30: Пр. Теория и методика футбола Прил.1 | I30: Пр. Анатомия человека Силаева Л.В. 143мбк
C31: 13.00-14.30 | F31: Пр. Использование электронной информационно-образовательной среды РУС "ГЦОЛИФК" Шевцов А.В. 220ауд.к. | G31: Пр. Речевое общение в профессиональной деятельности Волкова М.С. 513гл.к. (группа С1-04А-26); Пр. Гимнастика Козлов В.В. 205СК (группа С1-04Б-26) | H31: Пр. Анатомия человека Силаева Л.В. 143мбк(группа С1-05Б-26) , Мештель А.В. 151мбк (группа С1-05А-26) | I31: Пр. Использование электронной информационно-образовательной среды РУС "ГЦОЛИФК" Кузнецова Н.А. 401ауд.к.
C32: 14.50-16.20 | G32: Пр. Анатомия человека Силаева Л.В. 143мбк (группа С1-04А-26), Мештель А.В. 151мбк (группа С1-04Б-26) | H32: Пр. Речевое общение в профессиональной деятельности Волкова М.С. 513 гл.к.(группа С1-05Б-26)
C33: 16.40-18.10 | G33: Пр. Речевое общение в профессиональной деятельности Волкова М.С. 513гл.к.(группа С1-04Б-26)
A34: Суббота | B34: =B29+1 -> 46305 | C34: 8.50-10.20
C35: 10.40-12.10
C36: 13.00-14.30
C37: 14.50-16.20
C38: 16.40-18.10
D39: * Профили (направленность) указанны на титульном листе
C40: ='01.09'!C39 -> *Л. Речевое общение в профессиональной деятельности* | D40: ='28.09'!D40+COUNTIF(D$8:D$38,$C40) -> 5 | E40: ='28.09'!E40+COUNTIF(E$8:E$38,$C40) -> 5 | F40: ='28.09'!F40+COUNTIF(F$8:F$38,$C40) -> 5 | G40: ='28.09'!G40+COUNTIF(G$8:G$38,$C40) -> 5 | H40: ='28.09'!H40+COUNTIF(H$8:H$38,$C40) -> 5 | I40: ='28.09'!I40+COUNTIF(I$8:I$38,$C40) -> 5
...

Sheet 12.10
B1: Расписание учебных занятий на первое полугодие 2026-2027 учебного года
